[INFO] Starting execution.
[INFO] Downloading package list from PyPI ...
[ERROR] (0) Could not get a response from API for this package. See below for details.
Traceback (most recent call last):
  File "/usr/lib/python3.5/urllib/request.py", line 1254, in do_open
    h.request(req.get_method(), req.selector, req.data, headers)
  File "/usr/lib/python3.5/http/client.py", line 1107, in request
    self._send_request(method, url, body, headers)
  File "/usr/lib/python3.5/http/client.py", line 1152, in _send_request
    self.endheaders(body)
  File "/usr/lib/python3.5/http/client.py", line 1103, in endheaders
    self._send_output(message_body)
  File "/usr/lib/python3.5/http/client.py", line 934, in _send_output
    self.send(msg)
  File "/usr/lib/python3.5/http/client.py", line 877, in send
    self.connect()
  File "/usr/lib/python3.5/http/client.py", line 1261, in connect
    server_hostname=server_hostname)
  File "/usr/lib/python3.5/ssl.py", line 385, in wrap_socket
    _context=self)
  File "/usr/lib/python3.5/ssl.py", line 760, in __init__
    self.do_handshake()
  File "/usr/lib/python3.5/ssl.py", line 996, in do_handshake
    self._sslobj.do_handshake()
  File "/usr/lib/python3.5/ssl.py", line 641, in do_handshake
    self._sslobj.do_handshake()
socket.timeout: _ssl.c:703: The handshake operation timed out

During handling of the above exception, another exception occurred:

Traceback (most recent call last):
  File "/usr/local/lib/python3.5/dist-packages/pypicontents/api/pypi.py", line 264, in get_pkgdata
    timeout=10).read()
  File "/usr/lib/python3.5/urllib/request.py", line 163, in urlopen
    return opener.open(url, data, timeout)
  File "/usr/lib/python3.5/urllib/request.py", line 466, in open
    response = self._open(req, data)
  File "/usr/lib/python3.5/urllib/request.py", line 484, in _open
    '_open', req)
  File "/usr/lib/python3.5/urllib/request.py", line 444, in _call_chain
    result = func(*args)
  File "/usr/lib/python3.5/urllib/request.py", line 1297, in https_open
    context=self._context, check_hostname=self._check_hostname)
  File "/usr/lib/python3.5/urllib/request.py", line 1256, in do_open
    raise URLError(err)
urllib.error.URLError: <urlopen error _ssl.c:703: The handshake operation timed out>

[ERROR] (0-0) This package does not have downloadable releases.
[INFO] (0-0-1) This package is up to date.
[INFO] (0-core-client) This package is up to date.
[INFO] (0-orchestrator) This package is up to date.
[INFO] (00print-lol) This package is up to date.
[ERROR] (00smalinux) This package does not have downloadable releases.
[ERROR] (01changer) This package does not have downloadable releases.
[ERROR] (021) Could not get a response from API for this package. See below for details.
Traceback (most recent call last):
  File "/usr/lib/python3.5/urllib/request.py", line 1254, in do_open
    h.request(req.get_method(), req.selector, req.data, headers)
  File "/usr/lib/python3.5/http/client.py", line 1107, in request
    self._send_request(method, url, body, headers)
  File "/usr/lib/python3.5/http/client.py", line 1152, in _send_request
    self.endheaders(body)
  File "/usr/lib/python3.5/http/client.py", line 1103, in endheaders
    self._send_output(message_body)
  File "/usr/lib/python3.5/http/client.py", line 934, in _send_output
    self.send(msg)
  File "/usr/lib/python3.5/http/client.py", line 877, in send
    self.connect()
  File "/usr/lib/python3.5/http/client.py", line 1261, in connect
    server_hostname=server_hostname)
  File "/usr/lib/python3.5/ssl.py", line 385, in wrap_socket
    _context=self)
  File "/usr/lib/python3.5/ssl.py", line 760, in __init__
    self.do_handshake()
  File "/usr/lib/python3.5/ssl.py", line 996, in do_handshake
    self._sslobj.do_handshake()
  File "/usr/lib/python3.5/ssl.py", line 641, in do_handshake
    self._sslobj.do_handshake()
socket.timeout: _ssl.c:703: The handshake operation timed out

During handling of the above exception, another exception occurred:

Traceback (most recent call last):
  File "/usr/local/lib/python3.5/dist-packages/pypicontents/api/pypi.py", line 264, in get_pkgdata
    timeout=10).read()
  File "/usr/lib/python3.5/urllib/request.py", line 163, in urlopen
    return opener.open(url, data, timeout)
  File "/usr/lib/python3.5/urllib/request.py", line 466, in open
    response = self._open(req, data)
  File "/usr/lib/python3.5/urllib/request.py", line 484, in _open
    '_open', req)
  File "/usr/lib/python3.5/urllib/request.py", line 444, in _call_chain
    result = func(*args)
  File "/usr/lib/python3.5/urllib/request.py", line 1297, in https_open
    context=self._context, check_hostname=self._check_hostname)
  File "/usr/lib/python3.5/urllib/request.py", line 1256, in do_open
    raise URLError(err)
urllib.error.URLError: <urlopen error _ssl.c:703: The handshake operation timed out>

[INFO] (02exercicio) This package is up to date.
[INFO] (0805nexter) This package is up to date.
[INFO] (090807040506030201testpip) This package is up to date.
[ERROR] (0lever-so) Could not get a response from API for this package. See below for details.
Traceback (most recent call last):
  File "/usr/lib/python3.5/urllib/request.py", line 1254, in do_open
    h.request(req.get_method(), req.selector, req.data, headers)
  File "/usr/lib/python3.5/http/client.py", line 1107, in request
    self._send_request(method, url, body, headers)
  File "/usr/lib/python3.5/http/client.py", line 1152, in _send_request
    self.endheaders(body)
  File "/usr/lib/python3.5/http/client.py", line 1103, in endheaders
    self._send_output(message_body)
  File "/usr/lib/python3.5/http/client.py", line 934, in _send_output
    self.send(msg)
  File "/usr/lib/python3.5/http/client.py", line 877, in send
    self.connect()
  File "/usr/lib/python3.5/http/client.py", line 1261, in connect
    server_hostname=server_hostname)
  File "/usr/lib/python3.5/ssl.py", line 385, in wrap_socket
    _context=self)
  File "/usr/lib/python3.5/ssl.py", line 760, in __init__
    self.do_handshake()
  File "/usr/lib/python3.5/ssl.py", line 996, in do_handshake
    self._sslobj.do_handshake()
  File "/usr/lib/python3.5/ssl.py", line 641, in do_handshake
    self._sslobj.do_handshake()
socket.timeout: _ssl.c:703: The handshake operation timed out

During handling of the above exception, another exception occurred:

Traceback (most recent call last):
  File "/usr/local/lib/python3.5/dist-packages/pypicontents/api/pypi.py", line 264, in get_pkgdata
    timeout=10).read()
  File "/usr/lib/python3.5/urllib/request.py", line 163, in urlopen
    return opener.open(url, data, timeout)
  File "/usr/lib/python3.5/urllib/request.py", line 466, in open
    response = self._open(req, data)
  File "/usr/lib/python3.5/urllib/request.py", line 484, in _open
    '_open', req)
  File "/usr/lib/python3.5/urllib/request.py", line 444, in _call_chain
    result = func(*args)
  File "/usr/lib/python3.5/urllib/request.py", line 1297, in https_open
    context=self._context, check_hostname=self._check_hostname)
  File "/usr/lib/python3.5/urllib/request.py", line 1256, in do_open
    raise URLError(err)
urllib.error.URLError: <urlopen error _ssl.c:703: The handshake operation timed out>

[INFO] (0lever-utils) Data has been updated for this package.
[INFO] (0wdg9nbmpm) This package is up to date.
[INFO] (0wned) This package is up to date.
[INFO] (0x) This package is up to date.
[INFO] (0x-contract-addresses) This package is up to date.
[INFO] (0x-contract-artifacts) This package is up to date.
[INFO] (0x-json-schemas) This package is up to date.
[INFO] (0x-order-utils) This package is up to date.
[ERROR] (0x-sra-client) Could not get a response from API for this package. See below for details.
Traceback (most recent call last):
  File "/usr/lib/python3.5/urllib/request.py", line 1254, in do_open
    h.request(req.get_method(), req.selector, req.data, headers)
  File "/usr/lib/python3.5/http/client.py", line 1107, in request
    self._send_request(method, url, body, headers)
  File "/usr/lib/python3.5/http/client.py", line 1152, in _send_request
    self.endheaders(body)
  File "/usr/lib/python3.5/http/client.py", line 1103, in endheaders
    self._send_output(message_body)
  File "/usr/lib/python3.5/http/client.py", line 934, in _send_output
    self.send(msg)
  File "/usr/lib/python3.5/http/client.py", line 877, in send
    self.connect()
  File "/usr/lib/python3.5/http/client.py", line 1261, in connect
    server_hostname=server_hostname)
  File "/usr/lib/python3.5/ssl.py", line 385, in wrap_socket
    _context=self)
  File "/usr/lib/python3.5/ssl.py", line 760, in __init__
    self.do_handshake()
  File "/usr/lib/python3.5/ssl.py", line 996, in do_handshake
    self._sslobj.do_handshake()
  File "/usr/lib/python3.5/ssl.py", line 641, in do_handshake
    self._sslobj.do_handshake()
socket.timeout: _ssl.c:703: The handshake operation timed out

During handling of the above exception, another exception occurred:

Traceback (most recent call last):
  File "/usr/local/lib/python3.5/dist-packages/pypicontents/api/pypi.py", line 264, in get_pkgdata
    timeout=10).read()
  File "/usr/lib/python3.5/urllib/request.py", line 163, in urlopen
    return opener.open(url, data, timeout)
  File "/usr/lib/python3.5/urllib/request.py", line 466, in open
    response = self._open(req, data)
  File "/usr/lib/python3.5/urllib/request.py", line 484, in _open
    '_open', req)
  File "/usr/lib/python3.5/urllib/request.py", line 444, in _call_chain
    result = func(*args)
  File "/usr/lib/python3.5/urllib/request.py", line 1297, in https_open
    context=self._context, check_hostname=self._check_hostname)
  File "/usr/lib/python3.5/urllib/request.py", line 1256, in do_open
    raise URLError(err)
urllib.error.URLError: <urlopen error _ssl.c:703: The handshake operation timed out>

[INFO] (0x-web3) This package is up to date.
[INFO] (0x01-autocert-dns-aliyun) This package is up to date.
[INFO] (0x01-letsencrypt) This package is up to date.
[INFO] (0x10c-asm) This package is up to date.
[ERROR] (1) This package does not have downloadable releases.
[INFO] (100bot) This package is up to date.
[INFO] (1020-nester) This package is up to date.
[INFO] (10daysweb) This package is up to date.
[ERROR] (115wangpan) Could not get a response from API for this package. See below for details.
Traceback (most recent call last):
  File "/usr/lib/python3.5/urllib/request.py", line 1254, in do_open
    h.request(req.get_method(), req.selector, req.data, headers)
  File "/usr/lib/python3.5/http/client.py", line 1107, in request
    self._send_request(method, url, body, headers)
  File "/usr/lib/python3.5/http/client.py", line 1152, in _send_request
    self.endheaders(body)
  File "/usr/lib/python3.5/http/client.py", line 1103, in endheaders
    self._send_output(message_body)
  File "/usr/lib/python3.5/http/client.py", line 934, in _send_output
    self.send(msg)
  File "/usr/lib/python3.5/http/client.py", line 877, in send
    self.connect()
  File "/usr/lib/python3.5/http/client.py", line 1261, in connect
    server_hostname=server_hostname)
  File "/usr/lib/python3.5/ssl.py", line 385, in wrap_socket
    _context=self)
  File "/usr/lib/python3.5/ssl.py", line 760, in __init__
    self.do_handshake()
  File "/usr/lib/python3.5/ssl.py", line 996, in do_handshake
    self._sslobj.do_handshake()
  File "/usr/lib/python3.5/ssl.py", line 641, in do_handshake
    self._sslobj.do_handshake()
socket.timeout: _ssl.c:703: The handshake operation timed out

During handling of the above exception, another exception occurred:

Traceback (most recent call last):
  File "/usr/local/lib/python3.5/dist-packages/pypicontents/api/pypi.py", line 264, in get_pkgdata
    timeout=10).read()
  File "/usr/lib/python3.5/urllib/request.py", line 163, in urlopen
    return opener.open(url, data, timeout)
  File "/usr/lib/python3.5/urllib/request.py", line 466, in open
    response = self._open(req, data)
  File "/usr/lib/python3.5/urllib/request.py", line 484, in _open
    '_open', req)
  File "/usr/lib/python3.5/urllib/request.py", line 444, in _call_chain
    result = func(*args)
  File "/usr/lib/python3.5/urllib/request.py", line 1297, in https_open
    context=self._context, check_hostname=self._check_hostname)
  File "/usr/lib/python3.5/urllib/request.py", line 1256, in do_open
    raise URLError(err)
urllib.error.URLError: <urlopen error _ssl.c:703: The handshake operation timed out>

[INFO] (11l) This package is up to date.
[INFO] (12306-booking) This package is up to date.
[INFO] (12factor-vault) This package is up to date.
[INFO] (131228-pytest-1) This package is up to date.
[INFO] (1337) This package is up to date.
[INFO] (153957-theme) This package is up to date.
[INFO] (15five-django-ajax-selects) This package is up to date.
[INFO] (15five-snowplow-tracker) This package is up to date.
[ERROR] (17monip) Could not get a response from API for this package. See below for details.
Traceback (most recent call last):
  File "/usr/lib/python3.5/urllib/request.py", line 1254, in do_open
    h.request(req.get_method(), req.selector, req.data, headers)
  File "/usr/lib/python3.5/http/client.py", line 1107, in request
    self._send_request(method, url, body, headers)
  File "/usr/lib/python3.5/http/client.py", line 1152, in _send_request
    self.endheaders(body)
  File "/usr/lib/python3.5/http/client.py", line 1103, in endheaders
    self._send_output(message_body)
  File "/usr/lib/python3.5/http/client.py", line 934, in _send_output
    self.send(msg)
  File "/usr/lib/python3.5/http/client.py", line 877, in send
    self.connect()
  File "/usr/lib/python3.5/http/client.py", line 1261, in connect
    server_hostname=server_hostname)
  File "/usr/lib/python3.5/ssl.py", line 385, in wrap_socket
    _context=self)
  File "/usr/lib/python3.5/ssl.py", line 760, in __init__
    self.do_handshake()
  File "/usr/lib/python3.5/ssl.py", line 996, in do_handshake
    self._sslobj.do_handshake()
  File "/usr/lib/python3.5/ssl.py", line 641, in do_handshake
    self._sslobj.do_handshake()
socket.timeout: _ssl.c:703: The handshake operation timed out

During handling of the above exception, another exception occurred:

Traceback (most recent call last):
  File "/usr/local/lib/python3.5/dist-packages/pypicontents/api/pypi.py", line 264, in get_pkgdata
    timeout=10).read()
  File "/usr/lib/python3.5/urllib/request.py", line 163, in urlopen
    return opener.open(url, data, timeout)
  File "/usr/lib/python3.5/urllib/request.py", line 466, in open
    response = self._open(req, data)
  File "/usr/lib/python3.5/urllib/request.py", line 484, in _open
    '_open', req)
  File "/usr/lib/python3.5/urllib/request.py", line 444, in _call_chain
    result = func(*args)
  File "/usr/lib/python3.5/urllib/request.py", line 1297, in https_open
    context=self._context, check_hostname=self._check_hostname)
  File "/usr/lib/python3.5/urllib/request.py", line 1256, in do_open
    raise URLError(err)
urllib.error.URLError: <urlopen error _ssl.c:703: The handshake operation timed out>

[ERROR] (18-e) This package does not have downloadable releases.
[INFO] (199fix) This package is up to date.
[INFO] (1a23-telemetry) This package is up to date.
[ERROR] (1and1) Could not get a response from API for this package. See below for details.
Traceback (most recent call last):
  File "/usr/lib/python3.5/urllib/request.py", line 1254, in do_open
    h.request(req.get_method(), req.selector, req.data, headers)
  File "/usr/lib/python3.5/http/client.py", line 1107, in request
    self._send_request(method, url, body, headers)
  File "/usr/lib/python3.5/http/client.py", line 1152, in _send_request
    self.endheaders(body)
  File "/usr/lib/python3.5/http/client.py", line 1103, in endheaders
    self._send_output(message_body)
  File "/usr/lib/python3.5/http/client.py", line 934, in _send_output
    self.send(msg)
  File "/usr/lib/python3.5/http/client.py", line 877, in send
    self.connect()
  File "/usr/lib/python3.5/http/client.py", line 1261, in connect
    server_hostname=server_hostname)
  File "/usr/lib/python3.5/ssl.py", line 385, in wrap_socket
    _context=self)
  File "/usr/lib/python3.5/ssl.py", line 760, in __init__
    self.do_handshake()
  File "/usr/lib/python3.5/ssl.py", line 996, in do_handshake
    self._sslobj.do_handshake()
  File "/usr/lib/python3.5/ssl.py", line 641, in do_handshake
    self._sslobj.do_handshake()
socket.timeout: _ssl.c:703: The handshake operation timed out

During handling of the above exception, another exception occurred:

Traceback (most recent call last):
  File "/usr/local/lib/python3.5/dist-packages/pypicontents/api/pypi.py", line 264, in get_pkgdata
    timeout=10).read()
  File "/usr/lib/python3.5/urllib/request.py", line 163, in urlopen
    return opener.open(url, data, timeout)
  File "/usr/lib/python3.5/urllib/request.py", line 466, in open
    response = self._open(req, data)
  File "/usr/lib/python3.5/urllib/request.py", line 484, in _open
    '_open', req)
  File "/usr/lib/python3.5/urllib/request.py", line 444, in _call_chain
    result = func(*args)
  File "/usr/lib/python3.5/urllib/request.py", line 1297, in https_open
    context=self._context, check_hostname=self._check_hostname)
  File "/usr/lib/python3.5/urllib/request.py", line 1256, in do_open
    raise URLError(err)
urllib.error.URLError: <urlopen error _ssl.c:703: The handshake operation timed out>

[INFO] (1assl) This package is up to date.
[INFO] (1build) This package is up to date.
[INFO] (1c-utilites) This package is up to date.
[INFO] (1dyfolabs-test-script) This package is up to date.
[INFO] (1ee) This package is up to date.
[INFO] (1nester) This package is up to date.
[INFO] (1pass) This package is up to date.
[INFO] (1st) This package is up to date.
[INFO] (1to001) This package is up to date.
[ERROR] (2) Could not get a response from API for this package. See below for details.
Traceback (most recent call last):
  File "/usr/local/lib/python3.5/dist-packages/pypicontents/api/pypi.py", line 264, in get_pkgdata
    timeout=10).read()
  File "/usr/lib/python3.5/urllib/request.py", line 163, in urlopen
    return opener.open(url, data, timeout)
  File "/usr/lib/python3.5/urllib/request.py", line 472, in open
    response = meth(req, response)
  File "/usr/lib/python3.5/urllib/request.py", line 582, in http_response
    'http', request, response, code, msg, hdrs)
  File "/usr/lib/python3.5/urllib/request.py", line 510, in error
    return self._call_chain(*args)
  File "/usr/lib/python3.5/urllib/request.py", line 444, in _call_chain
    result = func(*args)
  File "/usr/lib/python3.5/urllib/request.py", line 590, in http_error_default
    raise HTTPError(req.full_url, code, msg, hdrs, fp)
urllib.error.HTTPError: HTTP Error 404: Not Found

[INFO] (2008webcrawler) This package is up to date.
[ERROR] (2013007-pyh) Could not get a response from API for this package. See below for details.
Traceback (most recent call last):
  File "/usr/lib/python3.5/urllib/request.py", line 1254, in do_open
    h.request(req.get_method(), req.selector, req.data, headers)
  File "/usr/lib/python3.5/http/client.py", line 1107, in request
    self._send_request(method, url, body, headers)
  File "/usr/lib/python3.5/http/client.py", line 1152, in _send_request
    self.endheaders(body)
  File "/usr/lib/python3.5/http/client.py", line 1103, in endheaders
    self._send_output(message_body)
  File "/usr/lib/python3.5/http/client.py", line 934, in _send_output
    self.send(msg)
  File "/usr/lib/python3.5/http/client.py", line 877, in send
    self.connect()
  File "/usr/lib/python3.5/http/client.py", line 1261, in connect
    server_hostname=server_hostname)
  File "/usr/lib/python3.5/ssl.py", line 385, in wrap_socket
    _context=self)
  File "/usr/lib/python3.5/ssl.py", line 760, in __init__
    self.do_handshake()
  File "/usr/lib/python3.5/ssl.py", line 996, in do_handshake
    self._sslobj.do_handshake()
  File "/usr/lib/python3.5/ssl.py", line 641, in do_handshake
    self._sslobj.do_handshake()
socket.timeout: _ssl.c:703: The handshake operation timed out

During handling of the above exception, another exception occurred:

Traceback (most recent call last):
  File "/usr/local/lib/python3.5/dist-packages/pypicontents/api/pypi.py", line 264, in get_pkgdata
    timeout=10).read()
  File "/usr/lib/python3.5/urllib/request.py", line 163, in urlopen
    return opener.open(url, data, timeout)
  File "/usr/lib/python3.5/urllib/request.py", line 466, in open
    response = self._open(req, data)
  File "/usr/lib/python3.5/urllib/request.py", line 484, in _open
    '_open', req)
  File "/usr/lib/python3.5/urllib/request.py", line 444, in _call_chain
    result = func(*args)
  File "/usr/lib/python3.5/urllib/request.py", line 1297, in https_open
    context=self._context, check_hostname=self._check_hostname)
  File "/usr/lib/python3.5/urllib/request.py", line 1256, in do_open
    raise URLError(err)
urllib.error.URLError: <urlopen error _ssl.c:703: The handshake operation timed out>

[INFO] (2048) This package is up to date.
[ERROR] (2112) Could not get a response from API for this package. See below for details.
Traceback (most recent call last):
  File "/usr/lib/python3.5/urllib/request.py", line 1254, in do_open
    h.request(req.get_method(), req.selector, req.data, headers)
  File "/usr/lib/python3.5/http/client.py", line 1107, in request
    self._send_request(method, url, body, headers)
  File "/usr/lib/python3.5/http/client.py", line 1152, in _send_request
    self.endheaders(body)
  File "/usr/lib/python3.5/http/client.py", line 1103, in endheaders
    self._send_output(message_body)
  File "/usr/lib/python3.5/http/client.py", line 934, in _send_output
    self.send(msg)
  File "/usr/lib/python3.5/http/client.py", line 877, in send
    self.connect()
  File "/usr/lib/python3.5/http/client.py", line 1261, in connect
    server_hostname=server_hostname)
  File "/usr/lib/python3.5/ssl.py", line 385, in wrap_socket
    _context=self)
  File "/usr/lib/python3.5/ssl.py", line 760, in __init__
    self.do_handshake()
  File "/usr/lib/python3.5/ssl.py", line 996, in do_handshake
    self._sslobj.do_handshake()
  File "/usr/lib/python3.5/ssl.py", line 641, in do_handshake
    self._sslobj.do_handshake()
socket.timeout: _ssl.c:703: The handshake operation timed out

During handling of the above exception, another exception occurred:

Traceback (most recent call last):
  File "/usr/local/lib/python3.5/dist-packages/pypicontents/api/pypi.py", line 264, in get_pkgdata
    timeout=10).read()
  File "/usr/lib/python3.5/urllib/request.py", line 163, in urlopen
    return opener.open(url, data, timeout)
  File "/usr/lib/python3.5/urllib/request.py", line 466, in open
    response = self._open(req, data)
  File "/usr/lib/python3.5/urllib/request.py", line 484, in _open
    '_open', req)
  File "/usr/lib/python3.5/urllib/request.py", line 444, in _call_chain
    result = func(*args)
  File "/usr/lib/python3.5/urllib/request.py", line 1297, in https_open
    context=self._context, check_hostname=self._check_hostname)
  File "/usr/lib/python3.5/urllib/request.py", line 1256, in do_open
    raise URLError(err)
urllib.error.URLError: <urlopen error _ssl.c:703: The handshake operation timed out>

[INFO] (23andme-to-vcf) This package is up to date.
[INFO] (24to25) This package is up to date.
[INFO] (2969nester) This package is up to date.
[ERROR] (2c-py) Could not extract data from this package. See below for details.
This package download URL does not point to a valid file: "http://code.google.com/p/2c-python/downloads/"
[ERROR] (2dfly-manbanzhen) Could not get a response from API for this package. See below for details.
Traceback (most recent call last):
  File "/usr/local/lib/python3.5/dist-packages/pypicontents/api/pypi.py", line 264, in get_pkgdata
    timeout=10).read()
  File "/usr/lib/python3.5/urllib/request.py", line 163, in urlopen
    return opener.open(url, data, timeout)
  File "/usr/lib/python3.5/urllib/request.py", line 472, in open
    response = meth(req, response)
  File "/usr/lib/python3.5/urllib/request.py", line 582, in http_response
    'http', request, response, code, msg, hdrs)
  File "/usr/lib/python3.5/urllib/request.py", line 510, in error
    return self._call_chain(*args)
  File "/usr/lib/python3.5/urllib/request.py", line 444, in _call_chain
    result = func(*args)
  File "/usr/lib/python3.5/urllib/request.py", line 590, in http_error_default
    raise HTTPError(req.full_url, code, msg, hdrs, fp)
urllib.error.HTTPError: HTTP Error 404: Not Found

[INFO] (2fa) This package is up to date.
[INFO] (2gis) This package is up to date.
[ERROR] (2jjtt6cwa6) This package does not have downloadable releases.
[ERROR] (2keys) Could not get a response from API for this package. See below for details.
Traceback (most recent call last):
  File "/usr/lib/python3.5/urllib/request.py", line 1254, in do_open
    h.request(req.get_method(), req.selector, req.data, headers)
  File "/usr/lib/python3.5/http/client.py", line 1107, in request
    self._send_request(method, url, body, headers)
  File "/usr/lib/python3.5/http/client.py", line 1152, in _send_request
    self.endheaders(body)
  File "/usr/lib/python3.5/http/client.py", line 1103, in endheaders
    self._send_output(message_body)
  File "/usr/lib/python3.5/http/client.py", line 934, in _send_output
    self.send(msg)
  File "/usr/lib/python3.5/http/client.py", line 877, in send
    self.connect()
  File "/usr/lib/python3.5/http/client.py", line 1261, in connect
    server_hostname=server_hostname)
  File "/usr/lib/python3.5/ssl.py", line 385, in wrap_socket
    _context=self)
  File "/usr/lib/python3.5/ssl.py", line 760, in __init__
    self.do_handshake()
  File "/usr/lib/python3.5/ssl.py", line 996, in do_handshake
    self._sslobj.do_handshake()
  File "/usr/lib/python3.5/ssl.py", line 641, in do_handshake
    self._sslobj.do_handshake()
socket.timeout: _ssl.c:703: The handshake operation timed out

During handling of the above exception, another exception occurred:

Traceback (most recent call last):
  File "/usr/local/lib/python3.5/dist-packages/pypicontents/api/pypi.py", line 264, in get_pkgdata
    timeout=10).read()
  File "/usr/lib/python3.5/urllib/request.py", line 163, in urlopen
    return opener.open(url, data, timeout)
  File "/usr/lib/python3.5/urllib/request.py", line 472, in open
    response = meth(req, response)
  File "/usr/lib/python3.5/urllib/request.py", line 582, in http_response
    'http', request, response, code, msg, hdrs)
  File "/usr/lib/python3.5/urllib/request.py", line 504, in error
    result = self._call_chain(*args)
  File "/usr/lib/python3.5/urllib/request.py", line 444, in _call_chain
    result = func(*args)
  File "/usr/lib/python3.5/urllib/request.py", line 696, in http_error_302
    return self.parent.open(new, timeout=req.timeout)
  File "/usr/lib/python3.5/urllib/request.py", line 466, in open
    response = self._open(req, data)
  File "/usr/lib/python3.5/urllib/request.py", line 484, in _open
    '_open', req)
  File "/usr/lib/python3.5/urllib/request.py", line 444, in _call_chain
    result = func(*args)
  File "/usr/lib/python3.5/urllib/request.py", line 1297, in https_open
    context=self._context, check_hostname=self._check_hostname)
  File "/usr/lib/python3.5/urllib/request.py", line 1256, in do_open
    raise URLError(err)
urllib.error.URLError: <urlopen error _ssl.c:703: The handshake operation timed out>

[INFO] (2lazy2rest) This package is up to date.
[INFO] (2mp3) This package is up to date.
[INFO] (2mp4) This package is up to date.
[INFO] (2or3) This package is up to date.
[INFO] (2to3) This package is up to date.
[INFO] (3) This package is up to date.
[INFO] (3-1) This package is up to date.
[INFO] (3049bab9) This package is up to date.
[INFO] (311devs-peewee) This package is up to date.
[INFO] (36-chambers) This package is up to date.
[ERROR] (36ban-commons) Could not get a response from API for this package. See below for details.
Traceback (most recent call last):
  File "/usr/lib/python3.5/urllib/request.py", line 1254, in do_open
    h.request(req.get_method(), req.selector, req.data, headers)
  File "/usr/lib/python3.5/http/client.py", line 1107, in request
    self._send_request(method, url, body, headers)
  File "/usr/lib/python3.5/http/client.py", line 1152, in _send_request
    self.endheaders(body)
  File "/usr/lib/python3.5/http/client.py", line 1103, in endheaders
    self._send_output(message_body)
  File "/usr/lib/python3.5/http/client.py", line 934, in _send_output
    self.send(msg)
  File "/usr/lib/python3.5/http/client.py", line 877, in send
    self.connect()
  File "/usr/lib/python3.5/http/client.py", line 1261, in connect
    server_hostname=server_hostname)
  File "/usr/lib/python3.5/ssl.py", line 385, in wrap_socket
    _context=self)
  File "/usr/lib/python3.5/ssl.py", line 760, in __init__
    self.do_handshake()
  File "/usr/lib/python3.5/ssl.py", line 996, in do_handshake
    self._sslobj.do_handshake()
  File "/usr/lib/python3.5/ssl.py", line 641, in do_handshake
    self._sslobj.do_handshake()
socket.timeout: _ssl.c:703: The handshake operation timed out

During handling of the above exception, another exception occurred:

Traceback (most recent call last):
  File "/usr/local/lib/python3.5/dist-packages/pypicontents/api/pypi.py", line 264, in get_pkgdata
    timeout=10).read()
  File "/usr/lib/python3.5/urllib/request.py", line 163, in urlopen
    return opener.open(url, data, timeout)
  File "/usr/lib/python3.5/urllib/request.py", line 466, in open
    response = self._open(req, data)
  File "/usr/lib/python3.5/urllib/request.py", line 484, in _open
    '_open', req)
  File "/usr/lib/python3.5/urllib/request.py", line 444, in _call_chain
    result = func(*args)
  File "/usr/lib/python3.5/urllib/request.py", line 1297, in https_open
    context=self._context, check_hostname=self._check_hostname)
  File "/usr/lib/python3.5/urllib/request.py", line 1256, in do_open
    raise URLError(err)
urllib.error.URLError: <urlopen error _ssl.c:703: The handshake operation timed out>

[ERROR] (36ke-py) Could not get a response from API for this package. See below for details.
Traceback (most recent call last):
  File "/usr/local/lib/python3.5/dist-packages/pypicontents/api/pypi.py", line 264, in get_pkgdata
    timeout=10).read()
  File "/usr/lib/python3.5/urllib/request.py", line 163, in urlopen
    return opener.open(url, data, timeout)
  File "/usr/lib/python3.5/urllib/request.py", line 472, in open
    response = meth(req, response)
  File "/usr/lib/python3.5/urllib/request.py", line 582, in http_response
    'http', request, response, code, msg, hdrs)
  File "/usr/lib/python3.5/urllib/request.py", line 504, in error
    result = self._call_chain(*args)
  File "/usr/lib/python3.5/urllib/request.py", line 444, in _call_chain
    result = func(*args)
  File "/usr/lib/python3.5/urllib/request.py", line 696, in http_error_302
    return self.parent.open(new, timeout=req.timeout)
  File "/usr/lib/python3.5/urllib/request.py", line 472, in open
    response = meth(req, response)
  File "/usr/lib/python3.5/urllib/request.py", line 582, in http_response
    'http', request, response, code, msg, hdrs)
  File "/usr/lib/python3.5/urllib/request.py", line 510, in error
    return self._call_chain(*args)
  File "/usr/lib/python3.5/urllib/request.py", line 444, in _call_chain
    result = func(*args)
  File "/usr/lib/python3.5/urllib/request.py", line 590, in http_error_default
    raise HTTPError(req.full_url, code, msg, hdrs, fp)
urllib.error.HTTPError: HTTP Error 404: Not Found

[INFO] (3890612457908641) This package is up to date.
[INFO] (392304jk324nkkl) This package is up to date.
[ERROR] (3color-press) This package does not have downloadable releases.
[ERROR] (3d-bin-container-packing) Could not get a response from API for this package. See below for details.
Traceback (most recent call last):
  File "/usr/local/lib/python3.5/dist-packages/pypicontents/api/pypi.py", line 264, in get_pkgdata
    timeout=10).read()
  File "/usr/lib/python3.5/urllib/request.py", line 163, in urlopen
    return opener.open(url, data, timeout)
  File "/usr/lib/python3.5/urllib/request.py", line 472, in open
    response = meth(req, response)
  File "/usr/lib/python3.5/urllib/request.py", line 582, in http_response
    'http', request, response, code, msg, hdrs)
  File "/usr/lib/python3.5/urllib/request.py", line 504, in error
    result = self._call_chain(*args)
  File "/usr/lib/python3.5/urllib/request.py", line 444, in _call_chain
    result = func(*args)
  File "/usr/lib/python3.5/urllib/request.py", line 696, in http_error_302
    return self.parent.open(new, timeout=req.timeout)
  File "/usr/lib/python3.5/urllib/request.py", line 472, in open
    response = meth(req, response)
  File "/usr/lib/python3.5/urllib/request.py", line 582, in http_response
    'http', request, response, code, msg, hdrs)
  File "/usr/lib/python3.5/urllib/request.py", line 510, in error
    return self._call_chain(*args)
  File "/usr/lib/python3.5/urllib/request.py", line 444, in _call_chain
    result = func(*args)
  File "/usr/lib/python3.5/urllib/request.py", line 590, in http_error_default
    raise HTTPError(req.full_url, code, msg, hdrs, fp)
urllib.error.HTTPError: HTTP Error 404: Not Found

[INFO] (3d-wallet-generator) This package is up to date.
[INFO] (3debt) This package is up to date.
[INFO] (3dfunctiongrapher) This package is up to date.
[ERROR] (3edit) Could not get a response from API for this package. See below for details.
Traceback (most recent call last):
  File "/usr/lib/python3.5/urllib/request.py", line 1254, in do_open
    h.request(req.get_method(), req.selector, req.data, headers)
  File "/usr/lib/python3.5/http/client.py", line 1107, in request
    self._send_request(method, url, body, headers)
  File "/usr/lib/python3.5/http/client.py", line 1152, in _send_request
    self.endheaders(body)
  File "/usr/lib/python3.5/http/client.py", line 1103, in endheaders
    self._send_output(message_body)
  File "/usr/lib/python3.5/http/client.py", line 934, in _send_output
    self.send(msg)
  File "/usr/lib/python3.5/http/client.py", line 877, in send
    self.connect()
  File "/usr/lib/python3.5/http/client.py", line 1261, in connect
    server_hostname=server_hostname)
  File "/usr/lib/python3.5/ssl.py", line 385, in wrap_socket
    _context=self)
  File "/usr/lib/python3.5/ssl.py", line 760, in __init__
    self.do_handshake()
  File "/usr/lib/python3.5/ssl.py", line 996, in do_handshake
    self._sslobj.do_handshake()
  File "/usr/lib/python3.5/ssl.py", line 641, in do_handshake
    self._sslobj.do_handshake()
socket.timeout: _ssl.c:703: The handshake operation timed out

During handling of the above exception, another exception occurred:

Traceback (most recent call last):
  File "/usr/local/lib/python3.5/dist-packages/pypicontents/api/pypi.py", line 264, in get_pkgdata
    timeout=10).read()
  File "/usr/lib/python3.5/urllib/request.py", line 163, in urlopen
    return opener.open(url, data, timeout)
  File "/usr/lib/python3.5/urllib/request.py", line 466, in open
    response = self._open(req, data)
  File "/usr/lib/python3.5/urllib/request.py", line 484, in _open
    '_open', req)
  File "/usr/lib/python3.5/urllib/request.py", line 444, in _call_chain
    result = func(*args)
  File "/usr/lib/python3.5/urllib/request.py", line 1297, in https_open
    context=self._context, check_hostname=self._check_hostname)
  File "/usr/lib/python3.5/urllib/request.py", line 1256, in do_open
    raise URLError(err)
urllib.error.URLError: <urlopen error _ssl.c:703: The handshake operation timed out>

[INFO] (3gpp-citations) This package is up to date.
[INFO] (3lwg) This package is up to date.
[ERROR] (3t) This package does not have downloadable releases.
[INFO] (3to2) This package is up to date.
[INFO] (3to2-py3k) This package is up to date.
[INFO] (3xsd) This package is up to date.
[INFO] (40wt-common-tasks) This package is up to date.
[ERROR] (42) This package does not have downloadable releases.
[INFO] (42cc-pystyle) This package is up to date.
[INFO] (42qucc) This package is up to date.
[INFO] (440-create-user) This package is up to date.
[ERROR] (4cdl) Could not get a response from API for this package. See below for details.
Traceback (most recent call last):
  File "/usr/lib/python3.5/urllib/request.py", line 1254, in do_open
    h.request(req.get_method(), req.selector, req.data, headers)
  File "/usr/lib/python3.5/http/client.py", line 1107, in request
    self._send_request(method, url, body, headers)
  File "/usr/lib/python3.5/http/client.py", line 1152, in _send_request
    self.endheaders(body)
  File "/usr/lib/python3.5/http/client.py", line 1103, in endheaders
    self._send_output(message_body)
  File "/usr/lib/python3.5/http/client.py", line 934, in _send_output
    self.send(msg)
  File "/usr/lib/python3.5/http/client.py", line 877, in send
    self.connect()
  File "/usr/lib/python3.5/http/client.py", line 1261, in connect
    server_hostname=server_hostname)
  File "/usr/lib/python3.5/ssl.py", line 385, in wrap_socket
    _context=self)
  File "/usr/lib/python3.5/ssl.py", line 760, in __init__
    self.do_handshake()
  File "/usr/lib/python3.5/ssl.py", line 996, in do_handshake
    self._sslobj.do_handshake()
  File "/usr/lib/python3.5/ssl.py", line 641, in do_handshake
    self._sslobj.do_handshake()
socket.timeout: _ssl.c:703: The handshake operation timed out

During handling of the above exception, another exception occurred:

Traceback (most recent call last):
  File "/usr/local/lib/python3.5/dist-packages/pypicontents/api/pypi.py", line 264, in get_pkgdata
    timeout=10).read()
  File "/usr/lib/python3.5/urllib/request.py", line 163, in urlopen
    return opener.open(url, data, timeout)
  File "/usr/lib/python3.5/urllib/request.py", line 466, in open
    response = self._open(req, data)
  File "/usr/lib/python3.5/urllib/request.py", line 484, in _open
    '_open', req)
  File "/usr/lib/python3.5/urllib/request.py", line 444, in _call_chain
    result = func(*args)
  File "/usr/lib/python3.5/urllib/request.py", line 1297, in https_open
    context=self._context, check_hostname=self._check_hostname)
  File "/usr/lib/python3.5/urllib/request.py", line 1256, in do_open
    raise URLError(err)
urllib.error.URLError: <urlopen error _ssl.c:703: The handshake operation timed out>

[INFO] (4ch) This package is up to date.
[INFO] (4chan) This package is up to date.
[INFO] (4chandownloader) This package is up to date.
[INFO] (4scanner) This package is up to date.
[ERROR] (4suite) This package does not have downloadable releases.
[INFO] (4suite-xml) This package is up to date.
[ERROR] (5) Could not get a response from API for this package. See below for details.
Traceback (most recent call last):
  File "/usr/lib/python3.5/urllib/request.py", line 1254, in do_open
    h.request(req.get_method(), req.selector, req.data, headers)
  File "/usr/lib/python3.5/http/client.py", line 1107, in request
    self._send_request(method, url, body, headers)
  File "/usr/lib/python3.5/http/client.py", line 1152, in _send_request
    self.endheaders(body)
  File "/usr/lib/python3.5/http/client.py", line 1103, in endheaders
    self._send_output(message_body)
  File "/usr/lib/python3.5/http/client.py", line 934, in _send_output
    self.send(msg)
  File "/usr/lib/python3.5/http/client.py", line 877, in send
    self.connect()
  File "/usr/lib/python3.5/http/client.py", line 1261, in connect
    server_hostname=server_hostname)
  File "/usr/lib/python3.5/ssl.py", line 385, in wrap_socket
    _context=self)
  File "/usr/lib/python3.5/ssl.py", line 760, in __init__
    self.do_handshake()
  File "/usr/lib/python3.5/ssl.py", line 996, in do_handshake
    self._sslobj.do_handshake()
  File "/usr/lib/python3.5/ssl.py", line 641, in do_handshake
    self._sslobj.do_handshake()
socket.timeout: _ssl.c:703: The handshake operation timed out

During handling of the above exception, another exception occurred:

Traceback (most recent call last):
  File "/usr/local/lib/python3.5/dist-packages/pypicontents/api/pypi.py", line 264, in get_pkgdata
    timeout=10).read()
  File "/usr/lib/python3.5/urllib/request.py", line 163, in urlopen
    return opener.open(url, data, timeout)
  File "/usr/lib/python3.5/urllib/request.py", line 466, in open
    response = self._open(req, data)
  File "/usr/lib/python3.5/urllib/request.py", line 484, in _open
    '_open', req)
  File "/usr/lib/python3.5/urllib/request.py", line 444, in _call_chain
    result = func(*args)
  File "/usr/lib/python3.5/urllib/request.py", line 1297, in https_open
    context=self._context, check_hostname=self._check_hostname)
  File "/usr/lib/python3.5/urllib/request.py", line 1256, in do_open
    raise URLError(err)
urllib.error.URLError: <urlopen error _ssl.c:703: The handshake operation timed out>

[INFO] (51degrees-mobile-detector) This package is up to date.
[INFO] (51degrees-mobile-detector-lite-pattern-wrapper) This package is up to date.
[INFO] (51degrees-mobile-detector-trie-wrapper) This package is up to date.
[INFO] (51degrees-mobile-detector-v3-trie-wrapper) This package is up to date.
[INFO] (51degrees-mobile-detector-v3-wrapper) This package is up to date.
[INFO] (51pub-pymodules) This package is up to date.
[ERROR] (51pubmodules) Could not get a response from API for this package. See below for details.
Traceback (most recent call last):
  File "/usr/lib/python3.5/urllib/request.py", line 1254, in do_open
    h.request(req.get_method(), req.selector, req.data, headers)
  File "/usr/lib/python3.5/http/client.py", line 1107, in request
    self._send_request(method, url, body, headers)
  File "/usr/lib/python3.5/http/client.py", line 1152, in _send_request
    self.endheaders(body)
  File "/usr/lib/python3.5/http/client.py", line 1103, in endheaders
    self._send_output(message_body)
  File "/usr/lib/python3.5/http/client.py", line 934, in _send_output
    self.send(msg)
  File "/usr/lib/python3.5/http/client.py", line 877, in send
    self.connect()
  File "/usr/lib/python3.5/http/client.py", line 1261, in connect
    server_hostname=server_hostname)
  File "/usr/lib/python3.5/ssl.py", line 385, in wrap_socket
    _context=self)
  File "/usr/lib/python3.5/ssl.py", line 760, in __init__
    self.do_handshake()
  File "/usr/lib/python3.5/ssl.py", line 996, in do_handshake
    self._sslobj.do_handshake()
  File "/usr/lib/python3.5/ssl.py", line 641, in do_handshake
    self._sslobj.do_handshake()
socket.timeout: _ssl.c:703: The handshake operation timed out

During handling of the above exception, another exception occurred:

Traceback (most recent call last):
  File "/usr/local/lib/python3.5/dist-packages/pypicontents/api/pypi.py", line 264, in get_pkgdata
    timeout=10).read()
  File "/usr/lib/python3.5/urllib/request.py", line 163, in urlopen
    return opener.open(url, data, timeout)
  File "/usr/lib/python3.5/urllib/request.py", line 472, in open
    response = meth(req, response)
  File "/usr/lib/python3.5/urllib/request.py", line 582, in http_response
    'http', request, response, code, msg, hdrs)
  File "/usr/lib/python3.5/urllib/request.py", line 504, in error
    result = self._call_chain(*args)
  File "/usr/lib/python3.5/urllib/request.py", line 444, in _call_chain
    result = func(*args)
  File "/usr/lib/python3.5/urllib/request.py", line 696, in http_error_302
    return self.parent.open(new, timeout=req.timeout)
  File "/usr/lib/python3.5/urllib/request.py", line 466, in open
    response = self._open(req, data)
  File "/usr/lib/python3.5/urllib/request.py", line 484, in _open
    '_open', req)
  File "/usr/lib/python3.5/urllib/request.py", line 444, in _call_chain
    result = func(*args)
  File "/usr/lib/python3.5/urllib/request.py", line 1297, in https_open
    context=self._context, check_hostname=self._check_hostname)
  File "/usr/lib/python3.5/urllib/request.py", line 1256, in do_open
    raise URLError(err)
urllib.error.URLError: <urlopen error _ssl.c:703: The handshake operation timed out>

[INFO] (5minute) This package is up to date.
[INFO] (5o4drel5mk) This package is up to date.
[INFO] (652ga) This package is up to date.
[INFO] (69) This package is up to date.
[INFO] (7) This package is up to date.
[ERROR] (73-portlet-links) This package does not have downloadable releases.
[ERROR] (73-unlockitems) Could not get a response from API for this package. See below for details.
Traceback (most recent call last):
  File "/usr/lib/python3.5/urllib/request.py", line 1254, in do_open
    h.request(req.get_method(), req.selector, req.data, headers)
  File "/usr/lib/python3.5/http/client.py", line 1107, in request
    self._send_request(method, url, body, headers)
  File "/usr/lib/python3.5/http/client.py", line 1152, in _send_request
    self.endheaders(body)
  File "/usr/lib/python3.5/http/client.py", line 1103, in endheaders
    self._send_output(message_body)
  File "/usr/lib/python3.5/http/client.py", line 934, in _send_output
    self.send(msg)
  File "/usr/lib/python3.5/http/client.py", line 877, in send
    self.connect()
  File "/usr/lib/python3.5/http/client.py", line 1261, in connect
    server_hostname=server_hostname)
  File "/usr/lib/python3.5/ssl.py", line 385, in wrap_socket
    _context=self)
  File "/usr/lib/python3.5/ssl.py", line 760, in __init__
    self.do_handshake()
  File "/usr/lib/python3.5/ssl.py", line 996, in do_handshake
    self._sslobj.do_handshake()
  File "/usr/lib/python3.5/ssl.py", line 641, in do_handshake
    self._sslobj.do_handshake()
socket.timeout: _ssl.c:703: The handshake operation timed out

During handling of the above exception, another exception occurred:

Traceback (most recent call last):
  File "/usr/local/lib/python3.5/dist-packages/pypicontents/api/pypi.py", line 264, in get_pkgdata
    timeout=10).read()
  File "/usr/lib/python3.5/urllib/request.py", line 163, in urlopen
    return opener.open(url, data, timeout)
  File "/usr/lib/python3.5/urllib/request.py", line 472, in open
    response = meth(req, response)
  File "/usr/lib/python3.5/urllib/request.py", line 582, in http_response
    'http', request, response, code, msg, hdrs)
  File "/usr/lib/python3.5/urllib/request.py", line 504, in error
    result = self._call_chain(*args)
  File "/usr/lib/python3.5/urllib/request.py", line 444, in _call_chain
    result = func(*args)
  File "/usr/lib/python3.5/urllib/request.py", line 696, in http_error_302
    return self.parent.open(new, timeout=req.timeout)
  File "/usr/lib/python3.5/urllib/request.py", line 466, in open
    response = self._open(req, data)
  File "/usr/lib/python3.5/urllib/request.py", line 484, in _open
    '_open', req)
  File "/usr/lib/python3.5/urllib/request.py", line 444, in _call_chain
    result = func(*args)
  File "/usr/lib/python3.5/urllib/request.py", line 1297, in https_open
    context=self._context, check_hostname=self._check_hostname)
  File "/usr/lib/python3.5/urllib/request.py", line 1256, in do_open
    raise URLError(err)
urllib.error.URLError: <urlopen error _ssl.c:703: The handshake operation timed out>

[INFO] (7i96) This package is up to date.
[INFO] (7lk-ocr-deploy) This package is up to date.
[ERROR] (7q-nester) This package does not have downloadable releases.
[INFO] (7th) This package is up to date.
[INFO] (7xydothis) This package is up to date.
[ERROR] (908dist) Could not get a response from API for this package. See below for details.
Traceback (most recent call last):
  File "/usr/lib/python3.5/urllib/request.py", line 1254, in do_open
    h.request(req.get_method(), req.selector, req.data, headers)
  File "/usr/lib/python3.5/http/client.py", line 1107, in request
    self._send_request(method, url, body, headers)
  File "/usr/lib/python3.5/http/client.py", line 1152, in _send_request
    self.endheaders(body)
  File "/usr/lib/python3.5/http/client.py", line 1103, in endheaders
    self._send_output(message_body)
  File "/usr/lib/python3.5/http/client.py", line 934, in _send_output
    self.send(msg)
  File "/usr/lib/python3.5/http/client.py", line 877, in send
    self.connect()
  File "/usr/lib/python3.5/http/client.py", line 1261, in connect
    server_hostname=server_hostname)
  File "/usr/lib/python3.5/ssl.py", line 385, in wrap_socket
    _context=self)
  File "/usr/lib/python3.5/ssl.py", line 760, in __init__
    self.do_handshake()
  File "/usr/lib/python3.5/ssl.py", line 996, in do_handshake
    self._sslobj.do_handshake()
  File "/usr/lib/python3.5/ssl.py", line 641, in do_handshake
    self._sslobj.do_handshake()
socket.timeout: _ssl.c:703: The handshake operation timed out

During handling of the above exception, another exception occurred:

Traceback (most recent call last):
  File "/usr/local/lib/python3.5/dist-packages/pypicontents/api/pypi.py", line 264, in get_pkgdata
    timeout=10).read()
  File "/usr/lib/python3.5/urllib/request.py", line 163, in urlopen
    return opener.open(url, data, timeout)
  File "/usr/lib/python3.5/urllib/request.py", line 466, in open
    response = self._open(req, data)
  File "/usr/lib/python3.5/urllib/request.py", line 484, in _open
    '_open', req)
  File "/usr/lib/python3.5/urllib/request.py", line 444, in _call_chain
    result = func(*args)
  File "/usr/lib/python3.5/urllib/request.py", line 1297, in https_open
    context=self._context, check_hostname=self._check_hostname)
  File "/usr/lib/python3.5/urllib/request.py", line 1256, in do_open
    raise URLError(err)
urllib.error.URLError: <urlopen error _ssl.c:703: The handshake operation timed out>

[INFO] (91downloader) This package is up to date.
[INFO] (99d4aa80-d846-424f-873b-a02c7215fc54) This package is up to date.
[INFO] 
[INFO] 
[INFO] Total packages: 128
[INFO]     Packages processed: 128
[INFO]         Packages updated: 1
[INFO]         Packages up-to-date: 93
[INFO]         Packages without response: 21
[INFO]         Packages without urls: 0
[INFO]         Packages without downloads: 12
[INFO]         Packages with data errors: 1
[INFO]     Packages not processed: 0
[INFO] 
[INFO] 
[INFO] Ending execution.
