[INFO] Starting execution.
[INFO] Downloading package list from PyPI ...
[ERROR] (m) This package does not have downloadable releases.
[INFO] (m-caching) This package is up to date.
[INFO] (m-lib) This package is up to date.
[INFO] (m-lib-defenc) This package is up to date.
[INFO] (m-lib-full) This package is up to date.
[INFO] (m-librarian) This package is up to date.
[INFO] (m-license) This package is up to date.
[INFO] (m-loop) This package is up to date.
[INFO] (m-monitor) This package is up to date.
[INFO] (m-nester) This package is up to date.
[INFO] (m-phate) This package is up to date.
[INFO] (m-pool) This package is up to date.
[INFO] (m-robot) This package is up to date.
[INFO] (m-schedule) This package is up to date.
[INFO] (m-singleton) This package is up to date.
[INFO] (m-stats) This package is up to date.
[INFO] (m-threadpool) This package is up to date.
[INFO] (m-transliteration) This package is up to date.
[INFO] (m-validator) This package is up to date.
[INFO] (m01-bayes) This package is up to date.
[INFO] (m01-fake) This package is up to date.
[INFO] (m01-form) This package is up to date.
[INFO] (m01-fs) This package is up to date.
[INFO] (m01-gmap) This package is up to date.
[INFO] (m01-grid) This package is up to date.
[INFO] (m01-i18n) This package is up to date.
[INFO] (m01-logger) This package is up to date.
[INFO] (m01-mongo) This package is up to date.
[INFO] (m01-mongofake) This package is up to date.
[INFO] (m01-publisher) This package is up to date.
[INFO] (m01-remote) This package is up to date.
[INFO] (m01-searcher) This package is up to date.
[INFO] (m01-session) This package is up to date.
[INFO] (m01-stub) This package is up to date.
[INFO] (m01-zfs) This package is up to date.
[INFO] (m1-8-writer) This package is up to date.
[INFO] (m10s) This package is up to date.
[INFO] (m14) This package is up to date.
[INFO] (m16-mlutils) This package is up to date.
[ERROR] (m209) This package does not have downloadable releases.
[INFO] (m26) This package is up to date.
[INFO] (m2bk) This package is up to date.
[INFO] (m2c) This package is up to date.
[INFO] (m2cgen) This package is up to date.
[INFO] (m2controller) This package is up to date.
[INFO] (m2core) This package is up to date.
[INFO] (m2crypto) This package is up to date.
[INFO] (m2cryptowin32) This package is up to date.
[INFO] (m2cryptowin64) This package is up to date.
[INFO] (m2dp) This package is up to date.
[INFO] (m2ext) This package is up to date.
[INFO] (m2m-certificates) This package is up to date.
[INFO] (m2mclient) This package is up to date.
[ERROR] (m2mdata) This package does not have downloadable releases.
[ERROR] (m2mdict) Could not get a response from API for this package. See below for details.
Traceback (most recent call last):
  File "/usr/lib/python3.7/urllib/request.py", line 1319, in do_open
    encode_chunked=req.has_header('Transfer-encoding'))
  File "/usr/lib/python3.7/http/client.py", line 1252, in request
    self._send_request(method, url, body, headers, encode_chunked)
  File "/usr/lib/python3.7/http/client.py", line 1298, in _send_request
    self.endheaders(body, encode_chunked=encode_chunked)
  File "/usr/lib/python3.7/http/client.py", line 1247, in endheaders
    self._send_output(message_body, encode_chunked=encode_chunked)
  File "/usr/lib/python3.7/http/client.py", line 1026, in _send_output
    self.send(msg)
  File "/usr/lib/python3.7/http/client.py", line 966, in send
    self.connect()
  File "/usr/lib/python3.7/http/client.py", line 1414, in connect
    super().connect()
  File "/usr/lib/python3.7/http/client.py", line 938, in connect
    (self.host,self.port), self.timeout, self.source_address)
  File "/usr/lib/python3.7/socket.py", line 707, in create_connection
    for res in getaddrinfo(host, port, 0, SOCK_STREAM):
  File "/usr/lib/python3.7/socket.py", line 752, in getaddrinfo
    for res in _socket.getaddrinfo(host, port, family, type, proto, flags):
socket.gaierror: [Errno -3] Temporary failure in name resolution

During handling of the above exception, another exception occurred:

Traceback (most recent call last):
  File "/usr/local/lib/python3.7/dist-packages/pypicontents/api/pypi.py", line 264, in get_pkgdata
    timeout=10).read()
  File "/usr/lib/python3.7/urllib/request.py", line 222, in urlopen
    return opener.open(url, data, timeout)
  File "/usr/lib/python3.7/urllib/request.py", line 525, in open
    response = self._open(req, data)
  File "/usr/lib/python3.7/urllib/request.py", line 543, in _open
    '_open', req)
  File "/usr/lib/python3.7/urllib/request.py", line 503, in _call_chain
    result = func(*args)
  File "/usr/lib/python3.7/urllib/request.py", line 1362, in https_open
    context=self._context, check_hostname=self._check_hostname)
  File "/usr/lib/python3.7/urllib/request.py", line 1321, in do_open
    raise URLError(err)
urllib.error.URLError: <urlopen error [Errno -3] Temporary failure in name resolution>

[INFO] (m2r) This package is up to date.
[INFO] (m2rr) This package is up to date.
[INFO] (m2secret) This package is up to date.
[INFO] (m2secret-py3) This package is up to date.
[ERROR] (m2tool) This package does not have downloadable releases.
[INFO] (m2tools) This package is up to date.
[INFO] (m2translate) This package is up to date.
[INFO] (m2websocket) This package is up to date.
[INFO] (m2wsgi) This package is up to date.
[INFO] (m2wsgid) This package is up to date.
[INFO] (m2x) This package is up to date.
[INFO] (m2x-mqtt) This package is up to date.
[INFO] (m3) This package is up to date.
[ERROR] (m3-aspell-python) Could not get a response from API for this package. See below for details.
Traceback (most recent call last):
  File "/usr/lib/python3.7/urllib/request.py", line 1319, in do_open
    encode_chunked=req.has_header('Transfer-encoding'))
  File "/usr/lib/python3.7/http/client.py", line 1252, in request
    self._send_request(method, url, body, headers, encode_chunked)
  File "/usr/lib/python3.7/http/client.py", line 1298, in _send_request
    self.endheaders(body, encode_chunked=encode_chunked)
  File "/usr/lib/python3.7/http/client.py", line 1247, in endheaders
    self._send_output(message_body, encode_chunked=encode_chunked)
  File "/usr/lib/python3.7/http/client.py", line 1026, in _send_output
    self.send(msg)
  File "/usr/lib/python3.7/http/client.py", line 966, in send
    self.connect()
  File "/usr/lib/python3.7/http/client.py", line 1414, in connect
    super().connect()
  File "/usr/lib/python3.7/http/client.py", line 938, in connect
    (self.host,self.port), self.timeout, self.source_address)
  File "/usr/lib/python3.7/socket.py", line 728, in create_connection
    raise err
  File "/usr/lib/python3.7/socket.py", line 716, in create_connection
    sock.connect(sa)
OSError: [Errno 99] Cannot assign requested address

During handling of the above exception, another exception occurred:

Traceback (most recent call last):
  File "/usr/local/lib/python3.7/dist-packages/pypicontents/api/pypi.py", line 264, in get_pkgdata
    timeout=10).read()
  File "/usr/lib/python3.7/urllib/request.py", line 222, in urlopen
    return opener.open(url, data, timeout)
  File "/usr/lib/python3.7/urllib/request.py", line 525, in open
    response = self._open(req, data)
  File "/usr/lib/python3.7/urllib/request.py", line 543, in _open
    '_open', req)
  File "/usr/lib/python3.7/urllib/request.py", line 503, in _call_chain
    result = func(*args)
  File "/usr/lib/python3.7/urllib/request.py", line 1362, in https_open
    context=self._context, check_hostname=self._check_hostname)
  File "/usr/lib/python3.7/urllib/request.py", line 1321, in do_open
    raise URLError(err)
urllib.error.URLError: <urlopen error [Errno 99] Cannot assign requested address>

[INFO] (m3-asynctask) This package is up to date.
[INFO] (m3-audit) This package is up to date.
[INFO] (m3-autologin) This package is up to date.
[INFO] (m3-calendar) This package is up to date.
[INFO] (m3-cdecimal) This package is up to date.
[INFO] (m3-checkie) This package is up to date.
[INFO] (m3-consolequery) This package is up to date.
[ERROR] (m3-core) Could not get a response from API for this package. See below for details.
Traceback (most recent call last):
  File "/usr/lib/python3.7/urllib/request.py", line 1319, in do_open
    encode_chunked=req.has_header('Transfer-encoding'))
  File "/usr/lib/python3.7/http/client.py", line 1252, in request
    self._send_request(method, url, body, headers, encode_chunked)
  File "/usr/lib/python3.7/http/client.py", line 1298, in _send_request
    self.endheaders(body, encode_chunked=encode_chunked)
  File "/usr/lib/python3.7/http/client.py", line 1247, in endheaders
    self._send_output(message_body, encode_chunked=encode_chunked)
  File "/usr/lib/python3.7/http/client.py", line 1026, in _send_output
    self.send(msg)
  File "/usr/lib/python3.7/http/client.py", line 966, in send
    self.connect()
  File "/usr/lib/python3.7/http/client.py", line 1414, in connect
    super().connect()
  File "/usr/lib/python3.7/http/client.py", line 938, in connect
    (self.host,self.port), self.timeout, self.source_address)
  File "/usr/lib/python3.7/socket.py", line 707, in create_connection
    for res in getaddrinfo(host, port, 0, SOCK_STREAM):
  File "/usr/lib/python3.7/socket.py", line 752, in getaddrinfo
    for res in _socket.getaddrinfo(host, port, family, type, proto, flags):
socket.gaierror: [Errno -3] Temporary failure in name resolution

During handling of the above exception, another exception occurred:

Traceback (most recent call last):
  File "/usr/local/lib/python3.7/dist-packages/pypicontents/api/pypi.py", line 264, in get_pkgdata
    timeout=10).read()
  File "/usr/lib/python3.7/urllib/request.py", line 222, in urlopen
    return opener.open(url, data, timeout)
  File "/usr/lib/python3.7/urllib/request.py", line 525, in open
    response = self._open(req, data)
  File "/usr/lib/python3.7/urllib/request.py", line 543, in _open
    '_open', req)
  File "/usr/lib/python3.7/urllib/request.py", line 503, in _call_chain
    result = func(*args)
  File "/usr/lib/python3.7/urllib/request.py", line 1362, in https_open
    context=self._context, check_hostname=self._check_hostname)
  File "/usr/lib/python3.7/urllib/request.py", line 1321, in do_open
    raise URLError(err)
urllib.error.URLError: <urlopen error [Errno -3] Temporary failure in name resolution>

[INFO] (m3-datalogging) This package is up to date.
[INFO] (m3-dbfpy) This package is up to date.
[INFO] (m3-debuggie) This package is up to date.
[INFO] (m3-designer) This package is up to date.
[INFO] (m3-dicts) This package is up to date.
[INFO] (m3-email) This package is up to date.
[INFO] (m3-excel-reporting) This package is up to date.
[INFO] (m3-fias) This package is up to date.
[INFO] (m3-kladr) This package is up to date.
[INFO] (m3-legacy) This package is up to date.
[INFO] (m3-libsmev) This package is up to date.
[INFO] (m3-libxml2-python) This package is up to date.
[INFO] (m3-license) This package is up to date.
[INFO] (m3-logview) This package is up to date.
[INFO] (m3-mutex) This package is up to date.
[INFO] (m3-next) This package is up to date.
[INFO] (m3-objectpack) This package is up to date.
[ERROR] (m3-pil) Could not get a response from API for this package. See below for details.
Traceback (most recent call last):
  File "/usr/lib/python3.7/urllib/request.py", line 1319, in do_open
    encode_chunked=req.has_header('Transfer-encoding'))
  File "/usr/lib/python3.7/http/client.py", line 1252, in request
    self._send_request(method, url, body, headers, encode_chunked)
  File "/usr/lib/python3.7/http/client.py", line 1298, in _send_request
    self.endheaders(body, encode_chunked=encode_chunked)
  File "/usr/lib/python3.7/http/client.py", line 1247, in endheaders
    self._send_output(message_body, encode_chunked=encode_chunked)
  File "/usr/lib/python3.7/http/client.py", line 1026, in _send_output
    self.send(msg)
  File "/usr/lib/python3.7/http/client.py", line 966, in send
    self.connect()
  File "/usr/lib/python3.7/http/client.py", line 1414, in connect
    super().connect()
  File "/usr/lib/python3.7/http/client.py", line 938, in connect
    (self.host,self.port), self.timeout, self.source_address)
  File "/usr/lib/python3.7/socket.py", line 707, in create_connection
    for res in getaddrinfo(host, port, 0, SOCK_STREAM):
  File "/usr/lib/python3.7/socket.py", line 752, in getaddrinfo
    for res in _socket.getaddrinfo(host, port, family, type, proto, flags):
socket.gaierror: [Errno -3] Temporary failure in name resolution

During handling of the above exception, another exception occurred:

Traceback (most recent call last):
  File "/usr/local/lib/python3.7/dist-packages/pypicontents/api/pypi.py", line 264, in get_pkgdata
    timeout=10).read()
  File "/usr/lib/python3.7/urllib/request.py", line 222, in urlopen
    return opener.open(url, data, timeout)
  File "/usr/lib/python3.7/urllib/request.py", line 531, in open
    response = meth(req, response)
  File "/usr/lib/python3.7/urllib/request.py", line 641, in http_response
    'http', request, response, code, msg, hdrs)
  File "/usr/lib/python3.7/urllib/request.py", line 563, in error
    result = self._call_chain(*args)
  File "/usr/lib/python3.7/urllib/request.py", line 503, in _call_chain
    result = func(*args)
  File "/usr/lib/python3.7/urllib/request.py", line 755, in http_error_302
    return self.parent.open(new, timeout=req.timeout)
  File "/usr/lib/python3.7/urllib/request.py", line 525, in open
    response = self._open(req, data)
  File "/usr/lib/python3.7/urllib/request.py", line 543, in _open
    '_open', req)
  File "/usr/lib/python3.7/urllib/request.py", line 503, in _call_chain
    result = func(*args)
  File "/usr/lib/python3.7/urllib/request.py", line 1362, in https_open
    context=self._context, check_hostname=self._check_hostname)
  File "/usr/lib/python3.7/urllib/request.py", line 1321, in do_open
    raise URLError(err)
urllib.error.URLError: <urlopen error [Errno -3] Temporary failure in name resolution>

[INFO] (m3-pushme) This package is up to date.
[INFO] (m3-recordpack) This package is up to date.
[INFO] (m3-registry) This package is up to date.
[INFO] (m3-report-generator) This package is up to date.
[INFO] (m3-simple-report) This package is up to date.
[INFO] (m3-soap) This package is up to date.
[INFO] (m3-spyne-smev) This package is up to date.
[INFO] (m3-ssosp) This package is up to date.
[INFO] (m3-task-scheduler) This package is up to date.
[INFO] (m3-ui) This package is up to date.
[INFO] (m3-users) This package is up to date.
[INFO] (m3-wellbehaved) This package is up to date.
[INFO] (m3-xmldsig) This package is up to date.
[INFO] (m3-zsi) This package is up to date.
[INFO] (m30w) This package is up to date.
[INFO] (m3cdecimal) This package is up to date.
[INFO] (m3core) This package is up to date.
[INFO] (m3d) This package is up to date.
[INFO] (m3inference) This package is up to date.
[INFO] (m3m3s) This package is up to date.
[INFO] (m3project-creator) This package is up to date.
[INFO] (m3s-scraper) This package is up to date.
[INFO] (m3tior-pyside2-style-test) This package is up to date.
[INFO] (m3u-dump) This package is up to date.
[INFO] (m3u8) This package is up to date.
[INFO] (m3u8-dl) This package is up to date.
[INFO] (m3u8-downloader) This package is up to date.
[INFO] (m3u8-generator) This package is up to date.
[INFO] (m3u8-video-downloader) This package is up to date.
[INFO] (m3u8downloader) This package is up to date.
[INFO] (m3u8tool) This package is up to date.
[INFO] (m3ull) This package is up to date.
[INFO] (m3ushuffler) This package is up to date.
[INFO] (m3uspiff) This package is up to date.
[INFO] (m3utorss) This package is up to date.
[INFO] (m4pomodoro) This package is up to date.
[INFO] (m4us) This package is up to date.
[INFO] (m5) This package is up to date.
[INFO] (m5expr) This package is up to date.
[ERROR] (m5fahrrad) This package does not have downloadable releases.
[INFO] (m5meta) This package is up to date.
[INFO] (m5pre) This package is up to date.
[INFO] (m6e-capnproto-sdk) This package is up to date.
[INFO] (m6e-graphql-sdk) This package is up to date.
[INFO] (m6e-grpc-sdk) This package is up to date.
[INFO] (m6e-openapi-sdk) This package is up to date.
[INFO] (m6e-swagger-sdk) This package is up to date.
[ERROR] (m6e-thrift-sdk) Could not get a response from API for this package. See below for details.
Traceback (most recent call last):
  File "/usr/lib/python3.7/urllib/request.py", line 1319, in do_open
    encode_chunked=req.has_header('Transfer-encoding'))
  File "/usr/lib/python3.7/http/client.py", line 1252, in request
    self._send_request(method, url, body, headers, encode_chunked)
  File "/usr/lib/python3.7/http/client.py", line 1298, in _send_request
    self.endheaders(body, encode_chunked=encode_chunked)
  File "/usr/lib/python3.7/http/client.py", line 1247, in endheaders
    self._send_output(message_body, encode_chunked=encode_chunked)
  File "/usr/lib/python3.7/http/client.py", line 1026, in _send_output
    self.send(msg)
  File "/usr/lib/python3.7/http/client.py", line 966, in send
    self.connect()
  File "/usr/lib/python3.7/http/client.py", line 1414, in connect
    super().connect()
  File "/usr/lib/python3.7/http/client.py", line 938, in connect
    (self.host,self.port), self.timeout, self.source_address)
  File "/usr/lib/python3.7/socket.py", line 707, in create_connection
    for res in getaddrinfo(host, port, 0, SOCK_STREAM):
  File "/usr/lib/python3.7/socket.py", line 752, in getaddrinfo
    for res in _socket.getaddrinfo(host, port, family, type, proto, flags):
socket.gaierror: [Errno -3] Temporary failure in name resolution

During handling of the above exception, another exception occurred:

Traceback (most recent call last):
  File "/usr/local/lib/python3.7/dist-packages/pypicontents/api/pypi.py", line 264, in get_pkgdata
    timeout=10).read()
  File "/usr/lib/python3.7/urllib/request.py", line 222, in urlopen
    return opener.open(url, data, timeout)
  File "/usr/lib/python3.7/urllib/request.py", line 525, in open
    response = self._open(req, data)
  File "/usr/lib/python3.7/urllib/request.py", line 543, in _open
    '_open', req)
  File "/usr/lib/python3.7/urllib/request.py", line 503, in _call_chain
    result = func(*args)
  File "/usr/lib/python3.7/urllib/request.py", line 1362, in https_open
    context=self._context, check_hostname=self._check_hostname)
  File "/usr/lib/python3.7/urllib/request.py", line 1321, in do_open
    raise URLError(err)
urllib.error.URLError: <urlopen error [Errno -3] Temporary failure in name resolution>

[INFO] (m79-hello) This package is up to date.
[INFO] (m79atomic) This package is up to date.
[INFO] (m79commons) This package is up to date.
[INFO] (m7pub-pylibs) This package is up to date.
[INFO] (m8tricks) This package is up to date.
[INFO] (m9dicts) This package is up to date.
[INFO] (m9s-customs-value) This package is up to date.
[INFO] (m9s-electronic-mail) This package is up to date.
[ERROR] (m9s-invoice-payment-gateway) Could not get a response from API for this package. See below for details.
Traceback (most recent call last):
  File "/usr/lib/python3.7/urllib/request.py", line 1319, in do_open
    encode_chunked=req.has_header('Transfer-encoding'))
  File "/usr/lib/python3.7/http/client.py", line 1252, in request
    self._send_request(method, url, body, headers, encode_chunked)
  File "/usr/lib/python3.7/http/client.py", line 1298, in _send_request
    self.endheaders(body, encode_chunked=encode_chunked)
  File "/usr/lib/python3.7/http/client.py", line 1247, in endheaders
    self._send_output(message_body, encode_chunked=encode_chunked)
  File "/usr/lib/python3.7/http/client.py", line 1026, in _send_output
    self.send(msg)
  File "/usr/lib/python3.7/http/client.py", line 966, in send
    self.connect()
  File "/usr/lib/python3.7/http/client.py", line 1414, in connect
    super().connect()
  File "/usr/lib/python3.7/http/client.py", line 938, in connect
    (self.host,self.port), self.timeout, self.source_address)
  File "/usr/lib/python3.7/socket.py", line 707, in create_connection
    for res in getaddrinfo(host, port, 0, SOCK_STREAM):
  File "/usr/lib/python3.7/socket.py", line 752, in getaddrinfo
    for res in _socket.getaddrinfo(host, port, family, type, proto, flags):
socket.gaierror: [Errno -3] Temporary failure in name resolution

During handling of the above exception, another exception occurred:

Traceback (most recent call last):
  File "/usr/local/lib/python3.7/dist-packages/pypicontents/api/pypi.py", line 264, in get_pkgdata
    timeout=10).read()
  File "/usr/lib/python3.7/urllib/request.py", line 222, in urlopen
    return opener.open(url, data, timeout)
  File "/usr/lib/python3.7/urllib/request.py", line 525, in open
    response = self._open(req, data)
  File "/usr/lib/python3.7/urllib/request.py", line 543, in _open
    '_open', req)
  File "/usr/lib/python3.7/urllib/request.py", line 503, in _call_chain
    result = func(*args)
  File "/usr/lib/python3.7/urllib/request.py", line 1362, in https_open
    context=self._context, check_hostname=self._check_hostname)
  File "/usr/lib/python3.7/urllib/request.py", line 1321, in do_open
    raise URLError(err)
urllib.error.URLError: <urlopen error [Errno -3] Temporary failure in name resolution>

[INFO] (m9s-nereid) This package is up to date.
[INFO] (m9s-nereid-catalog) This package is up to date.
[INFO] (m9s-nereid-catalog-tree) This package is up to date.
[INFO] (m9s-nereid-catalog-variants) This package is up to date.
[INFO] (m9s-nereid-cms) This package is up to date.
[ERROR] (m9s-nereid-image-transformation) Could not get a response from API for this package. See below for details.
Traceback (most recent call last):
  File "/usr/lib/python3.7/urllib/request.py", line 1319, in do_open
    encode_chunked=req.has_header('Transfer-encoding'))
  File "/usr/lib/python3.7/http/client.py", line 1252, in request
    self._send_request(method, url, body, headers, encode_chunked)
  File "/usr/lib/python3.7/http/client.py", line 1298, in _send_request
    self.endheaders(body, encode_chunked=encode_chunked)
  File "/usr/lib/python3.7/http/client.py", line 1247, in endheaders
    self._send_output(message_body, encode_chunked=encode_chunked)
  File "/usr/lib/python3.7/http/client.py", line 1026, in _send_output
    self.send(msg)
  File "/usr/lib/python3.7/http/client.py", line 966, in send
    self.connect()
  File "/usr/lib/python3.7/http/client.py", line 1414, in connect
    super().connect()
  File "/usr/lib/python3.7/http/client.py", line 938, in connect
    (self.host,self.port), self.timeout, self.source_address)
  File "/usr/lib/python3.7/socket.py", line 707, in create_connection
    for res in getaddrinfo(host, port, 0, SOCK_STREAM):
  File "/usr/lib/python3.7/socket.py", line 752, in getaddrinfo
    for res in _socket.getaddrinfo(host, port, family, type, proto, flags):
socket.gaierror: [Errno -3] Temporary failure in name resolution

During handling of the above exception, another exception occurred:

Traceback (most recent call last):
  File "/usr/local/lib/python3.7/dist-packages/pypicontents/api/pypi.py", line 264, in get_pkgdata
    timeout=10).read()
  File "/usr/lib/python3.7/urllib/request.py", line 222, in urlopen
    return opener.open(url, data, timeout)
  File "/usr/lib/python3.7/urllib/request.py", line 525, in open
    response = self._open(req, data)
  File "/usr/lib/python3.7/urllib/request.py", line 543, in _open
    '_open', req)
  File "/usr/lib/python3.7/urllib/request.py", line 503, in _call_chain
    result = func(*args)
  File "/usr/lib/python3.7/urllib/request.py", line 1362, in https_open
    context=self._context, check_hostname=self._check_hostname)
  File "/usr/lib/python3.7/urllib/request.py", line 1321, in do_open
    raise URLError(err)
urllib.error.URLError: <urlopen error [Errno -3] Temporary failure in name resolution>

[INFO] (m9s-payment-gateway) This package is up to date.
[INFO] (m9s-product-attribute-strict) This package is up to date.
[INFO] (m9s-product-variant) This package is up to date.
[INFO] (m9s-sale-channel) This package is up to date.
[INFO] (m9s-sale-payment-gateway) This package is up to date.
[INFO] (m9s-shipping) This package is up to date.
[INFO] (m9s-smtp) This package is up to date.
[INFO] (ma) This package is up to date.
[INFO] (ma-mongo) This package is up to date.
[INFO] (ma-praline) This package is up to date.
[INFO] (ma-shell) This package is up to date.
[INFO] (maachujdo) This package is up to date.
[INFO] (maads) This package is up to date.
[INFO] (maahinkainen-portlet-googlecalendar) This package is up to date.
[INFO] (maak) This package is up to date.
[INFO] (maas) This package is up to date.
[INFO] (maasclient) This package is up to date.
[INFO] (maasutil) This package is up to date.
[INFO] (maat) This package is up to date.
[INFO] (maat2) This package is up to date.
[INFO] (mab) This package is up to date.
[INFO] (mabalgs) This package is up to date.
[INFO] (mabandit) This package is up to date.
[ERROR] (maboss) Could not get a response from API for this package. See below for details.
Traceback (most recent call last):
  File "/usr/lib/python3.7/urllib/request.py", line 1319, in do_open
    encode_chunked=req.has_header('Transfer-encoding'))
  File "/usr/lib/python3.7/http/client.py", line 1252, in request
    self._send_request(method, url, body, headers, encode_chunked)
  File "/usr/lib/python3.7/http/client.py", line 1298, in _send_request
    self.endheaders(body, encode_chunked=encode_chunked)
  File "/usr/lib/python3.7/http/client.py", line 1247, in endheaders
    self._send_output(message_body, encode_chunked=encode_chunked)
  File "/usr/lib/python3.7/http/client.py", line 1026, in _send_output
    self.send(msg)
  File "/usr/lib/python3.7/http/client.py", line 966, in send
    self.connect()
  File "/usr/lib/python3.7/http/client.py", line 1414, in connect
    super().connect()
  File "/usr/lib/python3.7/http/client.py", line 938, in connect
    (self.host,self.port), self.timeout, self.source_address)
  File "/usr/lib/python3.7/socket.py", line 707, in create_connection
    for res in getaddrinfo(host, port, 0, SOCK_STREAM):
  File "/usr/lib/python3.7/socket.py", line 752, in getaddrinfo
    for res in _socket.getaddrinfo(host, port, family, type, proto, flags):
socket.gaierror: [Errno -3] Temporary failure in name resolution

During handling of the above exception, another exception occurred:

Traceback (most recent call last):
  File "/usr/local/lib/python3.7/dist-packages/pypicontents/api/pypi.py", line 264, in get_pkgdata
    timeout=10).read()
  File "/usr/lib/python3.7/urllib/request.py", line 222, in urlopen
    return opener.open(url, data, timeout)
  File "/usr/lib/python3.7/urllib/request.py", line 525, in open
    response = self._open(req, data)
  File "/usr/lib/python3.7/urllib/request.py", line 543, in _open
    '_open', req)
  File "/usr/lib/python3.7/urllib/request.py", line 503, in _call_chain
    result = func(*args)
  File "/usr/lib/python3.7/urllib/request.py", line 1362, in https_open
    context=self._context, check_hostname=self._check_hostname)
  File "/usr/lib/python3.7/urllib/request.py", line 1321, in do_open
    raise URLError(err)
urllib.error.URLError: <urlopen error [Errno -3] Temporary failure in name resolution>

[ERROR] (mabot) Could not extract data from this package. See below for details.
This package download URL does not point to a valid file: "http://code.google.com/p/robotframework-mabot/downloads/list"
[INFO] (mabpy) This package is up to date.
[INFO] (mabs) This package is up to date.
[INFO] (mac) This package is up to date.
[INFO] (mac-afk) This package is up to date.
[INFO] (mac-agents) This package is up to date.
[INFO] (mac-alias) This package is up to date.
[INFO] (mac-app) This package is up to date.
[INFO] (mac-app-bundleid) This package is up to date.
[INFO] (mac-app-cli) This package is up to date.
[INFO] (mac-app-env) This package is up to date.
[INFO] (mac-app-factory) This package is up to date.
[INFO] (mac-app-frontmost) This package is up to date.
[INFO] (mac-app-generator) This package is up to date.
[INFO] (mac-app-kill) This package is up to date.
[INFO] (mac-app-path) This package is up to date.
[INFO] (mac-app-pid) This package is up to date.
[INFO] (mac-appify) This package is up to date.
[INFO] (mac-brave) This package is up to date.
[INFO] (mac-chrome) This package is up to date.
[INFO] (mac-colors) This package is up to date.
[INFO] (mac-comment) This package is up to date.
[INFO] (mac-copy-capture) This package is up to date.
[INFO] (mac-desktop) This package is up to date.
[INFO] (mac-dialog) This package is up to date.
[INFO] (mac-display) This package is up to date.
[INFO] (mac-dock) This package is up to date.
[INFO] (mac-finder) This package is up to date.
[ERROR] (mac-headphones) Could not get a response from API for this package. See below for details.
Traceback (most recent call last):
  File "/usr/lib/python3.7/urllib/request.py", line 1319, in do_open
    encode_chunked=req.has_header('Transfer-encoding'))
  File "/usr/lib/python3.7/http/client.py", line 1252, in request
    self._send_request(method, url, body, headers, encode_chunked)
  File "/usr/lib/python3.7/http/client.py", line 1298, in _send_request
    self.endheaders(body, encode_chunked=encode_chunked)
  File "/usr/lib/python3.7/http/client.py", line 1247, in endheaders
    self._send_output(message_body, encode_chunked=encode_chunked)
  File "/usr/lib/python3.7/http/client.py", line 1026, in _send_output
    self.send(msg)
  File "/usr/lib/python3.7/http/client.py", line 966, in send
    self.connect()
  File "/usr/lib/python3.7/http/client.py", line 1414, in connect
    super().connect()
  File "/usr/lib/python3.7/http/client.py", line 938, in connect
    (self.host,self.port), self.timeout, self.source_address)
  File "/usr/lib/python3.7/socket.py", line 707, in create_connection
    for res in getaddrinfo(host, port, 0, SOCK_STREAM):
  File "/usr/lib/python3.7/socket.py", line 752, in getaddrinfo
    for res in _socket.getaddrinfo(host, port, family, type, proto, flags):
socket.gaierror: [Errno -3] Temporary failure in name resolution

During handling of the above exception, another exception occurred:

Traceback (most recent call last):
  File "/usr/local/lib/python3.7/dist-packages/pypicontents/api/pypi.py", line 264, in get_pkgdata
    timeout=10).read()
  File "/usr/lib/python3.7/urllib/request.py", line 222, in urlopen
    return opener.open(url, data, timeout)
  File "/usr/lib/python3.7/urllib/request.py", line 525, in open
    response = self._open(req, data)
  File "/usr/lib/python3.7/urllib/request.py", line 543, in _open
    '_open', req)
  File "/usr/lib/python3.7/urllib/request.py", line 503, in _call_chain
    result = func(*args)
  File "/usr/lib/python3.7/urllib/request.py", line 1362, in https_open
    context=self._context, check_hostname=self._check_hostname)
  File "/usr/lib/python3.7/urllib/request.py", line 1321, in do_open
    raise URLError(err)
urllib.error.URLError: <urlopen error [Errno -3] Temporary failure in name resolution>

[INFO] (mac-input) This package is up to date.
[INFO] (mac-itunes) This package is up to date.
[INFO] (mac-localized) This package is up to date.
[INFO] (mac-login-items) This package is up to date.
[INFO] (mac-logs) This package is up to date.
[INFO] (mac-open-apps) This package is up to date.
[ERROR] (mac-opera) Could not get a response from API for this package. See below for details.
Traceback (most recent call last):
  File "/usr/lib/python3.7/urllib/request.py", line 1319, in do_open
    encode_chunked=req.has_header('Transfer-encoding'))
  File "/usr/lib/python3.7/http/client.py", line 1252, in request
    self._send_request(method, url, body, headers, encode_chunked)
  File "/usr/lib/python3.7/http/client.py", line 1298, in _send_request
    self.endheaders(body, encode_chunked=encode_chunked)
  File "/usr/lib/python3.7/http/client.py", line 1247, in endheaders
    self._send_output(message_body, encode_chunked=encode_chunked)
  File "/usr/lib/python3.7/http/client.py", line 1026, in _send_output
    self.send(msg)
  File "/usr/lib/python3.7/http/client.py", line 966, in send
    self.connect()
  File "/usr/lib/python3.7/http/client.py", line 1414, in connect
    super().connect()
  File "/usr/lib/python3.7/http/client.py", line 938, in connect
    (self.host,self.port), self.timeout, self.source_address)
  File "/usr/lib/python3.7/socket.py", line 707, in create_connection
    for res in getaddrinfo(host, port, 0, SOCK_STREAM):
  File "/usr/lib/python3.7/socket.py", line 752, in getaddrinfo
    for res in _socket.getaddrinfo(host, port, family, type, proto, flags):
socket.gaierror: [Errno -3] Temporary failure in name resolution

During handling of the above exception, another exception occurred:

Traceback (most recent call last):
  File "/usr/local/lib/python3.7/dist-packages/pypicontents/api/pypi.py", line 264, in get_pkgdata
    timeout=10).read()
  File "/usr/lib/python3.7/urllib/request.py", line 222, in urlopen
    return opener.open(url, data, timeout)
  File "/usr/lib/python3.7/urllib/request.py", line 525, in open
    response = self._open(req, data)
  File "/usr/lib/python3.7/urllib/request.py", line 543, in _open
    '_open', req)
  File "/usr/lib/python3.7/urllib/request.py", line 503, in _call_chain
    result = func(*args)
  File "/usr/lib/python3.7/urllib/request.py", line 1362, in https_open
    context=self._context, check_hostname=self._check_hostname)
  File "/usr/lib/python3.7/urllib/request.py", line 1321, in do_open
    raise URLError(err)
urllib.error.URLError: <urlopen error [Errno -3] Temporary failure in name resolution>

[INFO] (mac-py) This package is up to date.
[INFO] (mac-say) This package is up to date.
[INFO] (mac-screensaver) This package is up to date.
[INFO] (mac-slideshow) This package is up to date.
[INFO] (mac-speech-cache) This package is up to date.
[INFO] (mac-speech-commands) This package is up to date.
[INFO] (mac-tag) This package is up to date.
[ERROR] (mac-tag-sync) Could not get a response from API for this package. See below for details.
Traceback (most recent call last):
  File "/usr/lib/python3.7/urllib/request.py", line 1319, in do_open
    encode_chunked=req.has_header('Transfer-encoding'))
  File "/usr/lib/python3.7/http/client.py", line 1252, in request
    self._send_request(method, url, body, headers, encode_chunked)
  File "/usr/lib/python3.7/http/client.py", line 1298, in _send_request
    self.endheaders(body, encode_chunked=encode_chunked)
  File "/usr/lib/python3.7/http/client.py", line 1247, in endheaders
    self._send_output(message_body, encode_chunked=encode_chunked)
  File "/usr/lib/python3.7/http/client.py", line 1026, in _send_output
    self.send(msg)
  File "/usr/lib/python3.7/http/client.py", line 966, in send
    self.connect()
  File "/usr/lib/python3.7/http/client.py", line 1414, in connect
    super().connect()
  File "/usr/lib/python3.7/http/client.py", line 938, in connect
    (self.host,self.port), self.timeout, self.source_address)
  File "/usr/lib/python3.7/socket.py", line 707, in create_connection
    for res in getaddrinfo(host, port, 0, SOCK_STREAM):
  File "/usr/lib/python3.7/socket.py", line 752, in getaddrinfo
    for res in _socket.getaddrinfo(host, port, family, type, proto, flags):
socket.gaierror: [Errno -3] Temporary failure in name resolution

During handling of the above exception, another exception occurred:

Traceback (most recent call last):
  File "/usr/local/lib/python3.7/dist-packages/pypicontents/api/pypi.py", line 264, in get_pkgdata
    timeout=10).read()
  File "/usr/lib/python3.7/urllib/request.py", line 222, in urlopen
    return opener.open(url, data, timeout)
  File "/usr/lib/python3.7/urllib/request.py", line 525, in open
    response = self._open(req, data)
  File "/usr/lib/python3.7/urllib/request.py", line 543, in _open
    '_open', req)
  File "/usr/lib/python3.7/urllib/request.py", line 503, in _call_chain
    result = func(*args)
  File "/usr/lib/python3.7/urllib/request.py", line 1362, in https_open
    context=self._context, check_hostname=self._check_hostname)
  File "/usr/lib/python3.7/urllib/request.py", line 1321, in do_open
    raise URLError(err)
urllib.error.URLError: <urlopen error [Errno -3] Temporary failure in name resolution>

[INFO] (mac-terminal-interpreter) This package is up to date.
[INFO] (mac-vendor-lookup) This package is up to date.
[INFO] (mac-vlc) This package is up to date.
[ERROR] (mac-volume) Could not get a response from API for this package. See below for details.
Traceback (most recent call last):
  File "/usr/lib/python3.7/urllib/request.py", line 1319, in do_open
    encode_chunked=req.has_header('Transfer-encoding'))
  File "/usr/lib/python3.7/http/client.py", line 1252, in request
    self._send_request(method, url, body, headers, encode_chunked)
  File "/usr/lib/python3.7/http/client.py", line 1298, in _send_request
    self.endheaders(body, encode_chunked=encode_chunked)
  File "/usr/lib/python3.7/http/client.py", line 1247, in endheaders
    self._send_output(message_body, encode_chunked=encode_chunked)
  File "/usr/lib/python3.7/http/client.py", line 1026, in _send_output
    self.send(msg)
  File "/usr/lib/python3.7/http/client.py", line 966, in send
    self.connect()
  File "/usr/lib/python3.7/http/client.py", line 1414, in connect
    super().connect()
  File "/usr/lib/python3.7/http/client.py", line 938, in connect
    (self.host,self.port), self.timeout, self.source_address)
  File "/usr/lib/python3.7/socket.py", line 707, in create_connection
    for res in getaddrinfo(host, port, 0, SOCK_STREAM):
  File "/usr/lib/python3.7/socket.py", line 752, in getaddrinfo
    for res in _socket.getaddrinfo(host, port, family, type, proto, flags):
socket.gaierror: [Errno -3] Temporary failure in name resolution

During handling of the above exception, another exception occurred:

Traceback (most recent call last):
  File "/usr/local/lib/python3.7/dist-packages/pypicontents/api/pypi.py", line 264, in get_pkgdata
    timeout=10).read()
  File "/usr/lib/python3.7/urllib/request.py", line 222, in urlopen
    return opener.open(url, data, timeout)
  File "/usr/lib/python3.7/urllib/request.py", line 525, in open
    response = self._open(req, data)
  File "/usr/lib/python3.7/urllib/request.py", line 543, in _open
    '_open', req)
  File "/usr/lib/python3.7/urllib/request.py", line 503, in _call_chain
    result = func(*args)
  File "/usr/lib/python3.7/urllib/request.py", line 1362, in https_open
    context=self._context, check_hostname=self._check_hostname)
  File "/usr/lib/python3.7/urllib/request.py", line 1321, in do_open
    raise URLError(err)
urllib.error.URLError: <urlopen error [Errno -3] Temporary failure in name resolution>

[ERROR] (mac-wallpaper) Could not get a response from API for this package. See below for details.
Traceback (most recent call last):
  File "/usr/lib/python3.7/urllib/request.py", line 1319, in do_open
    encode_chunked=req.has_header('Transfer-encoding'))
  File "/usr/lib/python3.7/http/client.py", line 1252, in request
    self._send_request(method, url, body, headers, encode_chunked)
  File "/usr/lib/python3.7/http/client.py", line 1298, in _send_request
    self.endheaders(body, encode_chunked=encode_chunked)
  File "/usr/lib/python3.7/http/client.py", line 1247, in endheaders
    self._send_output(message_body, encode_chunked=encode_chunked)
  File "/usr/lib/python3.7/http/client.py", line 1026, in _send_output
    self.send(msg)
  File "/usr/lib/python3.7/http/client.py", line 966, in send
    self.connect()
  File "/usr/lib/python3.7/http/client.py", line 1414, in connect
    super().connect()
  File "/usr/lib/python3.7/http/client.py", line 938, in connect
    (self.host,self.port), self.timeout, self.source_address)
  File "/usr/lib/python3.7/socket.py", line 707, in create_connection
    for res in getaddrinfo(host, port, 0, SOCK_STREAM):
  File "/usr/lib/python3.7/socket.py", line 752, in getaddrinfo
    for res in _socket.getaddrinfo(host, port, family, type, proto, flags):
socket.gaierror: [Errno -3] Temporary failure in name resolution

During handling of the above exception, another exception occurred:

Traceback (most recent call last):
  File "/usr/local/lib/python3.7/dist-packages/pypicontents/api/pypi.py", line 264, in get_pkgdata
    timeout=10).read()
  File "/usr/lib/python3.7/urllib/request.py", line 222, in urlopen
    return opener.open(url, data, timeout)
  File "/usr/lib/python3.7/urllib/request.py", line 525, in open
    response = self._open(req, data)
  File "/usr/lib/python3.7/urllib/request.py", line 543, in _open
    '_open', req)
  File "/usr/lib/python3.7/urllib/request.py", line 503, in _call_chain
    result = func(*args)
  File "/usr/lib/python3.7/urllib/request.py", line 1362, in https_open
    context=self._context, check_hostname=self._check_hostname)
  File "/usr/lib/python3.7/urllib/request.py", line 1321, in do_open
    raise URLError(err)
urllib.error.URLError: <urlopen error [Errno -3] Temporary failure in name resolution>

[INFO] (mac-youtube) This package is up to date.
[INFO] (mac2vendors) This package is up to date.
[INFO] (maca) This package is up to date.
[INFO] (macaca) This package is up to date.
[INFO] (macad-gym) This package is up to date.
[INFO] (macadamia) This package is up to date.
[INFO] (macaddress) This package is up to date.
[INFO] (macaddresslink) This package is up to date.
[INFO] (macaetr) This package is up to date.
[INFO] (macapi) This package is up to date.
[INFO] (macaron) This package is up to date.
[INFO] (macaroni) This package is up to date.
[INFO] (macaroonbakery) This package is up to date.
[INFO] (macattc) This package is up to date.
[INFO] (macaulay2-jupyter-kernel) This package is up to date.
[INFO] (macauthlib) This package is up to date.
[INFO] (macaw) This package is up to date.
[INFO] (macawspeak) This package is up to date.
[ERROR] (macbook) This package does not have downloadable releases.
[INFO] (maccabee) Data has been updated for this package.
[INFO] (maccabistats) This package is up to date.
[ERROR] (maccabistats-web) Could not get a response from API for this package. See below for details.
Traceback (most recent call last):
  File "/usr/local/lib/python3.7/dist-packages/pypicontents/api/pypi.py", line 264, in get_pkgdata
    timeout=10).read()
  File "/usr/lib/python3.7/urllib/request.py", line 222, in urlopen
    return opener.open(url, data, timeout)
  File "/usr/lib/python3.7/urllib/request.py", line 531, in open
    response = meth(req, response)
  File "/usr/lib/python3.7/urllib/request.py", line 641, in http_response
    'http', request, response, code, msg, hdrs)
  File "/usr/lib/python3.7/urllib/request.py", line 569, in error
    return self._call_chain(*args)
  File "/usr/lib/python3.7/urllib/request.py", line 503, in _call_chain
    result = func(*args)
  File "/usr/lib/python3.7/urllib/request.py", line 649, in http_error_default
    raise HTTPError(req.full_url, code, msg, hdrs, fp)
urllib.error.HTTPError: HTTP Error 404: Not Found

[INFO] (maccc) This package is up to date.
[INFO] (macdaily) This package is up to date.
[INFO] (macdict) This package is up to date.
[ERROR] (macdive) This package does not have downloadable releases.
[INFO] (macdtrader) This package is up to date.
[INFO] (mace) This package is up to date.
[INFO] (macfsevents) This package is up to date.
[INFO] (macgen) This package is up to date.
[ERROR] (macgyverproject) Could not get a response from API for this package. See below for details.
Traceback (most recent call last):
  File "/usr/lib/python3.7/urllib/request.py", line 1319, in do_open
    encode_chunked=req.has_header('Transfer-encoding'))
  File "/usr/lib/python3.7/http/client.py", line 1252, in request
    self._send_request(method, url, body, headers, encode_chunked)
  File "/usr/lib/python3.7/http/client.py", line 1298, in _send_request
    self.endheaders(body, encode_chunked=encode_chunked)
  File "/usr/lib/python3.7/http/client.py", line 1247, in endheaders
    self._send_output(message_body, encode_chunked=encode_chunked)
  File "/usr/lib/python3.7/http/client.py", line 1026, in _send_output
    self.send(msg)
  File "/usr/lib/python3.7/http/client.py", line 966, in send
    self.connect()
  File "/usr/lib/python3.7/http/client.py", line 1414, in connect
    super().connect()
  File "/usr/lib/python3.7/http/client.py", line 938, in connect
    (self.host,self.port), self.timeout, self.source_address)
  File "/usr/lib/python3.7/socket.py", line 707, in create_connection
    for res in getaddrinfo(host, port, 0, SOCK_STREAM):
  File "/usr/lib/python3.7/socket.py", line 752, in getaddrinfo
    for res in _socket.getaddrinfo(host, port, family, type, proto, flags):
socket.gaierror: [Errno -3] Temporary failure in name resolution

During handling of the above exception, another exception occurred:

Traceback (most recent call last):
  File "/usr/local/lib/python3.7/dist-packages/pypicontents/api/pypi.py", line 264, in get_pkgdata
    timeout=10).read()
  File "/usr/lib/python3.7/urllib/request.py", line 222, in urlopen
    return opener.open(url, data, timeout)
  File "/usr/lib/python3.7/urllib/request.py", line 525, in open
    response = self._open(req, data)
  File "/usr/lib/python3.7/urllib/request.py", line 543, in _open
    '_open', req)
  File "/usr/lib/python3.7/urllib/request.py", line 503, in _call_chain
    result = func(*args)
  File "/usr/lib/python3.7/urllib/request.py", line 1362, in https_open
    context=self._context, check_hostname=self._check_hostname)
  File "/usr/lib/python3.7/urllib/request.py", line 1321, in do_open
    raise URLError(err)
urllib.error.URLError: <urlopen error [Errno -3] Temporary failure in name resolution>

[INFO] (mach) This package is up to date.
[INFO] (mach-py) This package is up to date.
[INFO] (mach3) This package is up to date.
[INFO] (mach9) This package is up to date.
[INFO] (machete) This package is up to date.
[INFO] (machfs) This package is up to date.
[INFO] (machi) This package is up to date.
[INFO] (machi-store) This package is up to date.
[INFO] (machina) This package is up to date.
[ERROR] (machina-python) This package does not have downloadable releases.
[INFO] (machina-rl) This package is up to date.
[INFO] (machinable) This package is up to date.
[INFO] (machinae) This package is up to date.
[INFO] (machine) This package is up to date.
[INFO] (machine-engine-python) This package is up to date.
[INFO] (machine-learning) This package is up to date.
[INFO] (machine-learning-data-pipeline) This package is up to date.
[INFO] (machine-learning-py) This package is up to date.
[ERROR] (machine-learning-utility) Could not get a response from API for this package. See below for details.
Traceback (most recent call last):
  File "/usr/lib/python3.7/urllib/request.py", line 1319, in do_open
    encode_chunked=req.has_header('Transfer-encoding'))
  File "/usr/lib/python3.7/http/client.py", line 1252, in request
    self._send_request(method, url, body, headers, encode_chunked)
  File "/usr/lib/python3.7/http/client.py", line 1298, in _send_request
    self.endheaders(body, encode_chunked=encode_chunked)
  File "/usr/lib/python3.7/http/client.py", line 1247, in endheaders
    self._send_output(message_body, encode_chunked=encode_chunked)
  File "/usr/lib/python3.7/http/client.py", line 1026, in _send_output
    self.send(msg)
  File "/usr/lib/python3.7/http/client.py", line 966, in send
    self.connect()
  File "/usr/lib/python3.7/http/client.py", line 1414, in connect
    super().connect()
  File "/usr/lib/python3.7/http/client.py", line 938, in connect
    (self.host,self.port), self.timeout, self.source_address)
  File "/usr/lib/python3.7/socket.py", line 707, in create_connection
    for res in getaddrinfo(host, port, 0, SOCK_STREAM):
  File "/usr/lib/python3.7/socket.py", line 752, in getaddrinfo
    for res in _socket.getaddrinfo(host, port, family, type, proto, flags):
socket.gaierror: [Errno -3] Temporary failure in name resolution

During handling of the above exception, another exception occurred:

Traceback (most recent call last):
  File "/usr/local/lib/python3.7/dist-packages/pypicontents/api/pypi.py", line 264, in get_pkgdata
    timeout=10).read()
  File "/usr/lib/python3.7/urllib/request.py", line 222, in urlopen
    return opener.open(url, data, timeout)
  File "/usr/lib/python3.7/urllib/request.py", line 525, in open
    response = self._open(req, data)
  File "/usr/lib/python3.7/urllib/request.py", line 543, in _open
    '_open', req)
  File "/usr/lib/python3.7/urllib/request.py", line 503, in _call_chain
    result = func(*args)
  File "/usr/lib/python3.7/urllib/request.py", line 1362, in https_open
    context=self._context, check_hostname=self._check_hostname)
  File "/usr/lib/python3.7/urllib/request.py", line 1321, in do_open
    raise URLError(err)
urllib.error.URLError: <urlopen error [Errno -3] Temporary failure in name resolution>

[INFO] (machinebox-python-sdk) This package is up to date.
[INFO] (machinegun) This package is up to date.
[INFO] (machineids) This package is up to date.
[INFO] (machineio) This package is up to date.
[INFO] (machineit) This package is up to date.
[INFO] (machinelearning) This package is up to date.
[INFO] (machinelearning-master) This package is up to date.
[INFO] (machinelearningfortextcategory) This package is up to date.
[INFO] (machinelearningstanford) This package is up to date.
[INFO] (machinelearnlib) This package is up to date.
[INFO] (machinepack) This package is up to date.
[INFO] (machinepdf) This package is up to date.
[INFO] (machinerry) This package is up to date.
[ERROR] (machines) Could not get a response from API for this package. See below for details.
Traceback (most recent call last):
  File "/usr/lib/python3.7/urllib/request.py", line 1319, in do_open
    encode_chunked=req.has_header('Transfer-encoding'))
  File "/usr/lib/python3.7/http/client.py", line 1252, in request
    self._send_request(method, url, body, headers, encode_chunked)
  File "/usr/lib/python3.7/http/client.py", line 1298, in _send_request
    self.endheaders(body, encode_chunked=encode_chunked)
  File "/usr/lib/python3.7/http/client.py", line 1247, in endheaders
    self._send_output(message_body, encode_chunked=encode_chunked)
  File "/usr/lib/python3.7/http/client.py", line 1026, in _send_output
    self.send(msg)
  File "/usr/lib/python3.7/http/client.py", line 966, in send
    self.connect()
  File "/usr/lib/python3.7/http/client.py", line 1414, in connect
    super().connect()
  File "/usr/lib/python3.7/http/client.py", line 938, in connect
    (self.host,self.port), self.timeout, self.source_address)
  File "/usr/lib/python3.7/socket.py", line 707, in create_connection
    for res in getaddrinfo(host, port, 0, SOCK_STREAM):
  File "/usr/lib/python3.7/socket.py", line 752, in getaddrinfo
    for res in _socket.getaddrinfo(host, port, family, type, proto, flags):
socket.gaierror: [Errno -3] Temporary failure in name resolution

During handling of the above exception, another exception occurred:

Traceback (most recent call last):
  File "/usr/local/lib/python3.7/dist-packages/pypicontents/api/pypi.py", line 264, in get_pkgdata
    timeout=10).read()
  File "/usr/lib/python3.7/urllib/request.py", line 222, in urlopen
    return opener.open(url, data, timeout)
  File "/usr/lib/python3.7/urllib/request.py", line 525, in open
    response = self._open(req, data)
  File "/usr/lib/python3.7/urllib/request.py", line 543, in _open
    '_open', req)
  File "/usr/lib/python3.7/urllib/request.py", line 503, in _call_chain
    result = func(*args)
  File "/usr/lib/python3.7/urllib/request.py", line 1362, in https_open
    context=self._context, check_hostname=self._check_hostname)
  File "/usr/lib/python3.7/urllib/request.py", line 1321, in do_open
    raise URLError(err)
urllib.error.URLError: <urlopen error [Errno -3] Temporary failure in name resolution>

[ERROR] (machinesenseanalytics) Could not get a response from API for this package. See below for details.
Traceback (most recent call last):
  File "/usr/local/lib/python3.7/dist-packages/pypicontents/api/pypi.py", line 264, in get_pkgdata
    timeout=10).read()
  File "/usr/lib/python3.7/urllib/request.py", line 222, in urlopen
    return opener.open(url, data, timeout)
  File "/usr/lib/python3.7/urllib/request.py", line 531, in open
    response = meth(req, response)
  File "/usr/lib/python3.7/urllib/request.py", line 641, in http_response
    'http', request, response, code, msg, hdrs)
  File "/usr/lib/python3.7/urllib/request.py", line 563, in error
    result = self._call_chain(*args)
  File "/usr/lib/python3.7/urllib/request.py", line 503, in _call_chain
    result = func(*args)
  File "/usr/lib/python3.7/urllib/request.py", line 755, in http_error_302
    return self.parent.open(new, timeout=req.timeout)
  File "/usr/lib/python3.7/urllib/request.py", line 531, in open
    response = meth(req, response)
  File "/usr/lib/python3.7/urllib/request.py", line 641, in http_response
    'http', request, response, code, msg, hdrs)
  File "/usr/lib/python3.7/urllib/request.py", line 569, in error
    return self._call_chain(*args)
  File "/usr/lib/python3.7/urllib/request.py", line 503, in _call_chain
    result = func(*args)
  File "/usr/lib/python3.7/urllib/request.py", line 649, in http_error_default
    raise HTTPError(req.full_url, code, msg, hdrs, fp)
urllib.error.HTTPError: HTTP Error 404: Not Found

[INFO] (machinetalk-protobuf) This package is up to date.
[ERROR] (machinist) Could not get a response from API for this package. See below for details.
Traceback (most recent call last):
  File "/usr/lib/python3.7/urllib/request.py", line 1319, in do_open
    encode_chunked=req.has_header('Transfer-encoding'))
  File "/usr/lib/python3.7/http/client.py", line 1252, in request
    self._send_request(method, url, body, headers, encode_chunked)
  File "/usr/lib/python3.7/http/client.py", line 1298, in _send_request
    self.endheaders(body, encode_chunked=encode_chunked)
  File "/usr/lib/python3.7/http/client.py", line 1247, in endheaders
    self._send_output(message_body, encode_chunked=encode_chunked)
  File "/usr/lib/python3.7/http/client.py", line 1026, in _send_output
    self.send(msg)
  File "/usr/lib/python3.7/http/client.py", line 966, in send
    self.connect()
  File "/usr/lib/python3.7/http/client.py", line 1414, in connect
    super().connect()
  File "/usr/lib/python3.7/http/client.py", line 938, in connect
    (self.host,self.port), self.timeout, self.source_address)
  File "/usr/lib/python3.7/socket.py", line 707, in create_connection
    for res in getaddrinfo(host, port, 0, SOCK_STREAM):
  File "/usr/lib/python3.7/socket.py", line 752, in getaddrinfo
    for res in _socket.getaddrinfo(host, port, family, type, proto, flags):
socket.gaierror: [Errno -3] Temporary failure in name resolution

During handling of the above exception, another exception occurred:

Traceback (most recent call last):
  File "/usr/local/lib/python3.7/dist-packages/pypicontents/api/pypi.py", line 264, in get_pkgdata
    timeout=10).read()
  File "/usr/lib/python3.7/urllib/request.py", line 222, in urlopen
    return opener.open(url, data, timeout)
  File "/usr/lib/python3.7/urllib/request.py", line 525, in open
    response = self._open(req, data)
  File "/usr/lib/python3.7/urllib/request.py", line 543, in _open
    '_open', req)
  File "/usr/lib/python3.7/urllib/request.py", line 503, in _call_chain
    result = func(*args)
  File "/usr/lib/python3.7/urllib/request.py", line 1362, in https_open
    context=self._context, check_hostname=self._check_hostname)
  File "/usr/lib/python3.7/urllib/request.py", line 1321, in do_open
    raise URLError(err)
urllib.error.URLError: <urlopen error [Errno -3] Temporary failure in name resolution>

[INFO] (macho-analysis) This package is up to date.
[INFO] (macho-parser) This package is up to date.
[INFO] (machobot) This package is up to date.
[INFO] (macholib) This package is up to date.
[INFO] (machomachomangler) This package is up to date.
[ERROR] (machop) Could not get a response from API for this package. See below for details.
Traceback (most recent call last):
  File "/usr/local/lib/python3.7/dist-packages/pypicontents/api/pypi.py", line 264, in get_pkgdata
    timeout=10).read()
  File "/usr/lib/python3.7/urllib/request.py", line 222, in urlopen
    return opener.open(url, data, timeout)
  File "/usr/lib/python3.7/urllib/request.py", line 531, in open
    response = meth(req, response)
  File "/usr/lib/python3.7/urllib/request.py", line 641, in http_response
    'http', request, response, code, msg, hdrs)
  File "/usr/lib/python3.7/urllib/request.py", line 569, in error
    return self._call_chain(*args)
  File "/usr/lib/python3.7/urllib/request.py", line 503, in _call_chain
    result = func(*args)
  File "/usr/lib/python3.7/urllib/request.py", line 649, in http_error_default
    raise HTTPError(req.full_url, code, msg, hdrs, fp)
urllib.error.HTTPError: HTTP Error 404: Not Found

[INFO] (machotools) This package is up to date.
[INFO] (macht) This package is up to date.
[INFO] (machutil) This package is up to date.
[INFO] (macias-distributions) This package is up to date.
[INFO] (mack) This package is up to date.
[ERROR] (mackdown) Could not get a response from API for this package. See below for details.
Traceback (most recent call last):
  File "/usr/lib/python3.7/urllib/request.py", line 1319, in do_open
    encode_chunked=req.has_header('Transfer-encoding'))
  File "/usr/lib/python3.7/http/client.py", line 1252, in request
    self._send_request(method, url, body, headers, encode_chunked)
  File "/usr/lib/python3.7/http/client.py", line 1298, in _send_request
    self.endheaders(body, encode_chunked=encode_chunked)
  File "/usr/lib/python3.7/http/client.py", line 1247, in endheaders
    self._send_output(message_body, encode_chunked=encode_chunked)
  File "/usr/lib/python3.7/http/client.py", line 1026, in _send_output
    self.send(msg)
  File "/usr/lib/python3.7/http/client.py", line 966, in send
    self.connect()
  File "/usr/lib/python3.7/http/client.py", line 1414, in connect
    super().connect()
  File "/usr/lib/python3.7/http/client.py", line 938, in connect
    (self.host,self.port), self.timeout, self.source_address)
  File "/usr/lib/python3.7/socket.py", line 707, in create_connection
    for res in getaddrinfo(host, port, 0, SOCK_STREAM):
  File "/usr/lib/python3.7/socket.py", line 752, in getaddrinfo
    for res in _socket.getaddrinfo(host, port, family, type, proto, flags):
socket.gaierror: [Errno -3] Temporary failure in name resolution

During handling of the above exception, another exception occurred:

Traceback (most recent call last):
  File "/usr/local/lib/python3.7/dist-packages/pypicontents/api/pypi.py", line 264, in get_pkgdata
    timeout=10).read()
  File "/usr/lib/python3.7/urllib/request.py", line 222, in urlopen
    return opener.open(url, data, timeout)
  File "/usr/lib/python3.7/urllib/request.py", line 525, in open
    response = self._open(req, data)
  File "/usr/lib/python3.7/urllib/request.py", line 543, in _open
    '_open', req)
  File "/usr/lib/python3.7/urllib/request.py", line 503, in _call_chain
    result = func(*args)
  File "/usr/lib/python3.7/urllib/request.py", line 1362, in https_open
    context=self._context, check_hostname=self._check_hostname)
  File "/usr/lib/python3.7/urllib/request.py", line 1321, in do_open
    raise URLError(err)
urllib.error.URLError: <urlopen error [Errno -3] Temporary failure in name resolution>

[INFO] (mackerel) This package is up to date.
[ERROR] (mackerel-client) Could not get a response from API for this package. See below for details.
Traceback (most recent call last):
  File "/usr/lib/python3.7/urllib/request.py", line 1319, in do_open
    encode_chunked=req.has_header('Transfer-encoding'))
  File "/usr/lib/python3.7/http/client.py", line 1252, in request
    self._send_request(method, url, body, headers, encode_chunked)
  File "/usr/lib/python3.7/http/client.py", line 1298, in _send_request
    self.endheaders(body, encode_chunked=encode_chunked)
  File "/usr/lib/python3.7/http/client.py", line 1247, in endheaders
    self._send_output(message_body, encode_chunked=encode_chunked)
  File "/usr/lib/python3.7/http/client.py", line 1026, in _send_output
    self.send(msg)
  File "/usr/lib/python3.7/http/client.py", line 966, in send
    self.connect()
  File "/usr/lib/python3.7/http/client.py", line 1414, in connect
    super().connect()
  File "/usr/lib/python3.7/http/client.py", line 938, in connect
    (self.host,self.port), self.timeout, self.source_address)
  File "/usr/lib/python3.7/socket.py", line 707, in create_connection
    for res in getaddrinfo(host, port, 0, SOCK_STREAM):
  File "/usr/lib/python3.7/socket.py", line 752, in getaddrinfo
    for res in _socket.getaddrinfo(host, port, family, type, proto, flags):
socket.gaierror: [Errno -3] Temporary failure in name resolution

During handling of the above exception, another exception occurred:

Traceback (most recent call last):
  File "/usr/local/lib/python3.7/dist-packages/pypicontents/api/pypi.py", line 264, in get_pkgdata
    timeout=10).read()
  File "/usr/lib/python3.7/urllib/request.py", line 222, in urlopen
    return opener.open(url, data, timeout)
  File "/usr/lib/python3.7/urllib/request.py", line 531, in open
    response = meth(req, response)
  File "/usr/lib/python3.7/urllib/request.py", line 641, in http_response
    'http', request, response, code, msg, hdrs)
  File "/usr/lib/python3.7/urllib/request.py", line 563, in error
    result = self._call_chain(*args)
  File "/usr/lib/python3.7/urllib/request.py", line 503, in _call_chain
    result = func(*args)
  File "/usr/lib/python3.7/urllib/request.py", line 755, in http_error_302
    return self.parent.open(new, timeout=req.timeout)
  File "/usr/lib/python3.7/urllib/request.py", line 525, in open
    response = self._open(req, data)
  File "/usr/lib/python3.7/urllib/request.py", line 543, in _open
    '_open', req)
  File "/usr/lib/python3.7/urllib/request.py", line 503, in _call_chain
    result = func(*args)
  File "/usr/lib/python3.7/urllib/request.py", line 1362, in https_open
    context=self._context, check_hostname=self._check_hostname)
  File "/usr/lib/python3.7/urllib/request.py", line 1321, in do_open
    raise URLError(err)
urllib.error.URLError: <urlopen error [Errno -3] Temporary failure in name resolution>

[ERROR] (mackerel-clienthde) Could not get a response from API for this package. See below for details.
Traceback (most recent call last):
  File "/usr/lib/python3.7/urllib/request.py", line 1319, in do_open
    encode_chunked=req.has_header('Transfer-encoding'))
  File "/usr/lib/python3.7/http/client.py", line 1252, in request
    self._send_request(method, url, body, headers, encode_chunked)
  File "/usr/lib/python3.7/http/client.py", line 1298, in _send_request
    self.endheaders(body, encode_chunked=encode_chunked)
  File "/usr/lib/python3.7/http/client.py", line 1247, in endheaders
    self._send_output(message_body, encode_chunked=encode_chunked)
  File "/usr/lib/python3.7/http/client.py", line 1026, in _send_output
    self.send(msg)
  File "/usr/lib/python3.7/http/client.py", line 966, in send
    self.connect()
  File "/usr/lib/python3.7/http/client.py", line 1414, in connect
    super().connect()
  File "/usr/lib/python3.7/http/client.py", line 938, in connect
    (self.host,self.port), self.timeout, self.source_address)
  File "/usr/lib/python3.7/socket.py", line 707, in create_connection
    for res in getaddrinfo(host, port, 0, SOCK_STREAM):
  File "/usr/lib/python3.7/socket.py", line 752, in getaddrinfo
    for res in _socket.getaddrinfo(host, port, family, type, proto, flags):
socket.gaierror: [Errno -3] Temporary failure in name resolution

During handling of the above exception, another exception occurred:

Traceback (most recent call last):
  File "/usr/local/lib/python3.7/dist-packages/pypicontents/api/pypi.py", line 264, in get_pkgdata
    timeout=10).read()
  File "/usr/lib/python3.7/urllib/request.py", line 222, in urlopen
    return opener.open(url, data, timeout)
  File "/usr/lib/python3.7/urllib/request.py", line 531, in open
    response = meth(req, response)
  File "/usr/lib/python3.7/urllib/request.py", line 641, in http_response
    'http', request, response, code, msg, hdrs)
  File "/usr/lib/python3.7/urllib/request.py", line 563, in error
    result = self._call_chain(*args)
  File "/usr/lib/python3.7/urllib/request.py", line 503, in _call_chain
    result = func(*args)
  File "/usr/lib/python3.7/urllib/request.py", line 755, in http_error_302
    return self.parent.open(new, timeout=req.timeout)
  File "/usr/lib/python3.7/urllib/request.py", line 525, in open
    response = self._open(req, data)
  File "/usr/lib/python3.7/urllib/request.py", line 543, in _open
    '_open', req)
  File "/usr/lib/python3.7/urllib/request.py", line 503, in _call_chain
    result = func(*args)
  File "/usr/lib/python3.7/urllib/request.py", line 1362, in https_open
    context=self._context, check_hostname=self._check_hostname)
  File "/usr/lib/python3.7/urllib/request.py", line 1321, in do_open
    raise URLError(err)
urllib.error.URLError: <urlopen error [Errno -3] Temporary failure in name resolution>

[INFO] (mackinac) This package is up to date.
[INFO] (mackup) This package is up to date.
[INFO] (maclocate) This package is up to date.
[INFO] (maclookup) This package is up to date.
[INFO] (maclookup-cli) This package is up to date.
[INFO] (macltestmodule) This package is up to date.
[INFO] (macmac) This package is up to date.
[INFO] (macman) This package is up to date.
[ERROR] (macnotifications) Could not get a response from API for this package. See below for details.
Traceback (most recent call last):
  File "/usr/local/lib/python3.7/dist-packages/pypicontents/api/pypi.py", line 264, in get_pkgdata
    timeout=10).read()
  File "/usr/lib/python3.7/urllib/request.py", line 222, in urlopen
    return opener.open(url, data, timeout)
  File "/usr/lib/python3.7/urllib/request.py", line 531, in open
    response = meth(req, response)
  File "/usr/lib/python3.7/urllib/request.py", line 641, in http_response
    'http', request, response, code, msg, hdrs)
  File "/usr/lib/python3.7/urllib/request.py", line 569, in error
    return self._call_chain(*args)
  File "/usr/lib/python3.7/urllib/request.py", line 503, in _call_chain
    result = func(*args)
  File "/usr/lib/python3.7/urllib/request.py", line 649, in http_error_default
    raise HTTPError(req.full_url, code, msg, hdrs, fp)
urllib.error.HTTPError: HTTP Error 404: Not Found

[INFO] (macondo) This package is up to date.
[INFO] (macos-display) This package is up to date.
[INFO] (macos-free) This package is up to date.
[INFO] (macos-keychain) This package is up to date.
[INFO] (macos-lswin) This package is up to date.
[INFO] (macos-speech) This package is up to date.
[INFO] (macos-tags) Data has been updated for this package.
[INFO] (macosko2015) This package is up to date.
[INFO] (macpacbot) This package is up to date.
[INFO] (macpack) This package is up to date.
[INFO] (macpackagetest) This package is up to date.
[INFO] (macpackagetest2) This package is up to date.
[INFO] (macpwn) This package is up to date.
[INFO] (macpy) This package is up to date.
[INFO] (macresources) This package is up to date.
[INFO] (macro) This package is up to date.
[INFO] (macro-expander) This package is up to date.
[ERROR] (macro-of-inline) This package does not have downloadable releases.
[INFO] (macro-parser) This package is up to date.
[INFO] (macrobase) This package is up to date.
[INFO] (macrobase-driver) This package is up to date.
[INFO] (macrobond-api-constants) This package is up to date.
[INFO] (macrocast) This package is up to date.
[INFO] (macrocomplex-builder) This package is up to date.
[INFO] (macrodynamics) This package is up to date.
[INFO] (macroeco) This package is up to date.
[INFO] (macroecon) This package is up to date.
[INFO] (macroecotools) This package is up to date.
[INFO] (macroetym) This package is up to date.
[INFO] (macrofi) This package is up to date.
[INFO] (macrolyzer) This package is up to date.
[INFO] (macromax) This package is up to date.
[INFO] (macronaut) This package is up to date.
[ERROR] (macropodus) Could not get a response from API for this package. See below for details.
Traceback (most recent call last):
  File "/usr/lib/python3.7/urllib/request.py", line 1319, in do_open
    encode_chunked=req.has_header('Transfer-encoding'))
  File "/usr/lib/python3.7/http/client.py", line 1252, in request
    self._send_request(method, url, body, headers, encode_chunked)
  File "/usr/lib/python3.7/http/client.py", line 1298, in _send_request
    self.endheaders(body, encode_chunked=encode_chunked)
  File "/usr/lib/python3.7/http/client.py", line 1247, in endheaders
    self._send_output(message_body, encode_chunked=encode_chunked)
  File "/usr/lib/python3.7/http/client.py", line 1026, in _send_output
    self.send(msg)
  File "/usr/lib/python3.7/http/client.py", line 966, in send
    self.connect()
  File "/usr/lib/python3.7/http/client.py", line 1414, in connect
    super().connect()
  File "/usr/lib/python3.7/http/client.py", line 938, in connect
    (self.host,self.port), self.timeout, self.source_address)
  File "/usr/lib/python3.7/socket.py", line 707, in create_connection
    for res in getaddrinfo(host, port, 0, SOCK_STREAM):
  File "/usr/lib/python3.7/socket.py", line 752, in getaddrinfo
    for res in _socket.getaddrinfo(host, port, family, type, proto, flags):
socket.gaierror: [Errno -3] Temporary failure in name resolution

During handling of the above exception, another exception occurred:

Traceback (most recent call last):
  File "/usr/local/lib/python3.7/dist-packages/pypicontents/api/pypi.py", line 264, in get_pkgdata
    timeout=10).read()
  File "/usr/lib/python3.7/urllib/request.py", line 222, in urlopen
    return opener.open(url, data, timeout)
  File "/usr/lib/python3.7/urllib/request.py", line 531, in open
    response = meth(req, response)
  File "/usr/lib/python3.7/urllib/request.py", line 641, in http_response
    'http', request, response, code, msg, hdrs)
  File "/usr/lib/python3.7/urllib/request.py", line 563, in error
    result = self._call_chain(*args)
  File "/usr/lib/python3.7/urllib/request.py", line 503, in _call_chain
    result = func(*args)
  File "/usr/lib/python3.7/urllib/request.py", line 755, in http_error_302
    return self.parent.open(new, timeout=req.timeout)
  File "/usr/lib/python3.7/urllib/request.py", line 525, in open
    response = self._open(req, data)
  File "/usr/lib/python3.7/urllib/request.py", line 543, in _open
    '_open', req)
  File "/usr/lib/python3.7/urllib/request.py", line 503, in _call_chain
    result = func(*args)
  File "/usr/lib/python3.7/urllib/request.py", line 1362, in https_open
    context=self._context, check_hostname=self._check_hostname)
  File "/usr/lib/python3.7/urllib/request.py", line 1321, in do_open
    raise URLError(err)
urllib.error.URLError: <urlopen error [Errno -3] Temporary failure in name resolution>

[INFO] (macropy) This package is up to date.
[INFO] (macropy01) This package is up to date.
[INFO] (macropy3) This package is up to date.
[INFO] (macros) This package is up to date.
[INFO] (macroscope) This package is up to date.
[INFO] (macs) This package is up to date.
[INFO] (macs2) This package is up to date.
[INFO] (macsafer) This package is up to date.
[INFO] (macspeechx) This package is up to date.
[INFO] (macspell) This package is up to date.
[INFO] (macss-tallies) This package is up to date.
[INFO] (mactopeer) This package is up to date.
[INFO] (macumba) This package is up to date.
[INFO] (macutil) This package is up to date.
[INFO] (macvendor) This package is up to date.
[ERROR] (macvpnhelper) Could not get a response from API for this package. See below for details.
Traceback (most recent call last):
  File "/usr/lib/python3.7/urllib/request.py", line 1319, in do_open
    encode_chunked=req.has_header('Transfer-encoding'))
  File "/usr/lib/python3.7/http/client.py", line 1252, in request
    self._send_request(method, url, body, headers, encode_chunked)
  File "/usr/lib/python3.7/http/client.py", line 1298, in _send_request
    self.endheaders(body, encode_chunked=encode_chunked)
  File "/usr/lib/python3.7/http/client.py", line 1247, in endheaders
    self._send_output(message_body, encode_chunked=encode_chunked)
  File "/usr/lib/python3.7/http/client.py", line 1026, in _send_output
    self.send(msg)
  File "/usr/lib/python3.7/http/client.py", line 966, in send
    self.connect()
  File "/usr/lib/python3.7/http/client.py", line 1414, in connect
    super().connect()
  File "/usr/lib/python3.7/http/client.py", line 938, in connect
    (self.host,self.port), self.timeout, self.source_address)
  File "/usr/lib/python3.7/socket.py", line 707, in create_connection
    for res in getaddrinfo(host, port, 0, SOCK_STREAM):
  File "/usr/lib/python3.7/socket.py", line 752, in getaddrinfo
    for res in _socket.getaddrinfo(host, port, family, type, proto, flags):
socket.gaierror: [Errno -3] Temporary failure in name resolution

During handling of the above exception, another exception occurred:

Traceback (most recent call last):
  File "/usr/local/lib/python3.7/dist-packages/pypicontents/api/pypi.py", line 264, in get_pkgdata
    timeout=10).read()
  File "/usr/lib/python3.7/urllib/request.py", line 222, in urlopen
    return opener.open(url, data, timeout)
  File "/usr/lib/python3.7/urllib/request.py", line 525, in open
    response = self._open(req, data)
  File "/usr/lib/python3.7/urllib/request.py", line 543, in _open
    '_open', req)
  File "/usr/lib/python3.7/urllib/request.py", line 503, in _call_chain
    result = func(*args)
  File "/usr/lib/python3.7/urllib/request.py", line 1362, in https_open
    context=self._context, check_hostname=self._check_hostname)
  File "/usr/lib/python3.7/urllib/request.py", line 1321, in do_open
    raise URLError(err)
urllib.error.URLError: <urlopen error [Errno -3] Temporary failure in name resolution>

[INFO] (maczhis-nester) This package is up to date.
[INFO] (mad) This package is up to date.
[INFO] (mad-import) This package is up to date.
[INFO] (mad2) This package is up to date.
[INFO] (madagascar) This package is up to date.
[INFO] (madai-link-analyze) This package is up to date.
[INFO] (madam) This package is up to date.
[INFO] (madame) This package is up to date.
[INFO] (madarrays) This package is up to date.
[INFO] (madbot) This package is up to date.
[INFO] (madbot-extra) This package is up to date.
[INFO] (madbot-meta) This package is up to date.
[INFO] (madcc) This package is up to date.
[INFO] (madchappy) This package is up to date.
[INFO] (madcore) This package is up to date.
[INFO] (maddy) This package is up to date.
[INFO] (made) This package is up to date.
[INFO] (madeiracloud) This package is up to date.
[INFO] (madeiracloudagent) This package is up to date.
[INFO] (madeirarpc) This package is up to date.
[INFO] (madeleine) This package is up to date.
[ERROR] (madeline) Could not get a response from API for this package. See below for details.
Traceback (most recent call last):
  File "/usr/local/lib/python3.7/dist-packages/pypicontents/api/pypi.py", line 264, in get_pkgdata
    timeout=10).read()
  File "/usr/lib/python3.7/urllib/request.py", line 222, in urlopen
    return opener.open(url, data, timeout)
  File "/usr/lib/python3.7/urllib/request.py", line 531, in open
    response = meth(req, response)
  File "/usr/lib/python3.7/urllib/request.py", line 641, in http_response
    'http', request, response, code, msg, hdrs)
  File "/usr/lib/python3.7/urllib/request.py", line 569, in error
    return self._call_chain(*args)
  File "/usr/lib/python3.7/urllib/request.py", line 503, in _call_chain
    result = func(*args)
  File "/usr/lib/python3.7/urllib/request.py", line 649, in http_error_default
    raise HTTPError(req.full_url, code, msg, hdrs, fp)
urllib.error.HTTPError: HTTP Error 404: Not Found

[ERROR] (madeline-proto) Could not get a response from API for this package. See below for details.
Traceback (most recent call last):
  File "/usr/local/lib/python3.7/dist-packages/pypicontents/api/pypi.py", line 264, in get_pkgdata
    timeout=10).read()
  File "/usr/lib/python3.7/urllib/request.py", line 222, in urlopen
    return opener.open(url, data, timeout)
  File "/usr/lib/python3.7/urllib/request.py", line 531, in open
    response = meth(req, response)
  File "/usr/lib/python3.7/urllib/request.py", line 641, in http_response
    'http', request, response, code, msg, hdrs)
  File "/usr/lib/python3.7/urllib/request.py", line 569, in error
    return self._call_chain(*args)
  File "/usr/lib/python3.7/urllib/request.py", line 503, in _call_chain
    result = func(*args)
  File "/usr/lib/python3.7/urllib/request.py", line 649, in http_error_default
    raise HTTPError(req.full_url, code, msg, hdrs, fp)
urllib.error.HTTPError: HTTP Error 404: Not Found

[ERROR] (madeline-proto-py) Could not get a response from API for this package. See below for details.
Traceback (most recent call last):
  File "/usr/local/lib/python3.7/dist-packages/pypicontents/api/pypi.py", line 264, in get_pkgdata
    timeout=10).read()
  File "/usr/lib/python3.7/urllib/request.py", line 222, in urlopen
    return opener.open(url, data, timeout)
  File "/usr/lib/python3.7/urllib/request.py", line 531, in open
    response = meth(req, response)
  File "/usr/lib/python3.7/urllib/request.py", line 641, in http_response
    'http', request, response, code, msg, hdrs)
  File "/usr/lib/python3.7/urllib/request.py", line 563, in error
    result = self._call_chain(*args)
  File "/usr/lib/python3.7/urllib/request.py", line 503, in _call_chain
    result = func(*args)
  File "/usr/lib/python3.7/urllib/request.py", line 755, in http_error_302
    return self.parent.open(new, timeout=req.timeout)
  File "/usr/lib/python3.7/urllib/request.py", line 531, in open
    response = meth(req, response)
  File "/usr/lib/python3.7/urllib/request.py", line 641, in http_response
    'http', request, response, code, msg, hdrs)
  File "/usr/lib/python3.7/urllib/request.py", line 569, in error
    return self._call_chain(*args)
  File "/usr/lib/python3.7/urllib/request.py", line 503, in _call_chain
    result = func(*args)
  File "/usr/lib/python3.7/urllib/request.py", line 649, in http_error_default
    raise HTTPError(req.full_url, code, msg, hdrs, fp)
urllib.error.HTTPError: HTTP Error 404: Not Found

[ERROR] (madeline-protopy) Could not get a response from API for this package. See below for details.
Traceback (most recent call last):
  File "/usr/local/lib/python3.7/dist-packages/pypicontents/api/pypi.py", line 264, in get_pkgdata
    timeout=10).read()
  File "/usr/lib/python3.7/urllib/request.py", line 222, in urlopen
    return opener.open(url, data, timeout)
  File "/usr/lib/python3.7/urllib/request.py", line 531, in open
    response = meth(req, response)
  File "/usr/lib/python3.7/urllib/request.py", line 641, in http_response
    'http', request, response, code, msg, hdrs)
  File "/usr/lib/python3.7/urllib/request.py", line 563, in error
    result = self._call_chain(*args)
  File "/usr/lib/python3.7/urllib/request.py", line 503, in _call_chain
    result = func(*args)
  File "/usr/lib/python3.7/urllib/request.py", line 755, in http_error_302
    return self.parent.open(new, timeout=req.timeout)
  File "/usr/lib/python3.7/urllib/request.py", line 531, in open
    response = meth(req, response)
  File "/usr/lib/python3.7/urllib/request.py", line 641, in http_response
    'http', request, response, code, msg, hdrs)
  File "/usr/lib/python3.7/urllib/request.py", line 569, in error
    return self._call_chain(*args)
  File "/usr/lib/python3.7/urllib/request.py", line 503, in _call_chain
    result = func(*args)
  File "/usr/lib/python3.7/urllib/request.py", line 649, in http_error_default
    raise HTTPError(req.full_url, code, msg, hdrs, fp)
urllib.error.HTTPError: HTTP Error 404: Not Found

[ERROR] (madeline-py) Could not get a response from API for this package. See below for details.
Traceback (most recent call last):
  File "/usr/local/lib/python3.7/dist-packages/pypicontents/api/pypi.py", line 264, in get_pkgdata
    timeout=10).read()
  File "/usr/lib/python3.7/urllib/request.py", line 222, in urlopen
    return opener.open(url, data, timeout)
  File "/usr/lib/python3.7/urllib/request.py", line 531, in open
    response = meth(req, response)
  File "/usr/lib/python3.7/urllib/request.py", line 641, in http_response
    'http', request, response, code, msg, hdrs)
  File "/usr/lib/python3.7/urllib/request.py", line 563, in error
    result = self._call_chain(*args)
  File "/usr/lib/python3.7/urllib/request.py", line 503, in _call_chain
    result = func(*args)
  File "/usr/lib/python3.7/urllib/request.py", line 755, in http_error_302
    return self.parent.open(new, timeout=req.timeout)
  File "/usr/lib/python3.7/urllib/request.py", line 531, in open
    response = meth(req, response)
  File "/usr/lib/python3.7/urllib/request.py", line 641, in http_response
    'http', request, response, code, msg, hdrs)
  File "/usr/lib/python3.7/urllib/request.py", line 569, in error
    return self._call_chain(*args)
  File "/usr/lib/python3.7/urllib/request.py", line 503, in _call_chain
    result = func(*args)
  File "/usr/lib/python3.7/urllib/request.py", line 649, in http_error_default
    raise HTTPError(req.full_url, code, msg, hdrs, fp)
urllib.error.HTTPError: HTTP Error 404: Not Found

[ERROR] (madelineproto) Could not get a response from API for this package. See below for details.
Traceback (most recent call last):
  File "/usr/local/lib/python3.7/dist-packages/pypicontents/api/pypi.py", line 264, in get_pkgdata
    timeout=10).read()
  File "/usr/lib/python3.7/urllib/request.py", line 222, in urlopen
    return opener.open(url, data, timeout)
  File "/usr/lib/python3.7/urllib/request.py", line 531, in open
    response = meth(req, response)
  File "/usr/lib/python3.7/urllib/request.py", line 641, in http_response
    'http', request, response, code, msg, hdrs)
  File "/usr/lib/python3.7/urllib/request.py", line 569, in error
    return self._call_chain(*args)
  File "/usr/lib/python3.7/urllib/request.py", line 503, in _call_chain
    result = func(*args)
  File "/usr/lib/python3.7/urllib/request.py", line 649, in http_error_default
    raise HTTPError(req.full_url, code, msg, hdrs, fp)
urllib.error.HTTPError: HTTP Error 404: Not Found

[ERROR] (madelineproto-py) Could not get a response from API for this package. See below for details.
Traceback (most recent call last):
  File "/usr/lib/python3.7/urllib/request.py", line 1319, in do_open
    encode_chunked=req.has_header('Transfer-encoding'))
  File "/usr/lib/python3.7/http/client.py", line 1252, in request
    self._send_request(method, url, body, headers, encode_chunked)
  File "/usr/lib/python3.7/http/client.py", line 1298, in _send_request
    self.endheaders(body, encode_chunked=encode_chunked)
  File "/usr/lib/python3.7/http/client.py", line 1247, in endheaders
    self._send_output(message_body, encode_chunked=encode_chunked)
  File "/usr/lib/python3.7/http/client.py", line 1026, in _send_output
    self.send(msg)
  File "/usr/lib/python3.7/http/client.py", line 966, in send
    self.connect()
  File "/usr/lib/python3.7/http/client.py", line 1414, in connect
    super().connect()
  File "/usr/lib/python3.7/http/client.py", line 938, in connect
    (self.host,self.port), self.timeout, self.source_address)
  File "/usr/lib/python3.7/socket.py", line 707, in create_connection
    for res in getaddrinfo(host, port, 0, SOCK_STREAM):
  File "/usr/lib/python3.7/socket.py", line 752, in getaddrinfo
    for res in _socket.getaddrinfo(host, port, family, type, proto, flags):
socket.gaierror: [Errno -3] Temporary failure in name resolution

During handling of the above exception, another exception occurred:

Traceback (most recent call last):
  File "/usr/local/lib/python3.7/dist-packages/pypicontents/api/pypi.py", line 264, in get_pkgdata
    timeout=10).read()
  File "/usr/lib/python3.7/urllib/request.py", line 222, in urlopen
    return opener.open(url, data, timeout)
  File "/usr/lib/python3.7/urllib/request.py", line 525, in open
    response = self._open(req, data)
  File "/usr/lib/python3.7/urllib/request.py", line 543, in _open
    '_open', req)
  File "/usr/lib/python3.7/urllib/request.py", line 503, in _call_chain
    result = func(*args)
  File "/usr/lib/python3.7/urllib/request.py", line 1362, in https_open
    context=self._context, check_hostname=self._check_hostname)
  File "/usr/lib/python3.7/urllib/request.py", line 1321, in do_open
    raise URLError(err)
urllib.error.URLError: <urlopen error [Errno -3] Temporary failure in name resolution>

[ERROR] (madelineprotopy) Could not get a response from API for this package. See below for details.
Traceback (most recent call last):
  File "/usr/local/lib/python3.7/dist-packages/pypicontents/api/pypi.py", line 264, in get_pkgdata
    timeout=10).read()
  File "/usr/lib/python3.7/urllib/request.py", line 222, in urlopen
    return opener.open(url, data, timeout)
  File "/usr/lib/python3.7/urllib/request.py", line 531, in open
    response = meth(req, response)
  File "/usr/lib/python3.7/urllib/request.py", line 641, in http_response
    'http', request, response, code, msg, hdrs)
  File "/usr/lib/python3.7/urllib/request.py", line 569, in error
    return self._call_chain(*args)
  File "/usr/lib/python3.7/urllib/request.py", line 503, in _call_chain
    result = func(*args)
  File "/usr/lib/python3.7/urllib/request.py", line 649, in http_error_default
    raise HTTPError(req.full_url, code, msg, hdrs, fp)
urllib.error.HTTPError: HTTP Error 404: Not Found

[ERROR] (madelinepy) Could not get a response from API for this package. See below for details.
Traceback (most recent call last):
  File "/usr/local/lib/python3.7/dist-packages/pypicontents/api/pypi.py", line 264, in get_pkgdata
    timeout=10).read()
  File "/usr/lib/python3.7/urllib/request.py", line 222, in urlopen
    return opener.open(url, data, timeout)
  File "/usr/lib/python3.7/urllib/request.py", line 531, in open
    response = meth(req, response)
  File "/usr/lib/python3.7/urllib/request.py", line 641, in http_response
    'http', request, response, code, msg, hdrs)
  File "/usr/lib/python3.7/urllib/request.py", line 569, in error
    return self._call_chain(*args)
  File "/usr/lib/python3.7/urllib/request.py", line 503, in _call_chain
    result = func(*args)
  File "/usr/lib/python3.7/urllib/request.py", line 649, in http_error_default
    raise HTTPError(req.full_url, code, msg, hdrs, fp)
urllib.error.HTTPError: HTTP Error 404: Not Found

[ERROR] (madeout) This package does not have downloadable releases.
[INFO] (madera) This package is up to date.
[INFO] (madglory-ezl) This package is up to date.
[INFO] (madgui) This package is up to date.
[INFO] (madhupdf) This package is up to date.
[INFO] (madi2) This package is up to date.
[INFO] (madic) This package is up to date.
[INFO] (madiolahb) This package is up to date.
[INFO] (madison-axi) This package is up to date.
[INFO] (madison-wcb) This package is up to date.
[ERROR] (madiyanester) This package does not have downloadable releases.
[INFO] (madlab) This package is up to date.
[INFO] (madlag3dware) This package is up to date.
[INFO] (madliar) This package is up to date.
[INFO] (madlib) This package is up to date.
[INFO] (madmac) This package is up to date.
[INFO] (madmimi) This package is up to date.
[INFO] (madmin) This package is up to date.
[INFO] (madminer) This package is up to date.
[INFO] (madmom) This package is up to date.
[INFO] (madness) This package is up to date.
[INFO] (mado-test-wrapper) This package is up to date.
[INFO] (mado-wrappers) This package is up to date.
[INFO] (madoka) This package is up to date.
[ERROR] (madpipes) Could not get a response from API for this package. See below for details.
Traceback (most recent call last):
  File "/usr/local/lib/python3.7/dist-packages/pypicontents/api/pypi.py", line 264, in get_pkgdata
    timeout=10).read()
  File "/usr/lib/python3.7/urllib/request.py", line 222, in urlopen
    return opener.open(url, data, timeout)
  File "/usr/lib/python3.7/urllib/request.py", line 531, in open
    response = meth(req, response)
  File "/usr/lib/python3.7/urllib/request.py", line 641, in http_response
    'http', request, response, code, msg, hdrs)
  File "/usr/lib/python3.7/urllib/request.py", line 569, in error
    return self._call_chain(*args)
  File "/usr/lib/python3.7/urllib/request.py", line 503, in _call_chain
    result = func(*args)
  File "/usr/lib/python3.7/urllib/request.py", line 649, in http_error_default
    raise HTTPError(req.full_url, code, msg, hdrs, fp)
urllib.error.HTTPError: HTTP Error 404: Not Found

[INFO] (madplot) This package is up to date.
[ERROR] (madpy) This package does not have downloadable releases.
[INFO] (madpython) This package is up to date.
[INFO] (madrigalweb) This package is up to date.
[INFO] (madrona) This package is up to date.
[INFO] (mads) This package is up to date.
[WARNING] 
[WARNING] Processing has taken more than 2100 seconds. Interrupting.
[WARNING] Processing will continue in next iteration.
[WARNING] 
[INFO] 
[INFO] 
[INFO] Total packages: 11962
[INFO]     Packages processed: 433
[INFO]         Packages updated: 2
[INFO]         Packages up-to-date: 382
[INFO]         Packages without response: 36
[INFO]         Packages without urls: 0
[INFO]         Packages without downloads: 12
[INFO]         Packages with data errors: 1
[INFO]     Packages not processed: 11529
[INFO] 
[INFO] 
[INFO] Ending execution.
