[INFO] Starting execution.
[INFO] Downloading package list from PyPI ...
[ERROR] (m) This package does not have downloadable releases.
[INFO] (m-lib) This package is up to date.
[INFO] (m-lib-defenc) This package is up to date.
[INFO] (m-lib-full) This package is up to date.
[INFO] (m-librarian) This package is up to date.
[INFO] (m-loop) This package is up to date.
[INFO] (m-nester) This package is up to date.
[INFO] (m-pool) This package is up to date.
[INFO] (m-robot) This package is up to date.
[INFO] (m-schedule) This package is up to date.
[INFO] (m-singleton) This package is up to date.
[INFO] (m-threadpool) This package is up to date.
[INFO] (m-transliteration) This package is up to date.
[INFO] (m01-bayes) This package is up to date.
[INFO] (m01-fake) This package is up to date.
[INFO] (m01-form) This package is up to date.
[INFO] (m01-fs) This package is up to date.
[INFO] (m01-gmap) This package is up to date.
[INFO] (m01-grid) This package is up to date.
[INFO] (m01-i18n) This package is up to date.
[INFO] (m01-logger) This package is up to date.
[INFO] (m01-mongo) This package is up to date.
[INFO] (m01-mongofake) This package is up to date.
[INFO] (m01-publisher) This package is up to date.
[INFO] (m01-remote) This package is up to date.
[INFO] (m01-searcher) This package is up to date.
[INFO] (m01-session) This package is up to date.
[INFO] (m01-stub) This package is up to date.
[INFO] (m01-zfs) This package is up to date.
[INFO] (m16-mlutils) This package is up to date.
[ERROR] (m209) This package does not have downloadable releases.
[INFO] (m26) This package is up to date.
[INFO] (m2bk) This package is up to date.
[INFO] (m2core) This package is up to date.
[INFO] (m2crypto) This package is up to date.
[INFO] (m2cryptowin32) This package is up to date.
[INFO] (m2cryptowin64) This package is up to date.
[INFO] (m2ext) This package is up to date.
[INFO] (m2m-certificates) This package is up to date.
[INFO] (m2mclient) This package is up to date.
[ERROR] (m2mdata) This package does not have downloadable releases.
[INFO] (m2mdict) This package is up to date.
[INFO] (m2r) This package is up to date.
[INFO] (m2secret) This package is up to date.
[INFO] (m2secret-py3) This package is up to date.
[ERROR] (m2tool) This package does not have downloadable releases.
[INFO] (m2tools) This package is up to date.
[INFO] (m2translate) This package is up to date.
[INFO] (m2websocket) This package is up to date.
[INFO] (m2wsgi) This package is up to date.
[INFO] (m2wsgid) This package is up to date.
[INFO] (m2x) This package is up to date.
[INFO] (m2x-mqtt) This package is up to date.
[INFO] (m3) This package is up to date.
[INFO] (m3-aspell-python) This package is up to date.
[INFO] (m3-asynctask) This package is up to date.
[INFO] (m3-audit) This package is up to date.
[INFO] (m3-autologin) This package is up to date.
[INFO] (m3-calendar) This package is up to date.
[INFO] (m3-cdecimal) This package is up to date.
[INFO] (m3-checkie) This package is up to date.
[INFO] (m3-consolequery) This package is up to date.
[INFO] (m3-core) This package is up to date.
[INFO] (m3-datalogging) This package is up to date.
[INFO] (m3-dbfpy) This package is up to date.
[INFO] (m3-debuggie) This package is up to date.
[INFO] (m3-designer) This package is up to date.
[INFO] (m3-dicts) This package is up to date.
[INFO] (m3-email) This package is up to date.
[INFO] (m3-example-app) This package is up to date.
[INFO] (m3-excel-reporting) This package is up to date.
[INFO] (m3-fias) This package is up to date.
[INFO] (m3-kladr) This package is up to date.
[INFO] (m3-legacy) This package is up to date.
[INFO] (m3-libsmev) This package is up to date.
[INFO] (m3-libxml2-python) This package is up to date.
[INFO] (m3-license) This package is up to date.
[INFO] (m3-logview) This package is up to date.
[INFO] (m3-mutex) This package is up to date.
[INFO] (m3-objectpack) This package is up to date.
[INFO] (m3-pil) This package is up to date.
[INFO] (m3-pushme) This package is up to date.
[INFO] (m3-recordpack) This package is up to date.
[INFO] (m3-registry) This package is up to date.
[INFO] (m3-report-generator) This package is up to date.
[INFO] (m3-simple-report) This package is up to date.
[INFO] (m3-soap) This package is up to date.
[INFO] (m3-spyne-smev) This package is up to date.
[INFO] (m3-ssosp) This package is up to date.
[INFO] (m3-task-scheduler) This package is up to date.
[INFO] (m3-ui) This package is up to date.
[INFO] (m3-users) This package is up to date.
[INFO] (m3-wellbehaved) This package is up to date.
[INFO] (m3-xmldsig) This package is up to date.
[INFO] (m3-zsi) This package is up to date.
[INFO] (m30w) This package is up to date.
[INFO] (m3cdecimal) This package is up to date.
[INFO] (m3core) This package is up to date.
[INFO] (m3d) This package is up to date.
[INFO] (m3m3s) This package is up to date.
[INFO] (m3project-creator) This package is up to date.
[ERROR] (m3s-scraper) Could not get a response from API for this package. See below for details.
Traceback (most recent call last):
  File "/usr/lib/python3.5/urllib/request.py", line 1254, in do_open
    h.request(req.get_method(), req.selector, req.data, headers)
  File "/usr/lib/python3.5/http/client.py", line 1107, in request
    self._send_request(method, url, body, headers)
  File "/usr/lib/python3.5/http/client.py", line 1152, in _send_request
    self.endheaders(body)
  File "/usr/lib/python3.5/http/client.py", line 1103, in endheaders
    self._send_output(message_body)
  File "/usr/lib/python3.5/http/client.py", line 934, in _send_output
    self.send(msg)
  File "/usr/lib/python3.5/http/client.py", line 877, in send
    self.connect()
  File "/usr/lib/python3.5/http/client.py", line 1253, in connect
    super().connect()
  File "/usr/lib/python3.5/http/client.py", line 849, in connect
    (self.host,self.port), self.timeout, self.source_address)
  File "/usr/lib/python3.5/socket.py", line 712, in create_connection
    raise err
  File "/usr/lib/python3.5/socket.py", line 703, in create_connection
    sock.connect(sa)
OSError: [Errno 99] Cannot assign requested address

During handling of the above exception, another exception occurred:

Traceback (most recent call last):
  File "/usr/local/lib/python3.5/dist-packages/pypicontents/api/pypi.py", line 264, in get_pkgdata
    timeout=10).read()
  File "/usr/lib/python3.5/urllib/request.py", line 163, in urlopen
    return opener.open(url, data, timeout)
  File "/usr/lib/python3.5/urllib/request.py", line 466, in open
    response = self._open(req, data)
  File "/usr/lib/python3.5/urllib/request.py", line 484, in _open
    '_open', req)
  File "/usr/lib/python3.5/urllib/request.py", line 444, in _call_chain
    result = func(*args)
  File "/usr/lib/python3.5/urllib/request.py", line 1297, in https_open
    context=self._context, check_hostname=self._check_hostname)
  File "/usr/lib/python3.5/urllib/request.py", line 1256, in do_open
    raise URLError(err)
urllib.error.URLError: <urlopen error [Errno 99] Cannot assign requested address>

[INFO] (m3u-dump) This package is up to date.
[INFO] (m3u8) This package is up to date.
[INFO] (m3u8-downloader) This package is up to date.
[INFO] (m3u8-generator) This package is up to date.
[INFO] (m3ull) This package is up to date.
[INFO] (m3uspiff) This package is up to date.
[INFO] (m3utorss) This package is up to date.
[INFO] (m4pomodoro) This package is up to date.
[INFO] (m4us) This package is up to date.
[INFO] (m5) This package is up to date.
[ERROR] (m5fahrrad) This package does not have downloadable releases.
[INFO] (m79-hello) This package is up to date.
[INFO] (m79atomic) This package is up to date.
[INFO] (m79commons) This package is up to date.
[INFO] (m7pub-pylibs) This package is up to date.
[INFO] (m9dicts) This package is up to date.
[INFO] (ma) This package is up to date.
[INFO] (ma-mongo) This package is up to date.
[INFO] (ma-shell) This package is up to date.
[INFO] (maads) This package is up to date.
[INFO] (maahinkainen-portlet-googlecalendar) This package is up to date.
[INFO] (maak) This package is up to date.
[INFO] (maas) This package is up to date.
[INFO] (maasclient) This package is up to date.
[INFO] (maasutil) This package is up to date.
[INFO] (maat) This package is up to date.
[INFO] (maat2) This package is up to date.
[INFO] (mab) This package is up to date.
[INFO] (mabandit) This package is up to date.
[INFO] (maboss) This package is up to date.
[ERROR] (mabot) Could not extract data from this package. See below for details.
This package download URL does not point to a valid file: "http://code.google.com/p/robotframework-mabot/downloads/list"
[INFO] (mabpy) This package is up to date.
[INFO] (mabs) This package is up to date.
[INFO] (mac) This package is up to date.
[INFO] (mac-alias) This package is up to date.
[INFO] (mac-alias-cli) This package is up to date.
[INFO] (mac-appify-cli) This package is up to date.
[INFO] (mac-copy-capture) This package is up to date.
[INFO] (mac-desktop-cli) This package is up to date.
[INFO] (mac-notification) This package is up to date.
[INFO] (mac-py) This package is up to date.
[INFO] (mac-screensaver) This package is up to date.
[INFO] (mac-screensaver-cli) This package is up to date.
[INFO] (mac-wallpaper) This package is up to date.
[INFO] (mac-wallpaper-cli) This package is up to date.
[INFO] (mac-youtube-cli) This package is up to date.
[INFO] (mac2vendors) This package is up to date.
[INFO] (maca) This package is up to date.
[INFO] (macaca) This package is up to date.
[INFO] (macadamia) This package is up to date.
[INFO] (macaddresslink) This package is up to date.
[INFO] (macaron) This package is up to date.
[INFO] (macaroonbakery) This package is up to date.
[INFO] (macattc) This package is up to date.
[INFO] (macauthlib) This package is up to date.
[INFO] (macaw) This package is up to date.
[ERROR] (macbook) This package does not have downloadable releases.
[INFO] (maccabistats) This package is up to date.
[ERROR] (maccabistats-web) Could not get a response from API for this package. See below for details.
Traceback (most recent call last):
  File "/usr/local/lib/python3.5/dist-packages/pypicontents/api/pypi.py", line 264, in get_pkgdata
    timeout=10).read()
  File "/usr/lib/python3.5/urllib/request.py", line 163, in urlopen
    return opener.open(url, data, timeout)
  File "/usr/lib/python3.5/urllib/request.py", line 472, in open
    response = meth(req, response)
  File "/usr/lib/python3.5/urllib/request.py", line 582, in http_response
    'http', request, response, code, msg, hdrs)
  File "/usr/lib/python3.5/urllib/request.py", line 510, in error
    return self._call_chain(*args)
  File "/usr/lib/python3.5/urllib/request.py", line 444, in _call_chain
    result = func(*args)
  File "/usr/lib/python3.5/urllib/request.py", line 590, in http_error_default
    raise HTTPError(req.full_url, code, msg, hdrs, fp)
urllib.error.HTTPError: HTTP Error 404: Not Found

[INFO] (maccc) This package is up to date.
[INFO] (macdaily) Data has been updated for this package.
[INFO] (macdict) This package is up to date.
[ERROR] (macdive) This package does not have downloadable releases.
[INFO] (macdtrader) This package is up to date.
[INFO] (mace) This package is up to date.
[INFO] (macfsevents) This package is up to date.
[INFO] (macgyverproject) This package is up to date.
[INFO] (mach) This package is up to date.
[INFO] (mach-py) This package is up to date.
[INFO] (mach3) This package is up to date.
[INFO] (mach9) This package is up to date.
[INFO] (machete) This package is up to date.
[INFO] (machi) This package is up to date.
[INFO] (machina) This package is up to date.
[ERROR] (machina-python) This package does not have downloadable releases.
[INFO] (machinae) This package is up to date.
[INFO] (machine) This package is up to date.
[INFO] (machine-engine-python) This package is up to date.
[INFO] (machine-learning-py) This package is up to date.
[INFO] (machinegun) This package is up to date.
[INFO] (machineio) This package is up to date.
[INFO] (machinelearning) This package is up to date.
[INFO] (machinelearning-master) This package is up to date.
[INFO] (machinelearningstanford) This package is up to date.
[INFO] (machinelearnlib) This package is up to date.
[INFO] (machinepack) This package is up to date.
[INFO] (machinerry) This package is up to date.
[INFO] (machines) This package is up to date.
[INFO] (machinetalk-protobuf) This package is up to date.
[INFO] (machinist) This package is up to date.
[INFO] (macho-analysis) This package is up to date.
[INFO] (macho-parser) This package is up to date.
[INFO] (machobot) This package is up to date.
[INFO] (macholib) This package is up to date.
[INFO] (machomachomangler) This package is up to date.
[ERROR] (machop) Could not get a response from API for this package. See below for details.
Traceback (most recent call last):
  File "/usr/local/lib/python3.5/dist-packages/pypicontents/api/pypi.py", line 264, in get_pkgdata
    timeout=10).read()
  File "/usr/lib/python3.5/urllib/request.py", line 163, in urlopen
    return opener.open(url, data, timeout)
  File "/usr/lib/python3.5/urllib/request.py", line 472, in open
    response = meth(req, response)
  File "/usr/lib/python3.5/urllib/request.py", line 582, in http_response
    'http', request, response, code, msg, hdrs)
  File "/usr/lib/python3.5/urllib/request.py", line 510, in error
    return self._call_chain(*args)
  File "/usr/lib/python3.5/urllib/request.py", line 444, in _call_chain
    result = func(*args)
  File "/usr/lib/python3.5/urllib/request.py", line 590, in http_error_default
    raise HTTPError(req.full_url, code, msg, hdrs, fp)
urllib.error.HTTPError: HTTP Error 404: Not Found

[INFO] (machotools) This package is up to date.
[INFO] (macht) This package is up to date.
[INFO] (mack) This package is up to date.
[INFO] (mackerel) This package is up to date.
[INFO] (mackerel-client) This package is up to date.
[INFO] (mackerel-clienthde) This package is up to date.
[INFO] (mackinac) This package is up to date.
[INFO] (mackup) This package is up to date.
[INFO] (maclocate) This package is up to date.
[INFO] (macltestmodule) This package is up to date.
[INFO] (macman) This package is up to date.
[INFO] (macnotifications) This package is up to date.
[INFO] (macondo) This package is up to date.
[INFO] (macos-free) This package is up to date.
[INFO] (macosko2015) This package is up to date.
[INFO] (macpacbot) This package is up to date.
[INFO] (macpack) This package is up to date.
[INFO] (macpy) This package is up to date.
[INFO] (macro) This package is up to date.
[ERROR] (macro-of-inline) This package does not have downloadable releases.
[INFO] (macrocast) This package is up to date.
[INFO] (macroeco) This package is up to date.
[INFO] (macroecon) This package is up to date.
[INFO] (macroecotools) This package is up to date.
[INFO] (macroetym) This package is up to date.
[INFO] (macrofi) This package is up to date.
[INFO] (macrolyzer) This package is up to date.
[INFO] (macronaut) This package is up to date.
[INFO] (macropy) This package is up to date.
[INFO] (macropy3) This package is up to date.
[INFO] (macros) This package is up to date.
[INFO] (macrosql) This package is up to date.
[INFO] (macs) This package is up to date.
[INFO] (macs2) This package is up to date.
[INFO] (macsafer) This package is up to date.
[INFO] (macspeechx) This package is up to date.
[INFO] (macspell) This package is up to date.
[INFO] (macss-tallies) This package is up to date.
[INFO] (mactools) This package is up to date.
[INFO] (mactopeer) This package is up to date.
[INFO] (macumba) This package is up to date.
[INFO] (maczhis-nester) This package is up to date.
[INFO] (mad) This package is up to date.
[INFO] (mad2) This package is up to date.
[INFO] (madai-link-analyze) This package is up to date.
[INFO] (madam) This package is up to date.
[INFO] (madame) This package is up to date.
[INFO] (madarrays) This package is up to date.
[INFO] (madbot) This package is up to date.
[INFO] (madbot-extra) This package is up to date.
[INFO] (madbot-meta) This package is up to date.
[INFO] (madcc) This package is up to date.
[INFO] (madcore) This package is up to date.
[INFO] (maddy) This package is up to date.
[INFO] (madeiracloud) This package is up to date.
[INFO] (madeiracloudagent) This package is up to date.
[INFO] (madeirarpc) This package is up to date.
[ERROR] (madeline) Could not get a response from API for this package. See below for details.
Traceback (most recent call last):
  File "/usr/local/lib/python3.5/dist-packages/pypicontents/api/pypi.py", line 264, in get_pkgdata
    timeout=10).read()
  File "/usr/lib/python3.5/urllib/request.py", line 163, in urlopen
    return opener.open(url, data, timeout)
  File "/usr/lib/python3.5/urllib/request.py", line 472, in open
    response = meth(req, response)
  File "/usr/lib/python3.5/urllib/request.py", line 582, in http_response
    'http', request, response, code, msg, hdrs)
  File "/usr/lib/python3.5/urllib/request.py", line 510, in error
    return self._call_chain(*args)
  File "/usr/lib/python3.5/urllib/request.py", line 444, in _call_chain
    result = func(*args)
  File "/usr/lib/python3.5/urllib/request.py", line 590, in http_error_default
    raise HTTPError(req.full_url, code, msg, hdrs, fp)
urllib.error.HTTPError: HTTP Error 404: Not Found

[ERROR] (madeline-proto) Could not get a response from API for this package. See below for details.
Traceback (most recent call last):
  File "/usr/local/lib/python3.5/dist-packages/pypicontents/api/pypi.py", line 264, in get_pkgdata
    timeout=10).read()
  File "/usr/lib/python3.5/urllib/request.py", line 163, in urlopen
    return opener.open(url, data, timeout)
  File "/usr/lib/python3.5/urllib/request.py", line 472, in open
    response = meth(req, response)
  File "/usr/lib/python3.5/urllib/request.py", line 582, in http_response
    'http', request, response, code, msg, hdrs)
  File "/usr/lib/python3.5/urllib/request.py", line 510, in error
    return self._call_chain(*args)
  File "/usr/lib/python3.5/urllib/request.py", line 444, in _call_chain
    result = func(*args)
  File "/usr/lib/python3.5/urllib/request.py", line 590, in http_error_default
    raise HTTPError(req.full_url, code, msg, hdrs, fp)
urllib.error.HTTPError: HTTP Error 404: Not Found

[ERROR] (madeline-proto-py) Could not get a response from API for this package. See below for details.
Traceback (most recent call last):
  File "/usr/local/lib/python3.5/dist-packages/pypicontents/api/pypi.py", line 264, in get_pkgdata
    timeout=10).read()
  File "/usr/lib/python3.5/urllib/request.py", line 163, in urlopen
    return opener.open(url, data, timeout)
  File "/usr/lib/python3.5/urllib/request.py", line 472, in open
    response = meth(req, response)
  File "/usr/lib/python3.5/urllib/request.py", line 582, in http_response
    'http', request, response, code, msg, hdrs)
  File "/usr/lib/python3.5/urllib/request.py", line 504, in error
    result = self._call_chain(*args)
  File "/usr/lib/python3.5/urllib/request.py", line 444, in _call_chain
    result = func(*args)
  File "/usr/lib/python3.5/urllib/request.py", line 696, in http_error_302
    return self.parent.open(new, timeout=req.timeout)
  File "/usr/lib/python3.5/urllib/request.py", line 472, in open
    response = meth(req, response)
  File "/usr/lib/python3.5/urllib/request.py", line 582, in http_response
    'http', request, response, code, msg, hdrs)
  File "/usr/lib/python3.5/urllib/request.py", line 510, in error
    return self._call_chain(*args)
  File "/usr/lib/python3.5/urllib/request.py", line 444, in _call_chain
    result = func(*args)
  File "/usr/lib/python3.5/urllib/request.py", line 590, in http_error_default
    raise HTTPError(req.full_url, code, msg, hdrs, fp)
urllib.error.HTTPError: HTTP Error 404: Not Found

[ERROR] (madeline-protopy) Could not get a response from API for this package. See below for details.
Traceback (most recent call last):
  File "/usr/local/lib/python3.5/dist-packages/pypicontents/api/pypi.py", line 264, in get_pkgdata
    timeout=10).read()
  File "/usr/lib/python3.5/urllib/request.py", line 163, in urlopen
    return opener.open(url, data, timeout)
  File "/usr/lib/python3.5/urllib/request.py", line 472, in open
    response = meth(req, response)
  File "/usr/lib/python3.5/urllib/request.py", line 582, in http_response
    'http', request, response, code, msg, hdrs)
  File "/usr/lib/python3.5/urllib/request.py", line 504, in error
    result = self._call_chain(*args)
  File "/usr/lib/python3.5/urllib/request.py", line 444, in _call_chain
    result = func(*args)
  File "/usr/lib/python3.5/urllib/request.py", line 696, in http_error_302
    return self.parent.open(new, timeout=req.timeout)
  File "/usr/lib/python3.5/urllib/request.py", line 472, in open
    response = meth(req, response)
  File "/usr/lib/python3.5/urllib/request.py", line 582, in http_response
    'http', request, response, code, msg, hdrs)
  File "/usr/lib/python3.5/urllib/request.py", line 510, in error
    return self._call_chain(*args)
  File "/usr/lib/python3.5/urllib/request.py", line 444, in _call_chain
    result = func(*args)
  File "/usr/lib/python3.5/urllib/request.py", line 590, in http_error_default
    raise HTTPError(req.full_url, code, msg, hdrs, fp)
urllib.error.HTTPError: HTTP Error 404: Not Found

[ERROR] (madeline-py) Could not get a response from API for this package. See below for details.
Traceback (most recent call last):
  File "/usr/local/lib/python3.5/dist-packages/pypicontents/api/pypi.py", line 264, in get_pkgdata
    timeout=10).read()
  File "/usr/lib/python3.5/urllib/request.py", line 163, in urlopen
    return opener.open(url, data, timeout)
  File "/usr/lib/python3.5/urllib/request.py", line 472, in open
    response = meth(req, response)
  File "/usr/lib/python3.5/urllib/request.py", line 582, in http_response
    'http', request, response, code, msg, hdrs)
  File "/usr/lib/python3.5/urllib/request.py", line 504, in error
    result = self._call_chain(*args)
  File "/usr/lib/python3.5/urllib/request.py", line 444, in _call_chain
    result = func(*args)
  File "/usr/lib/python3.5/urllib/request.py", line 696, in http_error_302
    return self.parent.open(new, timeout=req.timeout)
  File "/usr/lib/python3.5/urllib/request.py", line 472, in open
    response = meth(req, response)
  File "/usr/lib/python3.5/urllib/request.py", line 582, in http_response
    'http', request, response, code, msg, hdrs)
  File "/usr/lib/python3.5/urllib/request.py", line 510, in error
    return self._call_chain(*args)
  File "/usr/lib/python3.5/urllib/request.py", line 444, in _call_chain
    result = func(*args)
  File "/usr/lib/python3.5/urllib/request.py", line 590, in http_error_default
    raise HTTPError(req.full_url, code, msg, hdrs, fp)
urllib.error.HTTPError: HTTP Error 404: Not Found

[ERROR] (madelineproto) Could not get a response from API for this package. See below for details.
Traceback (most recent call last):
  File "/usr/local/lib/python3.5/dist-packages/pypicontents/api/pypi.py", line 264, in get_pkgdata
    timeout=10).read()
  File "/usr/lib/python3.5/urllib/request.py", line 163, in urlopen
    return opener.open(url, data, timeout)
  File "/usr/lib/python3.5/urllib/request.py", line 472, in open
    response = meth(req, response)
  File "/usr/lib/python3.5/urllib/request.py", line 582, in http_response
    'http', request, response, code, msg, hdrs)
  File "/usr/lib/python3.5/urllib/request.py", line 510, in error
    return self._call_chain(*args)
  File "/usr/lib/python3.5/urllib/request.py", line 444, in _call_chain
    result = func(*args)
  File "/usr/lib/python3.5/urllib/request.py", line 590, in http_error_default
    raise HTTPError(req.full_url, code, msg, hdrs, fp)
urllib.error.HTTPError: HTTP Error 404: Not Found

[ERROR] (madelineproto-py) Could not get a response from API for this package. See below for details.
Traceback (most recent call last):
  File "/usr/local/lib/python3.5/dist-packages/pypicontents/api/pypi.py", line 264, in get_pkgdata
    timeout=10).read()
  File "/usr/lib/python3.5/urllib/request.py", line 163, in urlopen
    return opener.open(url, data, timeout)
  File "/usr/lib/python3.5/urllib/request.py", line 472, in open
    response = meth(req, response)
  File "/usr/lib/python3.5/urllib/request.py", line 582, in http_response
    'http', request, response, code, msg, hdrs)
  File "/usr/lib/python3.5/urllib/request.py", line 504, in error
    result = self._call_chain(*args)
  File "/usr/lib/python3.5/urllib/request.py", line 444, in _call_chain
    result = func(*args)
  File "/usr/lib/python3.5/urllib/request.py", line 696, in http_error_302
    return self.parent.open(new, timeout=req.timeout)
  File "/usr/lib/python3.5/urllib/request.py", line 472, in open
    response = meth(req, response)
  File "/usr/lib/python3.5/urllib/request.py", line 582, in http_response
    'http', request, response, code, msg, hdrs)
  File "/usr/lib/python3.5/urllib/request.py", line 510, in error
    return self._call_chain(*args)
  File "/usr/lib/python3.5/urllib/request.py", line 444, in _call_chain
    result = func(*args)
  File "/usr/lib/python3.5/urllib/request.py", line 590, in http_error_default
    raise HTTPError(req.full_url, code, msg, hdrs, fp)
urllib.error.HTTPError: HTTP Error 404: Not Found

[ERROR] (madelineprotopy) Could not get a response from API for this package. See below for details.
Traceback (most recent call last):
  File "/usr/local/lib/python3.5/dist-packages/pypicontents/api/pypi.py", line 264, in get_pkgdata
    timeout=10).read()
  File "/usr/lib/python3.5/urllib/request.py", line 163, in urlopen
    return opener.open(url, data, timeout)
  File "/usr/lib/python3.5/urllib/request.py", line 472, in open
    response = meth(req, response)
  File "/usr/lib/python3.5/urllib/request.py", line 582, in http_response
    'http', request, response, code, msg, hdrs)
  File "/usr/lib/python3.5/urllib/request.py", line 510, in error
    return self._call_chain(*args)
  File "/usr/lib/python3.5/urllib/request.py", line 444, in _call_chain
    result = func(*args)
  File "/usr/lib/python3.5/urllib/request.py", line 590, in http_error_default
    raise HTTPError(req.full_url, code, msg, hdrs, fp)
urllib.error.HTTPError: HTTP Error 404: Not Found

[ERROR] (madelinepy) Could not get a response from API for this package. See below for details.
Traceback (most recent call last):
  File "/usr/local/lib/python3.5/dist-packages/pypicontents/api/pypi.py", line 264, in get_pkgdata
    timeout=10).read()
  File "/usr/lib/python3.5/urllib/request.py", line 163, in urlopen
    return opener.open(url, data, timeout)
  File "/usr/lib/python3.5/urllib/request.py", line 472, in open
    response = meth(req, response)
  File "/usr/lib/python3.5/urllib/request.py", line 582, in http_response
    'http', request, response, code, msg, hdrs)
  File "/usr/lib/python3.5/urllib/request.py", line 510, in error
    return self._call_chain(*args)
  File "/usr/lib/python3.5/urllib/request.py", line 444, in _call_chain
    result = func(*args)
  File "/usr/lib/python3.5/urllib/request.py", line 590, in http_error_default
    raise HTTPError(req.full_url, code, msg, hdrs, fp)
urllib.error.HTTPError: HTTP Error 404: Not Found

[ERROR] (madeout) This package does not have downloadable releases.
[INFO] (madglory-ezl) This package is up to date.
[INFO] (madgui) This package is up to date.
[INFO] (madic) This package is up to date.
[INFO] (madiolahb) This package is up to date.
[INFO] (madison-wcb) This package is up to date.
[ERROR] (madiyanester) This package does not have downloadable releases.
[INFO] (madlag3dware) This package is up to date.
[INFO] (madliar) This package is up to date.
[INFO] (madlib) This package is up to date.
[INFO] (madmimi) This package is up to date.
[ERROR] (madmin) Could not get a response from API for this package. See below for details.
Traceback (most recent call last):
  File "/usr/lib/python3.5/urllib/request.py", line 1254, in do_open
    h.request(req.get_method(), req.selector, req.data, headers)
  File "/usr/lib/python3.5/http/client.py", line 1107, in request
    self._send_request(method, url, body, headers)
  File "/usr/lib/python3.5/http/client.py", line 1152, in _send_request
    self.endheaders(body)
  File "/usr/lib/python3.5/http/client.py", line 1103, in endheaders
    self._send_output(message_body)
  File "/usr/lib/python3.5/http/client.py", line 934, in _send_output
    self.send(msg)
  File "/usr/lib/python3.5/http/client.py", line 877, in send
    self.connect()
  File "/usr/lib/python3.5/http/client.py", line 1253, in connect
    super().connect()
  File "/usr/lib/python3.5/http/client.py", line 849, in connect
    (self.host,self.port), self.timeout, self.source_address)
  File "/usr/lib/python3.5/socket.py", line 712, in create_connection
    raise err
  File "/usr/lib/python3.5/socket.py", line 703, in create_connection
    sock.connect(sa)
OSError: [Errno 99] Cannot assign requested address

During handling of the above exception, another exception occurred:

Traceback (most recent call last):
  File "/usr/local/lib/python3.5/dist-packages/pypicontents/api/pypi.py", line 264, in get_pkgdata
    timeout=10).read()
  File "/usr/lib/python3.5/urllib/request.py", line 163, in urlopen
    return opener.open(url, data, timeout)
  File "/usr/lib/python3.5/urllib/request.py", line 466, in open
    response = self._open(req, data)
  File "/usr/lib/python3.5/urllib/request.py", line 484, in _open
    '_open', req)
  File "/usr/lib/python3.5/urllib/request.py", line 444, in _call_chain
    result = func(*args)
  File "/usr/lib/python3.5/urllib/request.py", line 1297, in https_open
    context=self._context, check_hostname=self._check_hostname)
  File "/usr/lib/python3.5/urllib/request.py", line 1256, in do_open
    raise URLError(err)
urllib.error.URLError: <urlopen error [Errno 99] Cannot assign requested address>

[INFO] (madmom) This package is up to date.
[INFO] (madoka) This package is up to date.
[ERROR] (madpy) This package does not have downloadable releases.
[INFO] (madpython) This package is up to date.
[INFO] (madrigalweb) This package is up to date.
[INFO] (madrona) This package is up to date.
[INFO] (mads) This package is up to date.
[INFO] (madsaf-list) This package is up to date.
[INFO] (madseq) This package is up to date.
[INFO] (madxpy) This package is up to date.
[INFO] (madz) This package is up to date.
[INFO] (maec) This package is up to date.
[INFO] (maec-to-stix) This package is up to date.
[INFO] (maec411) This package is up to date.
[INFO] (maegen) This package is up to date.
[INFO] (maek) This package is up to date.
[ERROR] (maelstrom) This package does not have downloadable releases.
[INFO] (maelstrom-py) This package is up to date.
[INFO] (maester) This package is up to date.
[INFO] (maestro) This package is up to date.
[INFO] (maestro-app) This package is up to date.
[INFO] (maestro-ng) This package is up to date.
[INFO] (maestroops) This package is up to date.
[INFO] (maestrowf) This package is up to date.
[INFO] (maetinject) This package is up to date.
[ERROR] (mafalb-nester) This package does not have downloadable releases.
[INFO] (mafan) This package is up to date.
[INFO] (mafan-traditional) This package is up to date.
[INFO] (maff) This package is up to date.
[INFO] (mafia) This package is up to date.
[INFO] (mafia-ops-tools) This package is up to date.
[ERROR] (mafipy) Could not get a response from API for this package. See below for details.
Traceback (most recent call last):
  File "/usr/local/lib/python3.5/dist-packages/pypicontents/api/pypi.py", line 264, in get_pkgdata
    timeout=10).read()
  File "/usr/lib/python3.5/urllib/request.py", line 163, in urlopen
    return opener.open(url, data, timeout)
  File "/usr/lib/python3.5/urllib/request.py", line 472, in open
    response = meth(req, response)
  File "/usr/lib/python3.5/urllib/request.py", line 582, in http_response
    'http', request, response, code, msg, hdrs)
  File "/usr/lib/python3.5/urllib/request.py", line 510, in error
    return self._call_chain(*args)
  File "/usr/lib/python3.5/urllib/request.py", line 444, in _call_chain
    result = func(*args)
  File "/usr/lib/python3.5/urllib/request.py", line 590, in http_error_default
    raise HTTPError(req.full_url, code, msg, hdrs, fp)
urllib.error.HTTPError: HTTP Error 404: Not Found

[INFO] (maga) This package is up to date.
[INFO] (magcode-core) This package is up to date.
[INFO] (magcolloid) This package is up to date.
[INFO] (mage) This package is up to date.
[INFO] (mage2gen) This package is up to date.
[INFO] (magedock) This package is up to date.
[INFO] (magellan) This package is up to date.
[INFO] (magen-datastore) This package is up to date.
[INFO] (magen-gmail-client) This package is up to date.
[INFO] (magen-hwa-service) This package is up to date.
[INFO] (magen-id-client) This package is up to date.
[INFO] (magen-id-service) This package is up to date.
[INFO] (magen-ingestion-service) This package is up to date.
[INFO] (magen-key-service) This package is up to date.
[INFO] (magen-logger) This package is up to date.
[INFO] (magen-mongo) This package is up to date.
[INFO] (magen-policy-service) This package is up to date.
[INFO] (magen-rest-service) This package is up to date.
[INFO] (magen-statistics-service) This package is up to date.
[INFO] (magen-test-utils) This package is up to date.
[INFO] (magen-user) This package is up to date.
[INFO] (magen-utils) This package is up to date.
[INFO] (magenta) This package is up to date.
[INFO] (magenta-gpu) This package is up to date.
[INFO] (magento) This package is up to date.
[INFO] (magento-adapter) This package is up to date.
[INFO] (magento-models) This package is up to date.
[INFO] (magento-python) This package is up to date.
[INFO] (magento2) This package is up to date.
[ERROR] (magentodb) This package does not have downloadable releases.
[INFO] (magentouch) This package is up to date.
[INFO] (magerestore) This package is up to date.
[INFO] (magery) This package is up to date.
[INFO] (magetool) This package is up to date.
[INFO] (magfacy) This package is up to date.
[INFO] (maggit) This package is up to date.
[INFO] (maggma) This package is up to date.
[INFO] (magi) This package is up to date.
[ERROR] (magic) Could not extract data from this package. See below for details.
".py" extension not supported.
[INFO] (magic-box) This package is up to date.
[INFO] (magic-comic-reader) This package is up to date.
[INFO] (magic-constraints) This package is up to date.
[INFO] (magic-django-markdown-editor) This package is up to date.
[ERROR] (magic-garden) This package does not have downloadable releases.
[INFO] (magic-import) This package is up to date.
[INFO] (magic-impute) This package is up to date.
[INFO] (magic-lightning-remote) This package is up to date.
[INFO] (magic-marker) This package is up to date.
[INFO] (magic-parameter) This package is up to date.
[INFO] (magic-pixel) This package is up to date.
[INFO] (magic-proxy) This package is up to date.
[INFO] (magic-reader) This package is up to date.
[INFO] (magic-square) This package is up to date.
[INFO] (magic-wormhole) This package is up to date.
[INFO] (magic-wormhole-mailbox-server) This package is up to date.
[INFO] (magic-wormhole-transit-relay) This package is up to date.
[INFO] (magic-xxl) This package is up to date.
[INFO] (magic16-nester) This package is up to date.
[ERROR] (magical) This package does not have downloadable releases.
[INFO] (magical-magic) This package is up to date.
[INFO] (magicalimport) This package is up to date.
[INFO] (magicarp-api) This package is up to date.
[INFO] (magicattr) This package is up to date.
[INFO] (magicbaidu) This package is up to date.
[INFO] (magicblue) This package is up to date.
[INFO] (magicbox) This package is up to date.
[INFO] (magicbus) This package is up to date.
[INFO] (magicdate) This package is up to date.
[INFO] (magicdict) This package is up to date.
[INFO] (magicdir) This package is up to date.
[INFO] (magicembed) This package is up to date.
[INFO] (magiceye-solve) This package is up to date.
[ERROR] (magiceye-solver) Could not get a response from API for this package. See below for details.
Traceback (most recent call last):
  File "/usr/local/lib/python3.5/dist-packages/pypicontents/api/pypi.py", line 264, in get_pkgdata
    timeout=10).read()
  File "/usr/lib/python3.5/urllib/request.py", line 163, in urlopen
    return opener.open(url, data, timeout)
  File "/usr/lib/python3.5/urllib/request.py", line 472, in open
    response = meth(req, response)
  File "/usr/lib/python3.5/urllib/request.py", line 582, in http_response
    'http', request, response, code, msg, hdrs)
  File "/usr/lib/python3.5/urllib/request.py", line 504, in error
    result = self._call_chain(*args)
  File "/usr/lib/python3.5/urllib/request.py", line 444, in _call_chain
    result = func(*args)
  File "/usr/lib/python3.5/urllib/request.py", line 696, in http_error_302
    return self.parent.open(new, timeout=req.timeout)
  File "/usr/lib/python3.5/urllib/request.py", line 472, in open
    response = meth(req, response)
  File "/usr/lib/python3.5/urllib/request.py", line 582, in http_response
    'http', request, response, code, msg, hdrs)
  File "/usr/lib/python3.5/urllib/request.py", line 510, in error
    return self._call_chain(*args)
  File "/usr/lib/python3.5/urllib/request.py", line 444, in _call_chain
    result = func(*args)
  File "/usr/lib/python3.5/urllib/request.py", line 590, in http_error_default
    raise HTTPError(req.full_url, code, msg, hdrs, fp)
urllib.error.HTTPError: HTTP Error 404: Not Found

[INFO] (magicfile) This package is up to date.
[INFO] (magicfolder) This package is up to date.
[INFO] (magicgoogle) This package is up to date.
[INFO] (magichomewifi) This package is up to date.
[INFO] (magichttp) This package is up to date.
[INFO] (magician) This package is up to date.
[INFO] (magicicadaprotocol) This package is up to date.
[ERROR] (magicio) This package does not have downloadable releases.
[ERROR] (magick) This package does not have downloadable releases.
[INFO] (magickpy) This package is up to date.
[INFO] (magickwand) This package is up to date.
[INFO] (magiclog) This package is up to date.
[INFO] (magicmemoryview) This package is up to date.
[INFO] (magicmethods) This package is up to date.
[INFO] (magicmock) This package is up to date.
[ERROR] (magicpy) This package does not have downloadable releases.
[INFO] (magicreq) This package is up to date.
[ERROR] (magicrequests) This package does not have downloadable releases.
[INFO] (magicseaweed) This package is up to date.
[INFO] (magicserver) This package is up to date.
[INFO] (magicsquare) This package is up to date.
[INFO] (magicstack) This package is up to date.
[INFO] (magicstore) This package is up to date.
[INFO] (magicstr) This package is up to date.
[INFO] (magicsuper) This package is up to date.
[ERROR] (magicsync) This package does not have downloadable releases.
[INFO] (magictree) This package is up to date.
[INFO] (magicword) This package is up to date.
[INFO] (magikeda) This package is up to date.
[INFO] (magistral) This package is up to date.
[INFO] (magma) This package is up to date.
[INFO] (magma-framework) This package is up to date.
[INFO] (magnatune) This package is up to date.
[INFO] (magnet) This package is up to date.
[INFO] (magnetic) This package is up to date.
[INFO] (magneticod) This package is up to date.
[INFO] (magneticow) This package is up to date.
[INFO] (magnetmatter) This package is up to date.
[INFO] (magneto) This package is up to date.
[INFO] (magnetodb) This package is up to date.
[INFO] (magnetor) This package is up to date.
[INFO] (magnetos) This package is up to date.
[ERROR] (magnetospheres) Could not extract data from this package. See below for details.
"http://www.perpetualpyramid/http://perpetualpyramid.com/Magnetospheres-0.1.tar.gz" file could not be downloaded. See below for details.
Traceback (most recent call last):
  File "/usr/lib/python3.5/urllib/request.py", line 1254, in do_open
    h.request(req.get_method(), req.selector, req.data, headers)
  File "/usr/lib/python3.5/http/client.py", line 1107, in request
    self._send_request(method, url, body, headers)
  File "/usr/lib/python3.5/http/client.py", line 1152, in _send_request
    self.endheaders(body)
  File "/usr/lib/python3.5/http/client.py", line 1103, in endheaders
    self._send_output(message_body)
  File "/usr/lib/python3.5/http/client.py", line 934, in _send_output
    self.send(msg)
  File "/usr/lib/python3.5/http/client.py", line 877, in send
    self.connect()
  File "/usr/lib/python3.5/http/client.py", line 849, in connect
    (self.host,self.port), self.timeout, self.source_address)
  File "/usr/lib/python3.5/socket.py", line 694, in create_connection
    for res in getaddrinfo(host, port, 0, SOCK_STREAM):
  File "/usr/lib/python3.5/socket.py", line 733, in getaddrinfo
    for res in _socket.getaddrinfo(host, port, family, type, proto, flags):
socket.gaierror: [Errno -2] Name or service not known

During handling of the above exception, another exception occurred:

Traceback (most recent call last):
  File "/usr/local/lib/python3.5/dist-packages/pypicontents/api/pypi.py", line 107, in download_tar
    f.write(urlopen(url=urlesc(pkgurl), timeout=10).read())
  File "/usr/lib/python3.5/urllib/request.py", line 163, in urlopen
    return opener.open(url, data, timeout)
  File "/usr/lib/python3.5/urllib/request.py", line 466, in open
    response = self._open(req, data)
  File "/usr/lib/python3.5/urllib/request.py", line 484, in _open
    '_open', req)
  File "/usr/lib/python3.5/urllib/request.py", line 444, in _call_chain
    result = func(*args)
  File "/usr/lib/python3.5/urllib/request.py", line 1282, in http_open
    return self.do_open(http.client.HTTPConnection, req)
  File "/usr/lib/python3.5/urllib/request.py", line 1256, in do_open
    raise URLError(err)
urllib.error.URLError: <urlopen error [Errno -2] Name or service not known>

[INFO] (magnetpy) This package is up to date.
[INFO] (magnetsdk2) This package is up to date.
[INFO] (magneturi) This package is up to date.
[INFO] (magni) This package is up to date.
[INFO] (magnitude) This package is up to date.
[INFO] (magnivore) This package is up to date.
[INFO] (magnolia-athletelist) This package is up to date.
[INFO] (magnolia-coach) This package is up to date.
[INFO] (magnum) This package is up to date.
[INFO] (magnum-pi) This package is up to date.
[INFO] (magnum-ui) This package is up to date.
[INFO] (magnum-ui-horizon) This package is up to date.
[ERROR] (magot) Could not get a response from API for this package. See below for details.
Traceback (most recent call last):
  File "/usr/lib/python3.5/urllib/request.py", line 1254, in do_open
    h.request(req.get_method(), req.selector, req.data, headers)
  File "/usr/lib/python3.5/http/client.py", line 1107, in request
    self._send_request(method, url, body, headers)
  File "/usr/lib/python3.5/http/client.py", line 1152, in _send_request
    self.endheaders(body)
  File "/usr/lib/python3.5/http/client.py", line 1103, in endheaders
    self._send_output(message_body)
  File "/usr/lib/python3.5/http/client.py", line 934, in _send_output
    self.send(msg)
  File "/usr/lib/python3.5/http/client.py", line 877, in send
    self.connect()
  File "/usr/lib/python3.5/http/client.py", line 1253, in connect
    super().connect()
  File "/usr/lib/python3.5/http/client.py", line 849, in connect
    (self.host,self.port), self.timeout, self.source_address)
  File "/usr/lib/python3.5/socket.py", line 712, in create_connection
    raise err
  File "/usr/lib/python3.5/socket.py", line 703, in create_connection
    sock.connect(sa)
OSError: [Errno 99] Cannot assign requested address

During handling of the above exception, another exception occurred:

Traceback (most recent call last):
  File "/usr/local/lib/python3.5/dist-packages/pypicontents/api/pypi.py", line 264, in get_pkgdata
    timeout=10).read()
  File "/usr/lib/python3.5/urllib/request.py", line 163, in urlopen
    return opener.open(url, data, timeout)
  File "/usr/lib/python3.5/urllib/request.py", line 466, in open
    response = self._open(req, data)
  File "/usr/lib/python3.5/urllib/request.py", line 484, in _open
    '_open', req)
  File "/usr/lib/python3.5/urllib/request.py", line 444, in _call_chain
    result = func(*args)
  File "/usr/lib/python3.5/urllib/request.py", line 1297, in https_open
    context=self._context, check_hostname=self._check_hostname)
  File "/usr/lib/python3.5/urllib/request.py", line 1256, in do_open
    raise URLError(err)
urllib.error.URLError: <urlopen error [Errno 99] Cannot assign requested address>

[INFO] (magpie) This package is up to date.
[INFO] (magpie-python) This package is up to date.
[ERROR] (magpie-test) This package does not have downloadable releases.
[INFO] (magplus) This package is up to date.
[ERROR] (magpy) This package does not have downloadable releases.
[INFO] (magpysv) This package is up to date.
[INFO] (magritte) This package is up to date.
[INFO] (magro) This package is up to date.
[INFO] (maguey) This package is up to date.
[INFO] (magus) This package is up to date.
[INFO] (magwitch) This package is up to date.
[INFO] (mahadiscom) This package is up to date.
[INFO] (maharishi) This package is up to date.
[ERROR] (mahdix111) Could not extract data from this package. See below for details.
"https://github.com/peterldowns/mypackage/tarball/master" file could not be downloaded. See below for details.
Traceback (most recent call last):
  File "/usr/local/lib/python3.5/dist-packages/pypicontents/api/pypi.py", line 107, in download_tar
    f.write(urlopen(url=urlesc(pkgurl), timeout=10).read())
  File "/usr/lib/python3.5/urllib/request.py", line 163, in urlopen
    return opener.open(url, data, timeout)
  File "/usr/lib/python3.5/urllib/request.py", line 472, in open
    response = meth(req, response)
  File "/usr/lib/python3.5/urllib/request.py", line 582, in http_response
    'http', request, response, code, msg, hdrs)
  File "/usr/lib/python3.5/urllib/request.py", line 510, in error
    return self._call_chain(*args)
  File "/usr/lib/python3.5/urllib/request.py", line 444, in _call_chain
    result = func(*args)
  File "/usr/lib/python3.5/urllib/request.py", line 590, in http_error_default
    raise HTTPError(req.full_url, code, msg, hdrs, fp)
urllib.error.HTTPError: HTTP Error 404: Not Found

[INFO] (mahendra-periodic-table) This package is up to date.
[ERROR] (mahendra-yaidavali-periodic-table) This package does not have downloadable releases.
[INFO] (mahisarithmetic) This package is up to date.
[INFO] (mahjong) This package is up to date.
[INFO] (mahmoq-nestor) This package is up to date.
[WARNING] 
[WARNING] Processing has taken more than 2100 seconds. Interrupting.
[WARNING] Processing will continue in next iteration.
[WARNING] 
[INFO] 
[INFO] 
[INFO] Total packages: 7886
[INFO]     Packages processed: 456
[INFO]         Packages updated: 1
[INFO]         Packages up-to-date: 410
[INFO]         Packages without response: 16
[INFO]         Packages without urls: 0
[INFO]         Packages without downloads: 25
[INFO]         Packages with data errors: 4
[INFO]     Packages not processed: 7430
[INFO] 
[INFO] 
[INFO] Ending execution.
