[INFO] Starting execution.
[INFO] Downloading package list from PyPI ...
[INFO] (w) This package is up to date.
[INFO] (w-encryption) This package is up to date.
[INFO] (w-i-l-l) This package is up to date.
[INFO] (w-nester) This package is up to date.
[INFO] (w1) This package is up to date.
[INFO] (w1-datalogger) This package is up to date.
[INFO] (w13scan) This package is up to date.
[INFO] (w163) This package is up to date.
[INFO] (w1thermsensor) This package is up to date.
[ERROR] (w20e-buildoutskel) Could not get a response from API for this package. See below for details.
Traceback (most recent call last):
  File "/usr/lib/python3.7/urllib/request.py", line 1319, in do_open
    encode_chunked=req.has_header('Transfer-encoding'))
  File "/usr/lib/python3.7/http/client.py", line 1252, in request
    self._send_request(method, url, body, headers, encode_chunked)
  File "/usr/lib/python3.7/http/client.py", line 1298, in _send_request
    self.endheaders(body, encode_chunked=encode_chunked)
  File "/usr/lib/python3.7/http/client.py", line 1247, in endheaders
    self._send_output(message_body, encode_chunked=encode_chunked)
  File "/usr/lib/python3.7/http/client.py", line 1026, in _send_output
    self.send(msg)
  File "/usr/lib/python3.7/http/client.py", line 966, in send
    self.connect()
  File "/usr/lib/python3.7/http/client.py", line 1414, in connect
    super().connect()
  File "/usr/lib/python3.7/http/client.py", line 938, in connect
    (self.host,self.port), self.timeout, self.source_address)
  File "/usr/lib/python3.7/socket.py", line 707, in create_connection
    for res in getaddrinfo(host, port, 0, SOCK_STREAM):
  File "/usr/lib/python3.7/socket.py", line 752, in getaddrinfo
    for res in _socket.getaddrinfo(host, port, family, type, proto, flags):
socket.gaierror: [Errno -3] Temporary failure in name resolution

During handling of the above exception, another exception occurred:

Traceback (most recent call last):
  File "/usr/local/lib/python3.7/dist-packages/pypicontents/api/pypi.py", line 264, in get_pkgdata
    timeout=10).read()
  File "/usr/lib/python3.7/urllib/request.py", line 222, in urlopen
    return opener.open(url, data, timeout)
  File "/usr/lib/python3.7/urllib/request.py", line 525, in open
    response = self._open(req, data)
  File "/usr/lib/python3.7/urllib/request.py", line 543, in _open
    '_open', req)
  File "/usr/lib/python3.7/urllib/request.py", line 503, in _call_chain
    result = func(*args)
  File "/usr/lib/python3.7/urllib/request.py", line 1362, in https_open
    context=self._context, check_hostname=self._check_hostname)
  File "/usr/lib/python3.7/urllib/request.py", line 1321, in do_open
    raise URLError(err)
urllib.error.URLError: <urlopen error [Errno -3] Temporary failure in name resolution>

[INFO] (w20e-forms) This package is up to date.
[INFO] (w20e-hitman) This package is up to date.
[INFO] (w20e-pycms) This package is up to date.
[INFO] (w20e-pycms-news) This package is up to date.
[ERROR] (w20e-pycms-sitemaker) This package does not have downloadable releases.
[ERROR] (w20e-pyramidwsgi-recipe) Could not get a response from API for this package. See below for details.
Traceback (most recent call last):
  File "/usr/lib/python3.7/urllib/request.py", line 1319, in do_open
    encode_chunked=req.has_header('Transfer-encoding'))
  File "/usr/lib/python3.7/http/client.py", line 1252, in request
    self._send_request(method, url, body, headers, encode_chunked)
  File "/usr/lib/python3.7/http/client.py", line 1298, in _send_request
    self.endheaders(body, encode_chunked=encode_chunked)
  File "/usr/lib/python3.7/http/client.py", line 1247, in endheaders
    self._send_output(message_body, encode_chunked=encode_chunked)
  File "/usr/lib/python3.7/http/client.py", line 1026, in _send_output
    self.send(msg)
  File "/usr/lib/python3.7/http/client.py", line 966, in send
    self.connect()
  File "/usr/lib/python3.7/http/client.py", line 1414, in connect
    super().connect()
  File "/usr/lib/python3.7/http/client.py", line 938, in connect
    (self.host,self.port), self.timeout, self.source_address)
  File "/usr/lib/python3.7/socket.py", line 707, in create_connection
    for res in getaddrinfo(host, port, 0, SOCK_STREAM):
  File "/usr/lib/python3.7/socket.py", line 752, in getaddrinfo
    for res in _socket.getaddrinfo(host, port, family, type, proto, flags):
socket.gaierror: [Errno -3] Temporary failure in name resolution

During handling of the above exception, another exception occurred:

Traceback (most recent call last):
  File "/usr/local/lib/python3.7/dist-packages/pypicontents/api/pypi.py", line 264, in get_pkgdata
    timeout=10).read()
  File "/usr/lib/python3.7/urllib/request.py", line 222, in urlopen
    return opener.open(url, data, timeout)
  File "/usr/lib/python3.7/urllib/request.py", line 531, in open
    response = meth(req, response)
  File "/usr/lib/python3.7/urllib/request.py", line 641, in http_response
    'http', request, response, code, msg, hdrs)
  File "/usr/lib/python3.7/urllib/request.py", line 563, in error
    result = self._call_chain(*args)
  File "/usr/lib/python3.7/urllib/request.py", line 503, in _call_chain
    result = func(*args)
  File "/usr/lib/python3.7/urllib/request.py", line 755, in http_error_302
    return self.parent.open(new, timeout=req.timeout)
  File "/usr/lib/python3.7/urllib/request.py", line 525, in open
    response = self._open(req, data)
  File "/usr/lib/python3.7/urllib/request.py", line 543, in _open
    '_open', req)
  File "/usr/lib/python3.7/urllib/request.py", line 503, in _call_chain
    result = func(*args)
  File "/usr/lib/python3.7/urllib/request.py", line 1362, in https_open
    context=self._context, check_hostname=self._check_hostname)
  File "/usr/lib/python3.7/urllib/request.py", line 1321, in do_open
    raise URLError(err)
urllib.error.URLError: <urlopen error [Errno -3] Temporary failure in name resolution>

[INFO] (w2m) This package is up to date.
[INFO] (w2ptemplate) This package is up to date.
[INFO] (w2re) This package is up to date.
[INFO] (w2vembeddings) This package is up to date.
[INFO] (w3af-api-client) This package is up to date.
[INFO] (w3blog) This package is up to date.
[INFO] (w3bparse) This package is up to date.
[INFO] (w3c-validator) This package is up to date.
[INFO] (w3c-validator-cli) This package is up to date.
[INFO] (w3g) This package is up to date.
[INFO] (w3lib) This package is up to date.
[INFO] (w600tool) This package is up to date.
[INFO] (w7x) This package is up to date.
[INFO] (w8) This package is up to date.
[INFO] (w8ing) This package is up to date.
[INFO] (w8m8) This package is up to date.
[INFO] (wa) This package is up to date.
[INFO] (wa-hack-cli) This package is up to date.
[INFO] (wa-kat) This package is up to date.
[INFO] (wa0517) This package is up to date.
[INFO] (waafle) This package is up to date.
[INFO] (waapi-client) This package is up to date.
[INFO] (waapuro) This package is up to date.
[INFO] (waas-client) This package is up to date.
[INFO] (wabbit-wappa) This package is up to date.
[INFO] (wabclient) This package is up to date.
[INFO] (wabisabi) This package is up to date.
[INFO] (waboxapp) This package is up to date.
[INFO] (wabson-chafon-rfid) This package is up to date.
[INFO] (wac) This package is up to date.
[INFO] (wachtwoord) This package is up to date.
[INFO] (wacks) This package is up to date.
[ERROR] (wacryptolib) Could not get a response from API for this package. See below for details.
Traceback (most recent call last):
  File "/usr/lib/python3.7/urllib/request.py", line 1319, in do_open
    encode_chunked=req.has_header('Transfer-encoding'))
  File "/usr/lib/python3.7/http/client.py", line 1252, in request
    self._send_request(method, url, body, headers, encode_chunked)
  File "/usr/lib/python3.7/http/client.py", line 1298, in _send_request
    self.endheaders(body, encode_chunked=encode_chunked)
  File "/usr/lib/python3.7/http/client.py", line 1247, in endheaders
    self._send_output(message_body, encode_chunked=encode_chunked)
  File "/usr/lib/python3.7/http/client.py", line 1026, in _send_output
    self.send(msg)
  File "/usr/lib/python3.7/http/client.py", line 966, in send
    self.connect()
  File "/usr/lib/python3.7/http/client.py", line 1414, in connect
    super().connect()
  File "/usr/lib/python3.7/http/client.py", line 938, in connect
    (self.host,self.port), self.timeout, self.source_address)
  File "/usr/lib/python3.7/socket.py", line 707, in create_connection
    for res in getaddrinfo(host, port, 0, SOCK_STREAM):
  File "/usr/lib/python3.7/socket.py", line 752, in getaddrinfo
    for res in _socket.getaddrinfo(host, port, family, type, proto, flags):
socket.gaierror: [Errno -3] Temporary failure in name resolution

During handling of the above exception, another exception occurred:

Traceback (most recent call last):
  File "/usr/local/lib/python3.7/dist-packages/pypicontents/api/pypi.py", line 264, in get_pkgdata
    timeout=10).read()
  File "/usr/lib/python3.7/urllib/request.py", line 222, in urlopen
    return opener.open(url, data, timeout)
  File "/usr/lib/python3.7/urllib/request.py", line 525, in open
    response = self._open(req, data)
  File "/usr/lib/python3.7/urllib/request.py", line 543, in _open
    '_open', req)
  File "/usr/lib/python3.7/urllib/request.py", line 503, in _call_chain
    result = func(*args)
  File "/usr/lib/python3.7/urllib/request.py", line 1362, in https_open
    context=self._context, check_hostname=self._check_hostname)
  File "/usr/lib/python3.7/urllib/request.py", line 1321, in do_open
    raise URLError(err)
urllib.error.URLError: <urlopen error [Errno -3] Temporary failure in name resolution>

[ERROR] (wad) Could not get a response from API for this package. See below for details.
Traceback (most recent call last):
  File "/usr/lib/python3.7/urllib/request.py", line 1319, in do_open
    encode_chunked=req.has_header('Transfer-encoding'))
  File "/usr/lib/python3.7/http/client.py", line 1252, in request
    self._send_request(method, url, body, headers, encode_chunked)
  File "/usr/lib/python3.7/http/client.py", line 1298, in _send_request
    self.endheaders(body, encode_chunked=encode_chunked)
  File "/usr/lib/python3.7/http/client.py", line 1247, in endheaders
    self._send_output(message_body, encode_chunked=encode_chunked)
  File "/usr/lib/python3.7/http/client.py", line 1026, in _send_output
    self.send(msg)
  File "/usr/lib/python3.7/http/client.py", line 966, in send
    self.connect()
  File "/usr/lib/python3.7/http/client.py", line 1414, in connect
    super().connect()
  File "/usr/lib/python3.7/http/client.py", line 938, in connect
    (self.host,self.port), self.timeout, self.source_address)
  File "/usr/lib/python3.7/socket.py", line 707, in create_connection
    for res in getaddrinfo(host, port, 0, SOCK_STREAM):
  File "/usr/lib/python3.7/socket.py", line 752, in getaddrinfo
    for res in _socket.getaddrinfo(host, port, family, type, proto, flags):
socket.gaierror: [Errno -3] Temporary failure in name resolution

During handling of the above exception, another exception occurred:

Traceback (most recent call last):
  File "/usr/local/lib/python3.7/dist-packages/pypicontents/api/pypi.py", line 264, in get_pkgdata
    timeout=10).read()
  File "/usr/lib/python3.7/urllib/request.py", line 222, in urlopen
    return opener.open(url, data, timeout)
  File "/usr/lib/python3.7/urllib/request.py", line 525, in open
    response = self._open(req, data)
  File "/usr/lib/python3.7/urllib/request.py", line 543, in _open
    '_open', req)
  File "/usr/lib/python3.7/urllib/request.py", line 503, in _call_chain
    result = func(*args)
  File "/usr/lib/python3.7/urllib/request.py", line 1362, in https_open
    context=self._context, check_hostname=self._check_hostname)
  File "/usr/lib/python3.7/urllib/request.py", line 1321, in do_open
    raise URLError(err)
urllib.error.URLError: <urlopen error [Errno -3] Temporary failure in name resolution>

[ERROR] (wadcomblog) This package does not have downloadable releases.
[INFO] (waddle) This package is up to date.
[INFO] (wade) This package is up to date.
[INFO] (wadebug) This package is up to date.
[INFO] (wadeqin-nestor) This package is up to date.
[INFO] (wadget) This package is up to date.
[INFO] (wadibyte) This package is up to date.
[INFO] (wadl2swagger) This package is up to date.
[INFO] (wadllib) This package is up to date.
[INFO] (wado) This package is up to date.
[ERROR] (wadofstuff-django-forms) Could not extract data from this package. See below for details.
"http://wadofstuff.googlecode.com/files/wadofstuff-django-forms-1.1.0.tar.gz" file could not be downloaded. See below for details.
Traceback (most recent call last):
  File "/usr/local/lib/python3.7/dist-packages/pypicontents/api/pypi.py", line 107, in download_tar
    f.write(urlopen(url=urlesc(pkgurl), timeout=10).read())
  File "/usr/lib/python3.7/urllib/request.py", line 222, in urlopen
    return opener.open(url, data, timeout)
  File "/usr/lib/python3.7/urllib/request.py", line 531, in open
    response = meth(req, response)
  File "/usr/lib/python3.7/urllib/request.py", line 641, in http_response
    'http', request, response, code, msg, hdrs)
  File "/usr/lib/python3.7/urllib/request.py", line 569, in error
    return self._call_chain(*args)
  File "/usr/lib/python3.7/urllib/request.py", line 503, in _call_chain
    result = func(*args)
  File "/usr/lib/python3.7/urllib/request.py", line 649, in http_error_default
    raise HTTPError(req.full_url, code, msg, hdrs, fp)
urllib.error.HTTPError: HTTP Error 404: Not Found

[INFO] (wadofstuff-django-serializers) This package is up to date.
[INFO] (wadofstuff-django-serializers-op) This package is up to date.
[ERROR] (wadofstuff-django-views) Could not extract data from this package. See below for details.
"http://wadofstuff.googlecode.com/files/wadofstuff-django-views-1.0.1.tar.gz" file could not be downloaded. See below for details.
Traceback (most recent call last):
  File "/usr/lib/python3.7/urllib/request.py", line 1319, in do_open
    encode_chunked=req.has_header('Transfer-encoding'))
  File "/usr/lib/python3.7/http/client.py", line 1252, in request
    self._send_request(method, url, body, headers, encode_chunked)
  File "/usr/lib/python3.7/http/client.py", line 1298, in _send_request
    self.endheaders(body, encode_chunked=encode_chunked)
  File "/usr/lib/python3.7/http/client.py", line 1247, in endheaders
    self._send_output(message_body, encode_chunked=encode_chunked)
  File "/usr/lib/python3.7/http/client.py", line 1026, in _send_output
    self.send(msg)
  File "/usr/lib/python3.7/http/client.py", line 966, in send
    self.connect()
  File "/usr/lib/python3.7/http/client.py", line 938, in connect
    (self.host,self.port), self.timeout, self.source_address)
  File "/usr/lib/python3.7/socket.py", line 728, in create_connection
    raise err
  File "/usr/lib/python3.7/socket.py", line 716, in create_connection
    sock.connect(sa)
OSError: [Errno 99] Cannot assign requested address

During handling of the above exception, another exception occurred:

Traceback (most recent call last):
  File "/usr/local/lib/python3.7/dist-packages/pypicontents/api/pypi.py", line 107, in download_tar
    f.write(urlopen(url=urlesc(pkgurl), timeout=10).read())
  File "/usr/lib/python3.7/urllib/request.py", line 222, in urlopen
    return opener.open(url, data, timeout)
  File "/usr/lib/python3.7/urllib/request.py", line 525, in open
    response = self._open(req, data)
  File "/usr/lib/python3.7/urllib/request.py", line 543, in _open
    '_open', req)
  File "/usr/lib/python3.7/urllib/request.py", line 503, in _call_chain
    result = func(*args)
  File "/usr/lib/python3.7/urllib/request.py", line 1347, in http_open
    return self.do_open(http.client.HTTPConnection, req)
  File "/usr/lib/python3.7/urllib/request.py", line 1321, in do_open
    raise URLError(err)
urllib.error.URLError: <urlopen error [Errno 99] Cannot assign requested address>

[ERROR] (wadofstuff-ip) Could not extract data from this package. See below for details.
"http://wadofstuff.googlecode.com/files/wadofstuff-ip-1.0.0.tar.gz" file could not be downloaded. See below for details.
Traceback (most recent call last):
  File "/usr/local/lib/python3.7/dist-packages/pypicontents/api/pypi.py", line 107, in download_tar
    f.write(urlopen(url=urlesc(pkgurl), timeout=10).read())
  File "/usr/lib/python3.7/urllib/request.py", line 222, in urlopen
    return opener.open(url, data, timeout)
  File "/usr/lib/python3.7/urllib/request.py", line 531, in open
    response = meth(req, response)
  File "/usr/lib/python3.7/urllib/request.py", line 641, in http_response
    'http', request, response, code, msg, hdrs)
  File "/usr/lib/python3.7/urllib/request.py", line 569, in error
    return self._call_chain(*args)
  File "/usr/lib/python3.7/urllib/request.py", line 503, in _call_chain
    result = func(*args)
  File "/usr/lib/python3.7/urllib/request.py", line 649, in http_error_default
    raise HTTPError(req.full_url, code, msg, hdrs, fp)
urllib.error.HTTPError: HTTP Error 404: Not Found

[INFO] (wadsworth) This package is up to date.
[INFO] (wadus) This package is up to date.
[INFO] (wae) This package is up to date.
[INFO] (waechter) This package is up to date.
[INFO] (waelstow) This package is up to date.
[INFO] (waeup-kofa) This package is up to date.
[INFO] (waeup-sphinx-autodoc) This package is up to date.
[INFO] (waf-brain) This package is up to date.
[INFO] (wafer) This package is up to date.
[INFO] (wafer-debconf) This package is up to date.
[INFO] (wafer-map) This package is up to date.
[INFO] (wafer-thin-mint) This package is up to date.
[INFO] (waferslim) This package is up to date.
[INFO] (waffle) This package is up to date.
[INFO] (waffle-window) This package is up to date.
[INFO] (wafflehaus) This package is up to date.
[INFO] (wafflehaus-iweb) This package is up to date.
[INFO] (wafflehaus-neutron) This package is up to date.
[INFO] (wafflehaus-nova) This package is up to date.
[ERROR] (waffls) Could not get a response from API for this package. See below for details.
Traceback (most recent call last):
  File "/usr/lib/python3.7/urllib/request.py", line 1319, in do_open
    encode_chunked=req.has_header('Transfer-encoding'))
  File "/usr/lib/python3.7/http/client.py", line 1252, in request
    self._send_request(method, url, body, headers, encode_chunked)
  File "/usr/lib/python3.7/http/client.py", line 1298, in _send_request
    self.endheaders(body, encode_chunked=encode_chunked)
  File "/usr/lib/python3.7/http/client.py", line 1247, in endheaders
    self._send_output(message_body, encode_chunked=encode_chunked)
  File "/usr/lib/python3.7/http/client.py", line 1026, in _send_output
    self.send(msg)
  File "/usr/lib/python3.7/http/client.py", line 966, in send
    self.connect()
  File "/usr/lib/python3.7/http/client.py", line 1414, in connect
    super().connect()
  File "/usr/lib/python3.7/http/client.py", line 938, in connect
    (self.host,self.port), self.timeout, self.source_address)
  File "/usr/lib/python3.7/socket.py", line 707, in create_connection
    for res in getaddrinfo(host, port, 0, SOCK_STREAM):
  File "/usr/lib/python3.7/socket.py", line 752, in getaddrinfo
    for res in _socket.getaddrinfo(host, port, family, type, proto, flags):
socket.gaierror: [Errno -3] Temporary failure in name resolution

During handling of the above exception, another exception occurred:

Traceback (most recent call last):
  File "/usr/local/lib/python3.7/dist-packages/pypicontents/api/pypi.py", line 264, in get_pkgdata
    timeout=10).read()
  File "/usr/lib/python3.7/urllib/request.py", line 222, in urlopen
    return opener.open(url, data, timeout)
  File "/usr/lib/python3.7/urllib/request.py", line 525, in open
    response = self._open(req, data)
  File "/usr/lib/python3.7/urllib/request.py", line 543, in _open
    '_open', req)
  File "/usr/lib/python3.7/urllib/request.py", line 503, in _call_chain
    result = func(*args)
  File "/usr/lib/python3.7/urllib/request.py", line 1362, in https_open
    context=self._context, check_hostname=self._check_hostname)
  File "/usr/lib/python3.7/urllib/request.py", line 1321, in do_open
    raise URLError(err)
urllib.error.URLError: <urlopen error [Errno -3] Temporary failure in name resolution>

[INFO] (waflabs) This package is up to date.
[ERROR] (wafo) Could not get a response from API for this package. See below for details.
Traceback (most recent call last):
  File "/usr/lib/python3.7/urllib/request.py", line 1319, in do_open
    encode_chunked=req.has_header('Transfer-encoding'))
  File "/usr/lib/python3.7/http/client.py", line 1252, in request
    self._send_request(method, url, body, headers, encode_chunked)
  File "/usr/lib/python3.7/http/client.py", line 1298, in _send_request
    self.endheaders(body, encode_chunked=encode_chunked)
  File "/usr/lib/python3.7/http/client.py", line 1247, in endheaders
    self._send_output(message_body, encode_chunked=encode_chunked)
  File "/usr/lib/python3.7/http/client.py", line 1026, in _send_output
    self.send(msg)
  File "/usr/lib/python3.7/http/client.py", line 966, in send
    self.connect()
  File "/usr/lib/python3.7/http/client.py", line 1414, in connect
    super().connect()
  File "/usr/lib/python3.7/http/client.py", line 938, in connect
    (self.host,self.port), self.timeout, self.source_address)
  File "/usr/lib/python3.7/socket.py", line 707, in create_connection
    for res in getaddrinfo(host, port, 0, SOCK_STREAM):
  File "/usr/lib/python3.7/socket.py", line 752, in getaddrinfo
    for res in _socket.getaddrinfo(host, port, family, type, proto, flags):
socket.gaierror: [Errno -3] Temporary failure in name resolution

During handling of the above exception, another exception occurred:

Traceback (most recent call last):
  File "/usr/local/lib/python3.7/dist-packages/pypicontents/api/pypi.py", line 264, in get_pkgdata
    timeout=10).read()
  File "/usr/lib/python3.7/urllib/request.py", line 222, in urlopen
    return opener.open(url, data, timeout)
  File "/usr/lib/python3.7/urllib/request.py", line 525, in open
    response = self._open(req, data)
  File "/usr/lib/python3.7/urllib/request.py", line 543, in _open
    '_open', req)
  File "/usr/lib/python3.7/urllib/request.py", line 503, in _call_chain
    result = func(*args)
  File "/usr/lib/python3.7/urllib/request.py", line 1362, in https_open
    context=self._context, check_hostname=self._check_hostname)
  File "/usr/lib/python3.7/urllib/request.py", line 1321, in do_open
    raise URLError(err)
urllib.error.URLError: <urlopen error [Errno -3] Temporary failure in name resolution>

[INFO] (wafoo) This package is up to date.
[INFO] (waftools) This package is up to date.
[INFO] (wafw00f) This package is up to date.
[ERROR] (wag) Could not get a response from API for this package. See below for details.
Traceback (most recent call last):
  File "/usr/lib/python3.7/urllib/request.py", line 1319, in do_open
    encode_chunked=req.has_header('Transfer-encoding'))
  File "/usr/lib/python3.7/http/client.py", line 1252, in request
    self._send_request(method, url, body, headers, encode_chunked)
  File "/usr/lib/python3.7/http/client.py", line 1298, in _send_request
    self.endheaders(body, encode_chunked=encode_chunked)
  File "/usr/lib/python3.7/http/client.py", line 1247, in endheaders
    self._send_output(message_body, encode_chunked=encode_chunked)
  File "/usr/lib/python3.7/http/client.py", line 1026, in _send_output
    self.send(msg)
  File "/usr/lib/python3.7/http/client.py", line 966, in send
    self.connect()
  File "/usr/lib/python3.7/http/client.py", line 1414, in connect
    super().connect()
  File "/usr/lib/python3.7/http/client.py", line 938, in connect
    (self.host,self.port), self.timeout, self.source_address)
  File "/usr/lib/python3.7/socket.py", line 707, in create_connection
    for res in getaddrinfo(host, port, 0, SOCK_STREAM):
  File "/usr/lib/python3.7/socket.py", line 752, in getaddrinfo
    for res in _socket.getaddrinfo(host, port, family, type, proto, flags):
socket.gaierror: [Errno -3] Temporary failure in name resolution

During handling of the above exception, another exception occurred:

Traceback (most recent call last):
  File "/usr/local/lib/python3.7/dist-packages/pypicontents/api/pypi.py", line 264, in get_pkgdata
    timeout=10).read()
  File "/usr/lib/python3.7/urllib/request.py", line 222, in urlopen
    return opener.open(url, data, timeout)
  File "/usr/lib/python3.7/urllib/request.py", line 525, in open
    response = self._open(req, data)
  File "/usr/lib/python3.7/urllib/request.py", line 543, in _open
    '_open', req)
  File "/usr/lib/python3.7/urllib/request.py", line 503, in _call_chain
    result = func(*args)
  File "/usr/lib/python3.7/urllib/request.py", line 1362, in https_open
    context=self._context, check_hostname=self._check_hostname)
  File "/usr/lib/python3.7/urllib/request.py", line 1321, in do_open
    raise URLError(err)
urllib.error.URLError: <urlopen error [Errno -3] Temporary failure in name resolution>

[INFO] (wagalytics) This package is up to date.
[INFO] (wagalytics-tier) This package is up to date.
[ERROR] (wagasciruncontrol) Could not get a response from API for this package. See below for details.
Traceback (most recent call last):
  File "/usr/lib/python3.7/urllib/request.py", line 1319, in do_open
    encode_chunked=req.has_header('Transfer-encoding'))
  File "/usr/lib/python3.7/http/client.py", line 1252, in request
    self._send_request(method, url, body, headers, encode_chunked)
  File "/usr/lib/python3.7/http/client.py", line 1298, in _send_request
    self.endheaders(body, encode_chunked=encode_chunked)
  File "/usr/lib/python3.7/http/client.py", line 1247, in endheaders
    self._send_output(message_body, encode_chunked=encode_chunked)
  File "/usr/lib/python3.7/http/client.py", line 1026, in _send_output
    self.send(msg)
  File "/usr/lib/python3.7/http/client.py", line 966, in send
    self.connect()
  File "/usr/lib/python3.7/http/client.py", line 1414, in connect
    super().connect()
  File "/usr/lib/python3.7/http/client.py", line 938, in connect
    (self.host,self.port), self.timeout, self.source_address)
  File "/usr/lib/python3.7/socket.py", line 707, in create_connection
    for res in getaddrinfo(host, port, 0, SOCK_STREAM):
  File "/usr/lib/python3.7/socket.py", line 752, in getaddrinfo
    for res in _socket.getaddrinfo(host, port, family, type, proto, flags):
socket.gaierror: [Errno -3] Temporary failure in name resolution

During handling of the above exception, another exception occurred:

Traceback (most recent call last):
  File "/usr/local/lib/python3.7/dist-packages/pypicontents/api/pypi.py", line 264, in get_pkgdata
    timeout=10).read()
  File "/usr/lib/python3.7/urllib/request.py", line 222, in urlopen
    return opener.open(url, data, timeout)
  File "/usr/lib/python3.7/urllib/request.py", line 531, in open
    response = meth(req, response)
  File "/usr/lib/python3.7/urllib/request.py", line 641, in http_response
    'http', request, response, code, msg, hdrs)
  File "/usr/lib/python3.7/urllib/request.py", line 563, in error
    result = self._call_chain(*args)
  File "/usr/lib/python3.7/urllib/request.py", line 503, in _call_chain
    result = func(*args)
  File "/usr/lib/python3.7/urllib/request.py", line 755, in http_error_302
    return self.parent.open(new, timeout=req.timeout)
  File "/usr/lib/python3.7/urllib/request.py", line 525, in open
    response = self._open(req, data)
  File "/usr/lib/python3.7/urllib/request.py", line 543, in _open
    '_open', req)
  File "/usr/lib/python3.7/urllib/request.py", line 503, in _call_chain
    result = func(*args)
  File "/usr/lib/python3.7/urllib/request.py", line 1362, in https_open
    context=self._context, check_hostname=self._check_hostname)
  File "/usr/lib/python3.7/urllib/request.py", line 1321, in do_open
    raise URLError(err)
urllib.error.URLError: <urlopen error [Errno -3] Temporary failure in name resolution>

[INFO] (wagent) This package is up to date.
[INFO] (waggle) This package is up to date.
[INFO] (wago) This package is up to date.
[INFO] (wagon) This package is up to date.
[INFO] (wagoner) This package is up to date.
[ERROR] (wagtail) Could not get a response from API for this package. See below for details.
Traceback (most recent call last):
  File "/usr/lib/python3.7/urllib/request.py", line 1319, in do_open
    encode_chunked=req.has_header('Transfer-encoding'))
  File "/usr/lib/python3.7/http/client.py", line 1252, in request
    self._send_request(method, url, body, headers, encode_chunked)
  File "/usr/lib/python3.7/http/client.py", line 1298, in _send_request
    self.endheaders(body, encode_chunked=encode_chunked)
  File "/usr/lib/python3.7/http/client.py", line 1247, in endheaders
    self._send_output(message_body, encode_chunked=encode_chunked)
  File "/usr/lib/python3.7/http/client.py", line 1026, in _send_output
    self.send(msg)
  File "/usr/lib/python3.7/http/client.py", line 966, in send
    self.connect()
  File "/usr/lib/python3.7/http/client.py", line 1414, in connect
    super().connect()
  File "/usr/lib/python3.7/http/client.py", line 938, in connect
    (self.host,self.port), self.timeout, self.source_address)
  File "/usr/lib/python3.7/socket.py", line 707, in create_connection
    for res in getaddrinfo(host, port, 0, SOCK_STREAM):
  File "/usr/lib/python3.7/socket.py", line 752, in getaddrinfo
    for res in _socket.getaddrinfo(host, port, family, type, proto, flags):
socket.gaierror: [Errno -3] Temporary failure in name resolution

During handling of the above exception, another exception occurred:

Traceback (most recent call last):
  File "/usr/local/lib/python3.7/dist-packages/pypicontents/api/pypi.py", line 264, in get_pkgdata
    timeout=10).read()
  File "/usr/lib/python3.7/urllib/request.py", line 222, in urlopen
    return opener.open(url, data, timeout)
  File "/usr/lib/python3.7/urllib/request.py", line 525, in open
    response = self._open(req, data)
  File "/usr/lib/python3.7/urllib/request.py", line 543, in _open
    '_open', req)
  File "/usr/lib/python3.7/urllib/request.py", line 503, in _call_chain
    result = func(*args)
  File "/usr/lib/python3.7/urllib/request.py", line 1362, in https_open
    context=self._context, check_hostname=self._check_hostname)
  File "/usr/lib/python3.7/urllib/request.py", line 1321, in do_open
    raise URLError(err)
urllib.error.URLError: <urlopen error [Errno -3] Temporary failure in name resolution>

[ERROR] (wagtail-2fa) Could not get a response from API for this package. See below for details.
Traceback (most recent call last):
  File "/usr/lib/python3.7/urllib/request.py", line 1319, in do_open
    encode_chunked=req.has_header('Transfer-encoding'))
  File "/usr/lib/python3.7/http/client.py", line 1252, in request
    self._send_request(method, url, body, headers, encode_chunked)
  File "/usr/lib/python3.7/http/client.py", line 1298, in _send_request
    self.endheaders(body, encode_chunked=encode_chunked)
  File "/usr/lib/python3.7/http/client.py", line 1247, in endheaders
    self._send_output(message_body, encode_chunked=encode_chunked)
  File "/usr/lib/python3.7/http/client.py", line 1026, in _send_output
    self.send(msg)
  File "/usr/lib/python3.7/http/client.py", line 966, in send
    self.connect()
  File "/usr/lib/python3.7/http/client.py", line 1414, in connect
    super().connect()
  File "/usr/lib/python3.7/http/client.py", line 938, in connect
    (self.host,self.port), self.timeout, self.source_address)
  File "/usr/lib/python3.7/socket.py", line 707, in create_connection
    for res in getaddrinfo(host, port, 0, SOCK_STREAM):
  File "/usr/lib/python3.7/socket.py", line 752, in getaddrinfo
    for res in _socket.getaddrinfo(host, port, family, type, proto, flags):
socket.gaierror: [Errno -3] Temporary failure in name resolution

During handling of the above exception, another exception occurred:

Traceback (most recent call last):
  File "/usr/local/lib/python3.7/dist-packages/pypicontents/api/pypi.py", line 264, in get_pkgdata
    timeout=10).read()
  File "/usr/lib/python3.7/urllib/request.py", line 222, in urlopen
    return opener.open(url, data, timeout)
  File "/usr/lib/python3.7/urllib/request.py", line 525, in open
    response = self._open(req, data)
  File "/usr/lib/python3.7/urllib/request.py", line 543, in _open
    '_open', req)
  File "/usr/lib/python3.7/urllib/request.py", line 503, in _call_chain
    result = func(*args)
  File "/usr/lib/python3.7/urllib/request.py", line 1362, in https_open
    context=self._context, check_hostname=self._check_hostname)
  File "/usr/lib/python3.7/urllib/request.py", line 1321, in do_open
    raise URLError(err)
urllib.error.URLError: <urlopen error [Errno -3] Temporary failure in name resolution>

[INFO] (wagtail-accessibility) This package is up to date.
[INFO] (wagtail-admin-live) This package is up to date.
[ERROR] (wagtail-admin-parent-filter) Could not get a response from API for this package. See below for details.
Traceback (most recent call last):
  File "/usr/lib/python3.7/urllib/request.py", line 1319, in do_open
    encode_chunked=req.has_header('Transfer-encoding'))
  File "/usr/lib/python3.7/http/client.py", line 1252, in request
    self._send_request(method, url, body, headers, encode_chunked)
  File "/usr/lib/python3.7/http/client.py", line 1298, in _send_request
    self.endheaders(body, encode_chunked=encode_chunked)
  File "/usr/lib/python3.7/http/client.py", line 1247, in endheaders
    self._send_output(message_body, encode_chunked=encode_chunked)
  File "/usr/lib/python3.7/http/client.py", line 1026, in _send_output
    self.send(msg)
  File "/usr/lib/python3.7/http/client.py", line 966, in send
    self.connect()
  File "/usr/lib/python3.7/http/client.py", line 1414, in connect
    super().connect()
  File "/usr/lib/python3.7/http/client.py", line 938, in connect
    (self.host,self.port), self.timeout, self.source_address)
  File "/usr/lib/python3.7/socket.py", line 707, in create_connection
    for res in getaddrinfo(host, port, 0, SOCK_STREAM):
  File "/usr/lib/python3.7/socket.py", line 752, in getaddrinfo
    for res in _socket.getaddrinfo(host, port, family, type, proto, flags):
socket.gaierror: [Errno -3] Temporary failure in name resolution

During handling of the above exception, another exception occurred:

Traceback (most recent call last):
  File "/usr/local/lib/python3.7/dist-packages/pypicontents/api/pypi.py", line 264, in get_pkgdata
    timeout=10).read()
  File "/usr/lib/python3.7/urllib/request.py", line 222, in urlopen
    return opener.open(url, data, timeout)
  File "/usr/lib/python3.7/urllib/request.py", line 525, in open
    response = self._open(req, data)
  File "/usr/lib/python3.7/urllib/request.py", line 543, in _open
    '_open', req)
  File "/usr/lib/python3.7/urllib/request.py", line 503, in _call_chain
    result = func(*args)
  File "/usr/lib/python3.7/urllib/request.py", line 1362, in https_open
    context=self._context, check_hostname=self._check_hostname)
  File "/usr/lib/python3.7/urllib/request.py", line 1321, in do_open
    raise URLError(err)
urllib.error.URLError: <urlopen error [Errno -3] Temporary failure in name resolution>

[INFO] (wagtail-adminsortable) This package is up to date.
[INFO] (wagtail-altstreamfield) This package is up to date.
[INFO] (wagtail-app-pages) This package is up to date.
[INFO] (wagtail-asciinema) This package is up to date.
[INFO] (wagtail-audit-trail) This package is up to date.
[ERROR] (wagtail-autocomplete) Could not get a response from API for this package. See below for details.
Traceback (most recent call last):
  File "/usr/lib/python3.7/urllib/request.py", line 1319, in do_open
    encode_chunked=req.has_header('Transfer-encoding'))
  File "/usr/lib/python3.7/http/client.py", line 1252, in request
    self._send_request(method, url, body, headers, encode_chunked)
  File "/usr/lib/python3.7/http/client.py", line 1298, in _send_request
    self.endheaders(body, encode_chunked=encode_chunked)
  File "/usr/lib/python3.7/http/client.py", line 1247, in endheaders
    self._send_output(message_body, encode_chunked=encode_chunked)
  File "/usr/lib/python3.7/http/client.py", line 1026, in _send_output
    self.send(msg)
  File "/usr/lib/python3.7/http/client.py", line 966, in send
    self.connect()
  File "/usr/lib/python3.7/http/client.py", line 1414, in connect
    super().connect()
  File "/usr/lib/python3.7/http/client.py", line 938, in connect
    (self.host,self.port), self.timeout, self.source_address)
  File "/usr/lib/python3.7/socket.py", line 707, in create_connection
    for res in getaddrinfo(host, port, 0, SOCK_STREAM):
  File "/usr/lib/python3.7/socket.py", line 752, in getaddrinfo
    for res in _socket.getaddrinfo(host, port, family, type, proto, flags):
socket.gaierror: [Errno -3] Temporary failure in name resolution

During handling of the above exception, another exception occurred:

Traceback (most recent call last):
  File "/usr/local/lib/python3.7/dist-packages/pypicontents/api/pypi.py", line 264, in get_pkgdata
    timeout=10).read()
  File "/usr/lib/python3.7/urllib/request.py", line 222, in urlopen
    return opener.open(url, data, timeout)
  File "/usr/lib/python3.7/urllib/request.py", line 525, in open
    response = self._open(req, data)
  File "/usr/lib/python3.7/urllib/request.py", line 543, in _open
    '_open', req)
  File "/usr/lib/python3.7/urllib/request.py", line 503, in _call_chain
    result = func(*args)
  File "/usr/lib/python3.7/urllib/request.py", line 1362, in https_open
    context=self._context, check_hostname=self._check_hostname)
  File "/usr/lib/python3.7/urllib/request.py", line 1321, in do_open
    raise URLError(err)
urllib.error.URLError: <urlopen error [Errno -3] Temporary failure in name resolution>

[ERROR] (wagtail-autofixtures) This package does not have downloadable releases.
[INFO] (wagtail-azure-cdn) This package is up to date.
[INFO] (wagtail-bakery) This package is up to date.
[ERROR] (wagtail-blocks) Could not get a response from API for this package. See below for details.
Traceback (most recent call last):
  File "/usr/lib/python3.7/urllib/request.py", line 1319, in do_open
    encode_chunked=req.has_header('Transfer-encoding'))
  File "/usr/lib/python3.7/http/client.py", line 1252, in request
    self._send_request(method, url, body, headers, encode_chunked)
  File "/usr/lib/python3.7/http/client.py", line 1298, in _send_request
    self.endheaders(body, encode_chunked=encode_chunked)
  File "/usr/lib/python3.7/http/client.py", line 1247, in endheaders
    self._send_output(message_body, encode_chunked=encode_chunked)
  File "/usr/lib/python3.7/http/client.py", line 1026, in _send_output
    self.send(msg)
  File "/usr/lib/python3.7/http/client.py", line 966, in send
    self.connect()
  File "/usr/lib/python3.7/http/client.py", line 1414, in connect
    super().connect()
  File "/usr/lib/python3.7/http/client.py", line 938, in connect
    (self.host,self.port), self.timeout, self.source_address)
  File "/usr/lib/python3.7/socket.py", line 707, in create_connection
    for res in getaddrinfo(host, port, 0, SOCK_STREAM):
  File "/usr/lib/python3.7/socket.py", line 752, in getaddrinfo
    for res in _socket.getaddrinfo(host, port, family, type, proto, flags):
socket.gaierror: [Errno -3] Temporary failure in name resolution

During handling of the above exception, another exception occurred:

Traceback (most recent call last):
  File "/usr/local/lib/python3.7/dist-packages/pypicontents/api/pypi.py", line 264, in get_pkgdata
    timeout=10).read()
  File "/usr/lib/python3.7/urllib/request.py", line 222, in urlopen
    return opener.open(url, data, timeout)
  File "/usr/lib/python3.7/urllib/request.py", line 525, in open
    response = self._open(req, data)
  File "/usr/lib/python3.7/urllib/request.py", line 543, in _open
    '_open', req)
  File "/usr/lib/python3.7/urllib/request.py", line 503, in _call_chain
    result = func(*args)
  File "/usr/lib/python3.7/urllib/request.py", line 1362, in https_open
    context=self._context, check_hostname=self._check_hostname)
  File "/usr/lib/python3.7/urllib/request.py", line 1321, in do_open
    raise URLError(err)
urllib.error.URLError: <urlopen error [Errno -3] Temporary failure in name resolution>

[INFO] (wagtail-blog) This package is up to date.
[INFO] (wagtail-blog-app) This package is up to date.
[INFO] (wagtail-cache) This package is up to date.
[INFO] (wagtail-calendar) This package is up to date.
[ERROR] (wagtail-carousel) This package does not have downloadable releases.
[INFO] (wagtail-charcount) This package is up to date.
[ERROR] (wagtail-clear-cache) Could not get a response from API for this package. See below for details.
Traceback (most recent call last):
  File "/usr/lib/python3.7/urllib/request.py", line 1319, in do_open
    encode_chunked=req.has_header('Transfer-encoding'))
  File "/usr/lib/python3.7/http/client.py", line 1252, in request
    self._send_request(method, url, body, headers, encode_chunked)
  File "/usr/lib/python3.7/http/client.py", line 1298, in _send_request
    self.endheaders(body, encode_chunked=encode_chunked)
  File "/usr/lib/python3.7/http/client.py", line 1247, in endheaders
    self._send_output(message_body, encode_chunked=encode_chunked)
  File "/usr/lib/python3.7/http/client.py", line 1026, in _send_output
    self.send(msg)
  File "/usr/lib/python3.7/http/client.py", line 966, in send
    self.connect()
  File "/usr/lib/python3.7/http/client.py", line 1414, in connect
    super().connect()
  File "/usr/lib/python3.7/http/client.py", line 938, in connect
    (self.host,self.port), self.timeout, self.source_address)
  File "/usr/lib/python3.7/socket.py", line 707, in create_connection
    for res in getaddrinfo(host, port, 0, SOCK_STREAM):
  File "/usr/lib/python3.7/socket.py", line 752, in getaddrinfo
    for res in _socket.getaddrinfo(host, port, family, type, proto, flags):
socket.gaierror: [Errno -3] Temporary failure in name resolution

During handling of the above exception, another exception occurred:

Traceback (most recent call last):
  File "/usr/local/lib/python3.7/dist-packages/pypicontents/api/pypi.py", line 264, in get_pkgdata
    timeout=10).read()
  File "/usr/lib/python3.7/urllib/request.py", line 222, in urlopen
    return opener.open(url, data, timeout)
  File "/usr/lib/python3.7/urllib/request.py", line 525, in open
    response = self._open(req, data)
  File "/usr/lib/python3.7/urllib/request.py", line 543, in _open
    '_open', req)
  File "/usr/lib/python3.7/urllib/request.py", line 503, in _call_chain
    result = func(*args)
  File "/usr/lib/python3.7/urllib/request.py", line 1362, in https_open
    context=self._context, check_hostname=self._check_hostname)
  File "/usr/lib/python3.7/urllib/request.py", line 1321, in do_open
    raise URLError(err)
urllib.error.URLError: <urlopen error [Errno -3] Temporary failure in name resolution>

[INFO] (wagtail-cloudfront-invalidate) This package is up to date.
[INFO] (wagtail-code-blog) This package is up to date.
[INFO] (wagtail-comments-xtd) This package is up to date.
[INFO] (wagtail-commonmark) This package is up to date.
[INFO] (wagtail-condensedinlinepanel) This package is up to date.
[INFO] (wagtail-constance) This package is up to date.
[INFO] (wagtail-content-import) This package is up to date.
[INFO] (wagtail-copyablemodeladmin) This package is up to date.
[ERROR] (wagtail-daterange) Could not get a response from API for this package. See below for details.
Traceback (most recent call last):
  File "/usr/local/lib/python3.7/dist-packages/pypicontents/api/pypi.py", line 264, in get_pkgdata
    timeout=10).read()
  File "/usr/lib/python3.7/urllib/request.py", line 222, in urlopen
    return opener.open(url, data, timeout)
  File "/usr/lib/python3.7/urllib/request.py", line 531, in open
    response = meth(req, response)
  File "/usr/lib/python3.7/urllib/request.py", line 641, in http_response
    'http', request, response, code, msg, hdrs)
  File "/usr/lib/python3.7/urllib/request.py", line 569, in error
    return self._call_chain(*args)
  File "/usr/lib/python3.7/urllib/request.py", line 503, in _call_chain
    result = func(*args)
  File "/usr/lib/python3.7/urllib/request.py", line 649, in http_error_default
    raise HTTPError(req.full_url, code, msg, hdrs, fp)
urllib.error.HTTPError: HTTP Error 404: Not Found

[INFO] (wagtail-demo-site) This package is up to date.
[INFO] (wagtail-django-recaptcha) This package is up to date.
[INFO] (wagtail-download-counter) This package is up to date.
[INFO] (wagtail-draftail-katex) This package is up to date.
[INFO] (wagtail-draftail-plugins) This package is up to date.
[INFO] (wagtail-draftail-snippet) This package is up to date.
[INFO] (wagtail-easy-thumbnails) This package is up to date.
[INFO] (wagtail-embed-videos) This package is up to date.
[INFO] (wagtail-eventcalendar) This package is up to date.
[INFO] (wagtail-events) This package is up to date.
[INFO] (wagtail-experiments) This package is up to date.
[INFO] (wagtail-exportcsv) This package is up to date.
[INFO] (wagtail-extras) This package is up to date.
[INFO] (wagtail-factories) This package is up to date.
[ERROR] (wagtail-fido-u2f) This package does not have downloadable releases.
[INFO] (wagtail-flags) This package is up to date.
[INFO] (wagtail-foliage) This package is up to date.
[INFO] (wagtail-gallery) This package is up to date.
[ERROR] (wagtail-gardentronic) Could not get a response from API for this package. See below for details.
Traceback (most recent call last):
  File "/usr/local/lib/python3.7/dist-packages/pypicontents/api/pypi.py", line 264, in get_pkgdata
    timeout=10).read()
  File "/usr/lib/python3.7/urllib/request.py", line 222, in urlopen
    return opener.open(url, data, timeout)
  File "/usr/lib/python3.7/urllib/request.py", line 531, in open
    response = meth(req, response)
  File "/usr/lib/python3.7/urllib/request.py", line 641, in http_response
    'http', request, response, code, msg, hdrs)
  File "/usr/lib/python3.7/urllib/request.py", line 569, in error
    return self._call_chain(*args)
  File "/usr/lib/python3.7/urllib/request.py", line 503, in _call_chain
    result = func(*args)
  File "/usr/lib/python3.7/urllib/request.py", line 649, in http_error_default
    raise HTTPError(req.full_url, code, msg, hdrs, fp)
urllib.error.HTTPError: HTTP Error 404: Not Found

[INFO] (wagtail-generic-chooser) This package is up to date.
[INFO] (wagtail-global-settings) This package is up to date.
[INFO] (wagtail-graphql) This package is up to date.
[ERROR] (wagtail-graphql-api) Could not get a response from API for this package. See below for details.
Traceback (most recent call last):
  File "/usr/lib/python3.7/urllib/request.py", line 1319, in do_open
    encode_chunked=req.has_header('Transfer-encoding'))
  File "/usr/lib/python3.7/http/client.py", line 1252, in request
    self._send_request(method, url, body, headers, encode_chunked)
  File "/usr/lib/python3.7/http/client.py", line 1298, in _send_request
    self.endheaders(body, encode_chunked=encode_chunked)
  File "/usr/lib/python3.7/http/client.py", line 1247, in endheaders
    self._send_output(message_body, encode_chunked=encode_chunked)
  File "/usr/lib/python3.7/http/client.py", line 1026, in _send_output
    self.send(msg)
  File "/usr/lib/python3.7/http/client.py", line 966, in send
    self.connect()
  File "/usr/lib/python3.7/http/client.py", line 1414, in connect
    super().connect()
  File "/usr/lib/python3.7/http/client.py", line 938, in connect
    (self.host,self.port), self.timeout, self.source_address)
  File "/usr/lib/python3.7/socket.py", line 707, in create_connection
    for res in getaddrinfo(host, port, 0, SOCK_STREAM):
  File "/usr/lib/python3.7/socket.py", line 752, in getaddrinfo
    for res in _socket.getaddrinfo(host, port, family, type, proto, flags):
socket.gaierror: [Errno -3] Temporary failure in name resolution

During handling of the above exception, another exception occurred:

Traceback (most recent call last):
  File "/usr/local/lib/python3.7/dist-packages/pypicontents/api/pypi.py", line 264, in get_pkgdata
    timeout=10).read()
  File "/usr/lib/python3.7/urllib/request.py", line 222, in urlopen
    return opener.open(url, data, timeout)
  File "/usr/lib/python3.7/urllib/request.py", line 525, in open
    response = self._open(req, data)
  File "/usr/lib/python3.7/urllib/request.py", line 543, in _open
    '_open', req)
  File "/usr/lib/python3.7/urllib/request.py", line 503, in _call_chain
    result = func(*args)
  File "/usr/lib/python3.7/urllib/request.py", line 1362, in https_open
    context=self._context, check_hostname=self._check_hostname)
  File "/usr/lib/python3.7/urllib/request.py", line 1321, in do_open
    raise URLError(err)
urllib.error.URLError: <urlopen error [Errno -3] Temporary failure in name resolution>

[INFO] (wagtail-grapple) This package is up to date.
[INFO] (wagtail-guide) This package is up to date.
[INFO] (wagtail-hallo-plugins) This package is up to date.
[INFO] (wagtail-headless-preview) This package is up to date.
[INFO] (wagtail-import-export) This package is up to date.
[INFO] (wagtail-import-export-tool) This package is up to date.
[INFO] (wagtail-instance-selector) This package is up to date.
[INFO] (wagtail-inventory) This package is up to date.
[ERROR] (wagtail-jinja2) Could not get a response from API for this package. See below for details.
Traceback (most recent call last):
  File "/usr/lib/python3.7/urllib/request.py", line 1319, in do_open
    encode_chunked=req.has_header('Transfer-encoding'))
  File "/usr/lib/python3.7/http/client.py", line 1252, in request
    self._send_request(method, url, body, headers, encode_chunked)
  File "/usr/lib/python3.7/http/client.py", line 1298, in _send_request
    self.endheaders(body, encode_chunked=encode_chunked)
  File "/usr/lib/python3.7/http/client.py", line 1247, in endheaders
    self._send_output(message_body, encode_chunked=encode_chunked)
  File "/usr/lib/python3.7/http/client.py", line 1026, in _send_output
    self.send(msg)
  File "/usr/lib/python3.7/http/client.py", line 966, in send
    self.connect()
  File "/usr/lib/python3.7/http/client.py", line 1414, in connect
    super().connect()
  File "/usr/lib/python3.7/http/client.py", line 938, in connect
    (self.host,self.port), self.timeout, self.source_address)
  File "/usr/lib/python3.7/socket.py", line 707, in create_connection
    for res in getaddrinfo(host, port, 0, SOCK_STREAM):
  File "/usr/lib/python3.7/socket.py", line 752, in getaddrinfo
    for res in _socket.getaddrinfo(host, port, family, type, proto, flags):
socket.gaierror: [Errno -3] Temporary failure in name resolution

During handling of the above exception, another exception occurred:

Traceback (most recent call last):
  File "/usr/local/lib/python3.7/dist-packages/pypicontents/api/pypi.py", line 264, in get_pkgdata
    timeout=10).read()
  File "/usr/lib/python3.7/urllib/request.py", line 222, in urlopen
    return opener.open(url, data, timeout)
  File "/usr/lib/python3.7/urllib/request.py", line 525, in open
    response = self._open(req, data)
  File "/usr/lib/python3.7/urllib/request.py", line 543, in _open
    '_open', req)
  File "/usr/lib/python3.7/urllib/request.py", line 503, in _call_chain
    result = func(*args)
  File "/usr/lib/python3.7/urllib/request.py", line 1362, in https_open
    context=self._context, check_hostname=self._check_hostname)
  File "/usr/lib/python3.7/urllib/request.py", line 1321, in do_open
    raise URLError(err)
urllib.error.URLError: <urlopen error [Errno -3] Temporary failure in name resolution>

[INFO] (wagtail-jsonschema-forms) This package is up to date.
[INFO] (wagtail-lazyimages) This package is up to date.
[INFO] (wagtail-lightadmin) This package is up to date.
[INFO] (wagtail-linkchecker) This package is up to date.
[INFO] (wagtail-links) This package is up to date.
[INFO] (wagtail-livepreview) This package is up to date.
[INFO] (wagtail-localize) This package is up to date.
[INFO] (wagtail-localize-pontoon) This package is up to date.
[INFO] (wagtail-managed404) This package is up to date.
[ERROR] (wagtail-markdown) Could not get a response from API for this package. See below for details.
Traceback (most recent call last):
  File "/usr/lib/python3.7/urllib/request.py", line 1319, in do_open
    encode_chunked=req.has_header('Transfer-encoding'))
  File "/usr/lib/python3.7/http/client.py", line 1252, in request
    self._send_request(method, url, body, headers, encode_chunked)
  File "/usr/lib/python3.7/http/client.py", line 1298, in _send_request
    self.endheaders(body, encode_chunked=encode_chunked)
  File "/usr/lib/python3.7/http/client.py", line 1247, in endheaders
    self._send_output(message_body, encode_chunked=encode_chunked)
  File "/usr/lib/python3.7/http/client.py", line 1026, in _send_output
    self.send(msg)
  File "/usr/lib/python3.7/http/client.py", line 966, in send
    self.connect()
  File "/usr/lib/python3.7/http/client.py", line 1414, in connect
    super().connect()
  File "/usr/lib/python3.7/http/client.py", line 938, in connect
    (self.host,self.port), self.timeout, self.source_address)
  File "/usr/lib/python3.7/socket.py", line 707, in create_connection
    for res in getaddrinfo(host, port, 0, SOCK_STREAM):
  File "/usr/lib/python3.7/socket.py", line 752, in getaddrinfo
    for res in _socket.getaddrinfo(host, port, family, type, proto, flags):
socket.gaierror: [Errno -3] Temporary failure in name resolution

During handling of the above exception, another exception occurred:

Traceback (most recent call last):
  File "/usr/local/lib/python3.7/dist-packages/pypicontents/api/pypi.py", line 264, in get_pkgdata
    timeout=10).read()
  File "/usr/lib/python3.7/urllib/request.py", line 222, in urlopen
    return opener.open(url, data, timeout)
  File "/usr/lib/python3.7/urllib/request.py", line 525, in open
    response = self._open(req, data)
  File "/usr/lib/python3.7/urllib/request.py", line 543, in _open
    '_open', req)
  File "/usr/lib/python3.7/urllib/request.py", line 503, in _call_chain
    result = func(*args)
  File "/usr/lib/python3.7/urllib/request.py", line 1362, in https_open
    context=self._context, check_hostname=self._check_hostname)
  File "/usr/lib/python3.7/urllib/request.py", line 1321, in do_open
    raise URLError(err)
urllib.error.URLError: <urlopen error [Errno -3] Temporary failure in name resolution>

[INFO] (wagtail-marketing-addons) This package is up to date.
[INFO] (wagtail-materializecss) This package is up to date.
[INFO] (wagtail-meeting-guide) This package is up to date.
[INFO] (wagtail-metadata) This package is up to date.
[INFO] (wagtail-metadata-mixin) This package is up to date.
[INFO] (wagtail-model-tools) This package is up to date.
[ERROR] (wagtail-model-utils) This package does not have downloadable releases.
[INFO] (wagtail-modelchooser) This package is up to date.
[INFO] (wagtail-modelchooser-1-13-1) This package is up to date.
[INFO] (wagtail-modeltranslation) This package is up to date.
[INFO] (wagtail-multi-image-edit) This package is up to date.
[INFO] (wagtail-mvc) This package is up to date.
[INFO] (wagtail-nav-menus) This package is up to date.
[INFO] (wagtail-nesting-box) This package is up to date.
[INFO] (wagtail-news-image) This package is up to date.
[ERROR] (wagtail-nhs-style) Could not get a response from API for this package. See below for details.
Traceback (most recent call last):
  File "/usr/lib/python3.7/urllib/request.py", line 1319, in do_open
    encode_chunked=req.has_header('Transfer-encoding'))
  File "/usr/lib/python3.7/http/client.py", line 1252, in request
    self._send_request(method, url, body, headers, encode_chunked)
  File "/usr/lib/python3.7/http/client.py", line 1298, in _send_request
    self.endheaders(body, encode_chunked=encode_chunked)
  File "/usr/lib/python3.7/http/client.py", line 1247, in endheaders
    self._send_output(message_body, encode_chunked=encode_chunked)
  File "/usr/lib/python3.7/http/client.py", line 1026, in _send_output
    self.send(msg)
  File "/usr/lib/python3.7/http/client.py", line 966, in send
    self.connect()
  File "/usr/lib/python3.7/http/client.py", line 1414, in connect
    super().connect()
  File "/usr/lib/python3.7/http/client.py", line 938, in connect
    (self.host,self.port), self.timeout, self.source_address)
  File "/usr/lib/python3.7/socket.py", line 707, in create_connection
    for res in getaddrinfo(host, port, 0, SOCK_STREAM):
  File "/usr/lib/python3.7/socket.py", line 752, in getaddrinfo
    for res in _socket.getaddrinfo(host, port, family, type, proto, flags):
socket.gaierror: [Errno -3] Temporary failure in name resolution

During handling of the above exception, another exception occurred:

Traceback (most recent call last):
  File "/usr/local/lib/python3.7/dist-packages/pypicontents/api/pypi.py", line 264, in get_pkgdata
    timeout=10).read()
  File "/usr/lib/python3.7/urllib/request.py", line 222, in urlopen
    return opener.open(url, data, timeout)
  File "/usr/lib/python3.7/urllib/request.py", line 525, in open
    response = self._open(req, data)
  File "/usr/lib/python3.7/urllib/request.py", line 543, in _open
    '_open', req)
  File "/usr/lib/python3.7/urllib/request.py", line 503, in _call_chain
    result = func(*args)
  File "/usr/lib/python3.7/urllib/request.py", line 1362, in https_open
    context=self._context, check_hostname=self._check_hostname)
  File "/usr/lib/python3.7/urllib/request.py", line 1321, in do_open
    raise URLError(err)
urllib.error.URLError: <urlopen error [Errno -3] Temporary failure in name resolution>

[ERROR] (wagtail-nhsuk-frontend) Could not get a response from API for this package. See below for details.
Traceback (most recent call last):
  File "/usr/lib/python3.7/urllib/request.py", line 1319, in do_open
    encode_chunked=req.has_header('Transfer-encoding'))
  File "/usr/lib/python3.7/http/client.py", line 1252, in request
    self._send_request(method, url, body, headers, encode_chunked)
  File "/usr/lib/python3.7/http/client.py", line 1298, in _send_request
    self.endheaders(body, encode_chunked=encode_chunked)
  File "/usr/lib/python3.7/http/client.py", line 1247, in endheaders
    self._send_output(message_body, encode_chunked=encode_chunked)
  File "/usr/lib/python3.7/http/client.py", line 1026, in _send_output
    self.send(msg)
  File "/usr/lib/python3.7/http/client.py", line 966, in send
    self.connect()
  File "/usr/lib/python3.7/http/client.py", line 1414, in connect
    super().connect()
  File "/usr/lib/python3.7/http/client.py", line 938, in connect
    (self.host,self.port), self.timeout, self.source_address)
  File "/usr/lib/python3.7/socket.py", line 707, in create_connection
    for res in getaddrinfo(host, port, 0, SOCK_STREAM):
  File "/usr/lib/python3.7/socket.py", line 752, in getaddrinfo
    for res in _socket.getaddrinfo(host, port, family, type, proto, flags):
socket.gaierror: [Errno -3] Temporary failure in name resolution

During handling of the above exception, another exception occurred:

Traceback (most recent call last):
  File "/usr/local/lib/python3.7/dist-packages/pypicontents/api/pypi.py", line 264, in get_pkgdata
    timeout=10).read()
  File "/usr/lib/python3.7/urllib/request.py", line 222, in urlopen
    return opener.open(url, data, timeout)
  File "/usr/lib/python3.7/urllib/request.py", line 525, in open
    response = self._open(req, data)
  File "/usr/lib/python3.7/urllib/request.py", line 543, in _open
    '_open', req)
  File "/usr/lib/python3.7/urllib/request.py", line 503, in _call_chain
    result = func(*args)
  File "/usr/lib/python3.7/urllib/request.py", line 1362, in https_open
    context=self._context, check_hostname=self._check_hostname)
  File "/usr/lib/python3.7/urllib/request.py", line 1321, in do_open
    raise URLError(err)
urllib.error.URLError: <urlopen error [Errno -3] Temporary failure in name resolution>

[INFO] (wagtail-opengraph-image-generator) This package is up to date.
[ERROR] (wagtail-orderable) Could not get a response from API for this package. See below for details.
Traceback (most recent call last):
  File "/usr/lib/python3.7/urllib/request.py", line 1319, in do_open
    encode_chunked=req.has_header('Transfer-encoding'))
  File "/usr/lib/python3.7/http/client.py", line 1252, in request
    self._send_request(method, url, body, headers, encode_chunked)
  File "/usr/lib/python3.7/http/client.py", line 1298, in _send_request
    self.endheaders(body, encode_chunked=encode_chunked)
  File "/usr/lib/python3.7/http/client.py", line 1247, in endheaders
    self._send_output(message_body, encode_chunked=encode_chunked)
  File "/usr/lib/python3.7/http/client.py", line 1026, in _send_output
    self.send(msg)
  File "/usr/lib/python3.7/http/client.py", line 966, in send
    self.connect()
  File "/usr/lib/python3.7/http/client.py", line 1414, in connect
    super().connect()
  File "/usr/lib/python3.7/http/client.py", line 938, in connect
    (self.host,self.port), self.timeout, self.source_address)
  File "/usr/lib/python3.7/socket.py", line 707, in create_connection
    for res in getaddrinfo(host, port, 0, SOCK_STREAM):
  File "/usr/lib/python3.7/socket.py", line 752, in getaddrinfo
    for res in _socket.getaddrinfo(host, port, family, type, proto, flags):
socket.gaierror: [Errno -3] Temporary failure in name resolution

During handling of the above exception, another exception occurred:

Traceback (most recent call last):
  File "/usr/local/lib/python3.7/dist-packages/pypicontents/api/pypi.py", line 264, in get_pkgdata
    timeout=10).read()
  File "/usr/lib/python3.7/urllib/request.py", line 222, in urlopen
    return opener.open(url, data, timeout)
  File "/usr/lib/python3.7/urllib/request.py", line 525, in open
    response = self._open(req, data)
  File "/usr/lib/python3.7/urllib/request.py", line 543, in _open
    '_open', req)
  File "/usr/lib/python3.7/urllib/request.py", line 503, in _call_chain
    result = func(*args)
  File "/usr/lib/python3.7/urllib/request.py", line 1362, in https_open
    context=self._context, check_hostname=self._check_hostname)
  File "/usr/lib/python3.7/urllib/request.py", line 1321, in do_open
    raise URLError(err)
urllib.error.URLError: <urlopen error [Errno -3] Temporary failure in name resolution>

[INFO] (wagtail-paginated-subpages) This package is up to date.
[INFO] (wagtail-peregrine) This package is up to date.
[INFO] (wagtail-personalisation) This package is up to date.
[INFO] (wagtail-personalisation-molo) This package is up to date.
[INFO] (wagtail-pg-search-backend) This package is up to date.
[INFO] (wagtail-photo-voter) This package is up to date.
[INFO] (wagtail-podcast) This package is up to date.
[ERROR] (wagtail-polls) Could not get a response from API for this package. See below for details.
Traceback (most recent call last):
  File "/usr/lib/python3.7/urllib/request.py", line 1319, in do_open
    encode_chunked=req.has_header('Transfer-encoding'))
  File "/usr/lib/python3.7/http/client.py", line 1252, in request
    self._send_request(method, url, body, headers, encode_chunked)
  File "/usr/lib/python3.7/http/client.py", line 1298, in _send_request
    self.endheaders(body, encode_chunked=encode_chunked)
  File "/usr/lib/python3.7/http/client.py", line 1247, in endheaders
    self._send_output(message_body, encode_chunked=encode_chunked)
  File "/usr/lib/python3.7/http/client.py", line 1026, in _send_output
    self.send(msg)
  File "/usr/lib/python3.7/http/client.py", line 966, in send
    self.connect()
  File "/usr/lib/python3.7/http/client.py", line 1414, in connect
    super().connect()
  File "/usr/lib/python3.7/http/client.py", line 938, in connect
    (self.host,self.port), self.timeout, self.source_address)
  File "/usr/lib/python3.7/socket.py", line 707, in create_connection
    for res in getaddrinfo(host, port, 0, SOCK_STREAM):
  File "/usr/lib/python3.7/socket.py", line 752, in getaddrinfo
    for res in _socket.getaddrinfo(host, port, family, type, proto, flags):
socket.gaierror: [Errno -3] Temporary failure in name resolution

During handling of the above exception, another exception occurred:

Traceback (most recent call last):
  File "/usr/local/lib/python3.7/dist-packages/pypicontents/api/pypi.py", line 264, in get_pkgdata
    timeout=10).read()
  File "/usr/lib/python3.7/urllib/request.py", line 222, in urlopen
    return opener.open(url, data, timeout)
  File "/usr/lib/python3.7/urllib/request.py", line 525, in open
    response = self._open(req, data)
  File "/usr/lib/python3.7/urllib/request.py", line 543, in _open
    '_open', req)
  File "/usr/lib/python3.7/urllib/request.py", line 503, in _call_chain
    result = func(*args)
  File "/usr/lib/python3.7/urllib/request.py", line 1362, in https_open
    context=self._context, check_hostname=self._check_hostname)
  File "/usr/lib/python3.7/urllib/request.py", line 1321, in do_open
    raise URLError(err)
urllib.error.URLError: <urlopen error [Errno -3] Temporary failure in name resolution>

[INFO] (wagtail-publish-preflight) This package is up to date.
[INFO] (wagtail-quick-create) This package is up to date.
[INFO] (wagtail-react-streamfield) This package is up to date.
[ERROR] (wagtail-readability) This package does not have downloadable releases.
[ERROR] (wagtail-readinglevel) Could not get a response from API for this package. See below for details.
Traceback (most recent call last):
  File "/usr/lib/python3.7/urllib/request.py", line 1319, in do_open
    encode_chunked=req.has_header('Transfer-encoding'))
  File "/usr/lib/python3.7/http/client.py", line 1252, in request
    self._send_request(method, url, body, headers, encode_chunked)
  File "/usr/lib/python3.7/http/client.py", line 1298, in _send_request
    self.endheaders(body, encode_chunked=encode_chunked)
  File "/usr/lib/python3.7/http/client.py", line 1247, in endheaders
    self._send_output(message_body, encode_chunked=encode_chunked)
  File "/usr/lib/python3.7/http/client.py", line 1026, in _send_output
    self.send(msg)
  File "/usr/lib/python3.7/http/client.py", line 966, in send
    self.connect()
  File "/usr/lib/python3.7/http/client.py", line 1414, in connect
    super().connect()
  File "/usr/lib/python3.7/http/client.py", line 938, in connect
    (self.host,self.port), self.timeout, self.source_address)
  File "/usr/lib/python3.7/socket.py", line 707, in create_connection
    for res in getaddrinfo(host, port, 0, SOCK_STREAM):
  File "/usr/lib/python3.7/socket.py", line 752, in getaddrinfo
    for res in _socket.getaddrinfo(host, port, family, type, proto, flags):
socket.gaierror: [Errno -3] Temporary failure in name resolution

During handling of the above exception, another exception occurred:

Traceback (most recent call last):
  File "/usr/local/lib/python3.7/dist-packages/pypicontents/api/pypi.py", line 264, in get_pkgdata
    timeout=10).read()
  File "/usr/lib/python3.7/urllib/request.py", line 222, in urlopen
    return opener.open(url, data, timeout)
  File "/usr/lib/python3.7/urllib/request.py", line 525, in open
    response = self._open(req, data)
  File "/usr/lib/python3.7/urllib/request.py", line 543, in _open
    '_open', req)
  File "/usr/lib/python3.7/urllib/request.py", line 503, in _call_chain
    result = func(*args)
  File "/usr/lib/python3.7/urllib/request.py", line 1362, in https_open
    context=self._context, check_hostname=self._check_hostname)
  File "/usr/lib/python3.7/urllib/request.py", line 1321, in do_open
    raise URLError(err)
urllib.error.URLError: <urlopen error [Errno -3] Temporary failure in name resolution>

[INFO] (wagtail-readingtime) This package is up to date.
[ERROR] (wagtail-redactor) This package does not have downloadable releases.
[INFO] (wagtail-references) This package is up to date.
[INFO] (wagtail-related) This package is up to date.
[INFO] (wagtail-resume) This package is up to date.
[INFO] (wagtail-review) This package is up to date.
[INFO] (wagtail-robots) This package is up to date.
[INFO] (wagtail-schema-org) This package is up to date.
[INFO] (wagtail-sendinblue) This package is up to date.
[INFO] (wagtail-sentiment) This package is up to date.
[INFO] (wagtail-sharing) This package is up to date.
[INFO] (wagtail-shop) This package is up to date.
[INFO] (wagtail-simple-demo) This package is up to date.
[INFO] (wagtail-simple-gallery) This package is up to date.
[INFO] (wagtail-simple-math-captcha) This package is up to date.
[INFO] (wagtail-site) This package is up to date.
[INFO] (wagtail-site-of-alexandro-by) This package is up to date.
[INFO] (wagtail-site-sections) This package is up to date.
[INFO] (wagtail-smart-selects) This package is up to date.
[INFO] (wagtail-smartstream) This package is up to date.
[INFO] (wagtail-snippet-image) This package is up to date.
[INFO] (wagtail-spa-integration) This package is up to date.
[INFO] (wagtail-spa-routing) This package is up to date.
[INFO] (wagtail-speech) This package is up to date.
[INFO] (wagtail-stacks) This package is up to date.
[INFO] (wagtail-stacks-embed) This package is up to date.
[INFO] (wagtail-stacks-featuredlink) This package is up to date.
[INFO] (wagtail-stacks-image) This package is up to date.
[INFO] (wagtail-storages) This package is up to date.
[INFO] (wagtail-streamfield-migrate) This package is up to date.
[INFO] (wagtail-streamfieldtools) This package is up to date.
[INFO] (wagtail-table-block) This package is up to date.
[INFO] (wagtail-tag-manager) This package is up to date.
[INFO] (wagtail-textract) This package is up to date.
[INFO] (wagtail-themes) This package is up to date.
[INFO] (wagtail-tinify) This package is up to date.
[INFO] (wagtail-transfer) This package is up to date.
[INFO] (wagtail-treemodeladmin) This package is up to date.
[INFO] (wagtail-uplift) This package is up to date.
[INFO] (wagtail-utphy-richdocument) This package is up to date.
[INFO] (wagtail-video) This package is up to date.
[INFO] (wagtail-videos) This package is up to date.
[INFO] (wagtail-whoosh) This package is up to date.
[ERROR] (wagtail1-13-1-modelchooser) Could not get a response from API for this package. See below for details.
Traceback (most recent call last):
  File "/usr/lib/python3.7/urllib/request.py", line 1319, in do_open
    encode_chunked=req.has_header('Transfer-encoding'))
  File "/usr/lib/python3.7/http/client.py", line 1252, in request
    self._send_request(method, url, body, headers, encode_chunked)
  File "/usr/lib/python3.7/http/client.py", line 1298, in _send_request
    self.endheaders(body, encode_chunked=encode_chunked)
  File "/usr/lib/python3.7/http/client.py", line 1247, in endheaders
    self._send_output(message_body, encode_chunked=encode_chunked)
  File "/usr/lib/python3.7/http/client.py", line 1026, in _send_output
    self.send(msg)
  File "/usr/lib/python3.7/http/client.py", line 966, in send
    self.connect()
  File "/usr/lib/python3.7/http/client.py", line 1414, in connect
    super().connect()
  File "/usr/lib/python3.7/http/client.py", line 938, in connect
    (self.host,self.port), self.timeout, self.source_address)
  File "/usr/lib/python3.7/socket.py", line 707, in create_connection
    for res in getaddrinfo(host, port, 0, SOCK_STREAM):
  File "/usr/lib/python3.7/socket.py", line 752, in getaddrinfo
    for res in _socket.getaddrinfo(host, port, family, type, proto, flags):
socket.gaierror: [Errno -3] Temporary failure in name resolution

During handling of the above exception, another exception occurred:

Traceback (most recent call last):
  File "/usr/local/lib/python3.7/dist-packages/pypicontents/api/pypi.py", line 264, in get_pkgdata
    timeout=10).read()
  File "/usr/lib/python3.7/urllib/request.py", line 222, in urlopen
    return opener.open(url, data, timeout)
  File "/usr/lib/python3.7/urllib/request.py", line 525, in open
    response = self._open(req, data)
  File "/usr/lib/python3.7/urllib/request.py", line 543, in _open
    '_open', req)
  File "/usr/lib/python3.7/urllib/request.py", line 503, in _call_chain
    result = func(*args)
  File "/usr/lib/python3.7/urllib/request.py", line 1362, in https_open
    context=self._context, check_hostname=self._check_hostname)
  File "/usr/lib/python3.7/urllib/request.py", line 1321, in do_open
    raise URLError(err)
urllib.error.URLError: <urlopen error [Errno -3] Temporary failure in name resolution>

[INFO] (wagtailadminintercom) This package is up to date.
[INFO] (wagtailaltgenerator) This package is up to date.
[INFO] (wagtailannotatedimage) This package is up to date.
[ERROR] (wagtailapi) This package does not have downloadable releases.
[INFO] (wagtailapi-legacy) This package is up to date.
[ERROR] (wagtailapiclient) This package does not have downloadable releases.
[INFO] (wagtailapproval) This package is up to date.
[INFO] (wagtailatomicadmin) This package is up to date.
[INFO] (wagtailbettereditor) This package is up to date.
[INFO] (wagtailblocks-cards) This package is up to date.
[INFO] (wagtailbookmarklet) This package is up to date.
[INFO] (wagtailclearstream) This package is up to date.
[INFO] (wagtailcloudinary) This package is up to date.
[INFO] (wagtailcodeblock) This package is up to date.
[INFO] (wagtailcolourpicker) This package is up to date.
[INFO] (wagtailcolumnblocks) This package is up to date.
[INFO] (wagtailcomments) This package is up to date.
[INFO] (wagtailcomments-xtd) This package is up to date.
[INFO] (wagtailcommonblocks) This package is up to date.
[INFO] (wagtailcontentstream) This package is up to date.
[ERROR] (wagtaildependencies) Could not get a response from API for this package. See below for details.
Traceback (most recent call last):
  File "/usr/lib/python3.7/urllib/request.py", line 1319, in do_open
    encode_chunked=req.has_header('Transfer-encoding'))
  File "/usr/lib/python3.7/http/client.py", line 1252, in request
    self._send_request(method, url, body, headers, encode_chunked)
  File "/usr/lib/python3.7/http/client.py", line 1298, in _send_request
    self.endheaders(body, encode_chunked=encode_chunked)
  File "/usr/lib/python3.7/http/client.py", line 1247, in endheaders
    self._send_output(message_body, encode_chunked=encode_chunked)
  File "/usr/lib/python3.7/http/client.py", line 1026, in _send_output
    self.send(msg)
  File "/usr/lib/python3.7/http/client.py", line 966, in send
    self.connect()
  File "/usr/lib/python3.7/http/client.py", line 1414, in connect
    super().connect()
  File "/usr/lib/python3.7/http/client.py", line 938, in connect
    (self.host,self.port), self.timeout, self.source_address)
  File "/usr/lib/python3.7/socket.py", line 707, in create_connection
    for res in getaddrinfo(host, port, 0, SOCK_STREAM):
  File "/usr/lib/python3.7/socket.py", line 752, in getaddrinfo
    for res in _socket.getaddrinfo(host, port, family, type, proto, flags):
socket.gaierror: [Errno -3] Temporary failure in name resolution

During handling of the above exception, another exception occurred:

Traceback (most recent call last):
  File "/usr/local/lib/python3.7/dist-packages/pypicontents/api/pypi.py", line 264, in get_pkgdata
    timeout=10).read()
  File "/usr/lib/python3.7/urllib/request.py", line 222, in urlopen
    return opener.open(url, data, timeout)
  File "/usr/lib/python3.7/urllib/request.py", line 525, in open
    response = self._open(req, data)
  File "/usr/lib/python3.7/urllib/request.py", line 543, in _open
    '_open', req)
  File "/usr/lib/python3.7/urllib/request.py", line 503, in _call_chain
    result = func(*args)
  File "/usr/lib/python3.7/urllib/request.py", line 1362, in https_open
    context=self._context, check_hostname=self._check_hostname)
  File "/usr/lib/python3.7/urllib/request.py", line 1321, in do_open
    raise URLError(err)
urllib.error.URLError: <urlopen error [Errno -3] Temporary failure in name resolution>

[INFO] (wagtaildocs-previews) This package is up to date.
[INFO] (wagtaildraftail) This package is up to date.
[INFO] (wagtailembedder) This package is up to date.
[INFO] (wagtailembedpeertube) This package is up to date.
[INFO] (wagtailemoji) This package is up to date.
[INFO] (wagtailenforcer) This package is up to date.
[INFO] (wagtailerrorpages) This package is up to date.
[INFO] (wagtailextraicons) This package is up to date.
[INFO] (wagtailextras) This package is up to date.
[INFO] (wagtailfacelift) This package is up to date.
[INFO] (wagtailfontawesome) This package is up to date.
[INFO] (wagtailformblocks) This package is up to date.
[INFO] (wagtailforums) This package is up to date.
[INFO] (wagtailfroala) This package is up to date.
[ERROR] (wagtailgatsby) Could not get a response from API for this package. See below for details.
Traceback (most recent call last):
  File "/usr/lib/python3.7/urllib/request.py", line 1319, in do_open
    encode_chunked=req.has_header('Transfer-encoding'))
  File "/usr/lib/python3.7/http/client.py", line 1252, in request
    self._send_request(method, url, body, headers, encode_chunked)
  File "/usr/lib/python3.7/http/client.py", line 1298, in _send_request
    self.endheaders(body, encode_chunked=encode_chunked)
  File "/usr/lib/python3.7/http/client.py", line 1247, in endheaders
    self._send_output(message_body, encode_chunked=encode_chunked)
  File "/usr/lib/python3.7/http/client.py", line 1026, in _send_output
    self.send(msg)
  File "/usr/lib/python3.7/http/client.py", line 966, in send
    self.connect()
  File "/usr/lib/python3.7/http/client.py", line 1414, in connect
    super().connect()
  File "/usr/lib/python3.7/http/client.py", line 938, in connect
    (self.host,self.port), self.timeout, self.source_address)
  File "/usr/lib/python3.7/socket.py", line 707, in create_connection
    for res in getaddrinfo(host, port, 0, SOCK_STREAM):
  File "/usr/lib/python3.7/socket.py", line 752, in getaddrinfo
    for res in _socket.getaddrinfo(host, port, family, type, proto, flags):
socket.gaierror: [Errno -3] Temporary failure in name resolution

During handling of the above exception, another exception occurred:

Traceback (most recent call last):
  File "/usr/local/lib/python3.7/dist-packages/pypicontents/api/pypi.py", line 264, in get_pkgdata
    timeout=10).read()
  File "/usr/lib/python3.7/urllib/request.py", line 222, in urlopen
    return opener.open(url, data, timeout)
  File "/usr/lib/python3.7/urllib/request.py", line 525, in open
    response = self._open(req, data)
  File "/usr/lib/python3.7/urllib/request.py", line 543, in _open
    '_open', req)
  File "/usr/lib/python3.7/urllib/request.py", line 503, in _call_chain
    result = func(*args)
  File "/usr/lib/python3.7/urllib/request.py", line 1362, in https_open
    context=self._context, check_hostname=self._check_hostname)
  File "/usr/lib/python3.7/urllib/request.py", line 1321, in do_open
    raise URLError(err)
urllib.error.URLError: <urlopen error [Errno -3] Temporary failure in name resolution>

[INFO] (wagtailgeowidget) This package is up to date.
[INFO] (wagtailgmaps) This package is up to date.
[INFO] (wagtailgridder) This package is up to date.
[INFO] (wagtailhavetheabilitytoactuallyseefieldsintheadmin) This package is up to date.
[INFO] (wagtailimporter) This package is up to date.
[INFO] (wagtailinvoices) This package is up to date.
[INFO] (wagtailleafletwidget) This package is up to date.
[INFO] (wagtailmarkdownblock) This package is up to date.
[INFO] (wagtailmath) This package is up to date.
[INFO] (wagtailmedia) This package is up to date.
[INFO] (wagtailmenus) This package is up to date.
[INFO] (wagtailmodeladmin) This package is up to date.
[INFO] (wagtailmodelchooser) This package is up to date.
[INFO] (wagtailmodelchoosers) This package is up to date.
[INFO] (wagtailnest) This package is up to date.
[INFO] (wagtailnetlify) This package is up to date.
[INFO] (wagtailnews) This package is up to date.
[INFO] (wagtailnews-collection) This package is up to date.
[INFO] (wagtailosm) This package is up to date.
[INFO] (wagtailperson) This package is up to date.
[INFO] (wagtailplus) This package is up to date.
[INFO] (wagtailpolls) This package is up to date.
[INFO] (wagtailpress) This package is up to date.
[ERROR] (wagtailsettings) Could not get a response from API for this package. See below for details.
Traceback (most recent call last):
  File "/usr/lib/python3.7/urllib/request.py", line 1319, in do_open
    encode_chunked=req.has_header('Transfer-encoding'))
  File "/usr/lib/python3.7/http/client.py", line 1252, in request
    self._send_request(method, url, body, headers, encode_chunked)
  File "/usr/lib/python3.7/http/client.py", line 1298, in _send_request
    self.endheaders(body, encode_chunked=encode_chunked)
  File "/usr/lib/python3.7/http/client.py", line 1247, in endheaders
    self._send_output(message_body, encode_chunked=encode_chunked)
  File "/usr/lib/python3.7/http/client.py", line 1026, in _send_output
    self.send(msg)
  File "/usr/lib/python3.7/http/client.py", line 966, in send
    self.connect()
  File "/usr/lib/python3.7/http/client.py", line 1414, in connect
    super().connect()
  File "/usr/lib/python3.7/http/client.py", line 938, in connect
    (self.host,self.port), self.timeout, self.source_address)
  File "/usr/lib/python3.7/socket.py", line 707, in create_connection
    for res in getaddrinfo(host, port, 0, SOCK_STREAM):
  File "/usr/lib/python3.7/socket.py", line 752, in getaddrinfo
    for res in _socket.getaddrinfo(host, port, family, type, proto, flags):
socket.gaierror: [Errno -3] Temporary failure in name resolution

During handling of the above exception, another exception occurred:

Traceback (most recent call last):
  File "/usr/local/lib/python3.7/dist-packages/pypicontents/api/pypi.py", line 264, in get_pkgdata
    timeout=10).read()
  File "/usr/lib/python3.7/urllib/request.py", line 222, in urlopen
    return opener.open(url, data, timeout)
  File "/usr/lib/python3.7/urllib/request.py", line 525, in open
    response = self._open(req, data)
  File "/usr/lib/python3.7/urllib/request.py", line 543, in _open
    '_open', req)
  File "/usr/lib/python3.7/urllib/request.py", line 503, in _call_chain
    result = func(*args)
  File "/usr/lib/python3.7/urllib/request.py", line 1362, in https_open
    context=self._context, check_hostname=self._check_hostname)
  File "/usr/lib/python3.7/urllib/request.py", line 1321, in do_open
    raise URLError(err)
urllib.error.URLError: <urlopen error [Errno -3] Temporary failure in name resolution>

[ERROR] (wagtailsnippetscopy) Could not get a response from API for this package. See below for details.
Traceback (most recent call last):
  File "/usr/lib/python3.7/urllib/request.py", line 1319, in do_open
    encode_chunked=req.has_header('Transfer-encoding'))
  File "/usr/lib/python3.7/http/client.py", line 1252, in request
    self._send_request(method, url, body, headers, encode_chunked)
  File "/usr/lib/python3.7/http/client.py", line 1298, in _send_request
    self.endheaders(body, encode_chunked=encode_chunked)
  File "/usr/lib/python3.7/http/client.py", line 1247, in endheaders
    self._send_output(message_body, encode_chunked=encode_chunked)
  File "/usr/lib/python3.7/http/client.py", line 1026, in _send_output
    self.send(msg)
  File "/usr/lib/python3.7/http/client.py", line 966, in send
    self.connect()
  File "/usr/lib/python3.7/http/client.py", line 1414, in connect
    super().connect()
  File "/usr/lib/python3.7/http/client.py", line 938, in connect
    (self.host,self.port), self.timeout, self.source_address)
  File "/usr/lib/python3.7/socket.py", line 707, in create_connection
    for res in getaddrinfo(host, port, 0, SOCK_STREAM):
  File "/usr/lib/python3.7/socket.py", line 752, in getaddrinfo
    for res in _socket.getaddrinfo(host, port, family, type, proto, flags):
socket.gaierror: [Errno -3] Temporary failure in name resolution

During handling of the above exception, another exception occurred:

Traceback (most recent call last):
  File "/usr/local/lib/python3.7/dist-packages/pypicontents/api/pypi.py", line 264, in get_pkgdata
    timeout=10).read()
  File "/usr/lib/python3.7/urllib/request.py", line 222, in urlopen
    return opener.open(url, data, timeout)
  File "/usr/lib/python3.7/urllib/request.py", line 525, in open
    response = self._open(req, data)
  File "/usr/lib/python3.7/urllib/request.py", line 543, in _open
    '_open', req)
  File "/usr/lib/python3.7/urllib/request.py", line 503, in _call_chain
    result = func(*args)
  File "/usr/lib/python3.7/urllib/request.py", line 1362, in https_open
    context=self._context, check_hostname=self._check_hostname)
  File "/usr/lib/python3.7/urllib/request.py", line 1321, in do_open
    raise URLError(err)
urllib.error.URLError: <urlopen error [Errno -3] Temporary failure in name resolution>

[INFO] (wagtailsocialfeed) This package is up to date.
[ERROR] (wagtailstartproject) Could not get a response from API for this package. See below for details.
Traceback (most recent call last):
  File "/usr/lib/python3.7/urllib/request.py", line 1319, in do_open
    encode_chunked=req.has_header('Transfer-encoding'))
  File "/usr/lib/python3.7/http/client.py", line 1252, in request
    self._send_request(method, url, body, headers, encode_chunked)
  File "/usr/lib/python3.7/http/client.py", line 1298, in _send_request
    self.endheaders(body, encode_chunked=encode_chunked)
  File "/usr/lib/python3.7/http/client.py", line 1247, in endheaders
    self._send_output(message_body, encode_chunked=encode_chunked)
  File "/usr/lib/python3.7/http/client.py", line 1026, in _send_output
    self.send(msg)
  File "/usr/lib/python3.7/http/client.py", line 966, in send
    self.connect()
  File "/usr/lib/python3.7/http/client.py", line 1414, in connect
    super().connect()
  File "/usr/lib/python3.7/http/client.py", line 938, in connect
    (self.host,self.port), self.timeout, self.source_address)
  File "/usr/lib/python3.7/socket.py", line 707, in create_connection
    for res in getaddrinfo(host, port, 0, SOCK_STREAM):
  File "/usr/lib/python3.7/socket.py", line 752, in getaddrinfo
    for res in _socket.getaddrinfo(host, port, family, type, proto, flags):
socket.gaierror: [Errno -3] Temporary failure in name resolution

During handling of the above exception, another exception occurred:

Traceback (most recent call last):
  File "/usr/local/lib/python3.7/dist-packages/pypicontents/api/pypi.py", line 264, in get_pkgdata
    timeout=10).read()
  File "/usr/lib/python3.7/urllib/request.py", line 222, in urlopen
    return opener.open(url, data, timeout)
  File "/usr/lib/python3.7/urllib/request.py", line 525, in open
    response = self._open(req, data)
  File "/usr/lib/python3.7/urllib/request.py", line 543, in _open
    '_open', req)
  File "/usr/lib/python3.7/urllib/request.py", line 503, in _call_chain
    result = func(*args)
  File "/usr/lib/python3.7/urllib/request.py", line 1362, in https_open
    context=self._context, check_hostname=self._check_hostname)
  File "/usr/lib/python3.7/urllib/request.py", line 1321, in do_open
    raise URLError(err)
urllib.error.URLError: <urlopen error [Errno -3] Temporary failure in name resolution>

[INFO] (wagtailstreamforms) This package is up to date.
[INFO] (wagtailsurveys) This package is up to date.
[INFO] (wagtailsweetcaptcha) This package is up to date.
[INFO] (wagtailsystemtext) This package is up to date.
[INFO] (wagtailtestutils) This package is up to date.
[INFO] (wagtailtextanalysis) This package is up to date.
[INFO] (wagtailtinymce) This package is up to date.
[INFO] (wagtailtinypng) This package is up to date.
[INFO] (wagtailtrans) This package is up to date.
[ERROR] (wagtailtranslations) Could not get a response from API for this package. See below for details.
Traceback (most recent call last):
  File "/usr/lib/python3.7/urllib/request.py", line 1319, in do_open
    encode_chunked=req.has_header('Transfer-encoding'))
  File "/usr/lib/python3.7/http/client.py", line 1252, in request
    self._send_request(method, url, body, headers, encode_chunked)
  File "/usr/lib/python3.7/http/client.py", line 1298, in _send_request
    self.endheaders(body, encode_chunked=encode_chunked)
  File "/usr/lib/python3.7/http/client.py", line 1247, in endheaders
    self._send_output(message_body, encode_chunked=encode_chunked)
  File "/usr/lib/python3.7/http/client.py", line 1026, in _send_output
    self.send(msg)
  File "/usr/lib/python3.7/http/client.py", line 966, in send
    self.connect()
  File "/usr/lib/python3.7/http/client.py", line 1414, in connect
    super().connect()
  File "/usr/lib/python3.7/http/client.py", line 938, in connect
    (self.host,self.port), self.timeout, self.source_address)
  File "/usr/lib/python3.7/socket.py", line 707, in create_connection
    for res in getaddrinfo(host, port, 0, SOCK_STREAM):
  File "/usr/lib/python3.7/socket.py", line 752, in getaddrinfo
    for res in _socket.getaddrinfo(host, port, family, type, proto, flags):
socket.gaierror: [Errno -3] Temporary failure in name resolution

During handling of the above exception, another exception occurred:

Traceback (most recent call last):
  File "/usr/local/lib/python3.7/dist-packages/pypicontents/api/pypi.py", line 264, in get_pkgdata
    timeout=10).read()
  File "/usr/lib/python3.7/urllib/request.py", line 222, in urlopen
    return opener.open(url, data, timeout)
  File "/usr/lib/python3.7/urllib/request.py", line 525, in open
    response = self._open(req, data)
  File "/usr/lib/python3.7/urllib/request.py", line 543, in _open
    '_open', req)
  File "/usr/lib/python3.7/urllib/request.py", line 503, in _call_chain
    result = func(*args)
  File "/usr/lib/python3.7/urllib/request.py", line 1362, in https_open
    context=self._context, check_hostname=self._check_hostname)
  File "/usr/lib/python3.7/urllib/request.py", line 1321, in do_open
    raise URLError(err)
urllib.error.URLError: <urlopen error [Errno -3] Temporary failure in name resolution>

[INFO] (wagtailuiplus) This package is up to date.
[INFO] (wagtailvideos) This package is up to date.
[ERROR] (wah-cade) Could not extract data from this package. See below for details.
"http://www.anti-particle.com/projects/wahcade/wahcade-0.19.tar.gz" file could not be downloaded. See below for details.
Traceback (most recent call last):
  File "/usr/local/lib/python3.7/dist-packages/pypicontents/api/pypi.py", line 107, in download_tar
    f.write(urlopen(url=urlesc(pkgurl), timeout=10).read())
  File "/usr/lib/python3.7/urllib/request.py", line 222, in urlopen
    return opener.open(url, data, timeout)
  File "/usr/lib/python3.7/urllib/request.py", line 531, in open
    response = meth(req, response)
  File "/usr/lib/python3.7/urllib/request.py", line 641, in http_response
    'http', request, response, code, msg, hdrs)
  File "/usr/lib/python3.7/urllib/request.py", line 569, in error
    return self._call_chain(*args)
  File "/usr/lib/python3.7/urllib/request.py", line 503, in _call_chain
    result = func(*args)
  File "/usr/lib/python3.7/urllib/request.py", line 649, in http_error_default
    raise HTTPError(req.full_url, code, msg, hdrs, fp)
urllib.error.HTTPError: HTTP Error 404: Not Found

[ERROR] (wahji) Could not get a response from API for this package. See below for details.
Traceback (most recent call last):
  File "/usr/local/lib/python3.7/dist-packages/pypicontents/api/pypi.py", line 264, in get_pkgdata
    timeout=10).read()
  File "/usr/lib/python3.7/urllib/request.py", line 222, in urlopen
    return opener.open(url, data, timeout)
  File "/usr/lib/python3.7/urllib/request.py", line 531, in open
    response = meth(req, response)
  File "/usr/lib/python3.7/urllib/request.py", line 641, in http_response
    'http', request, response, code, msg, hdrs)
  File "/usr/lib/python3.7/urllib/request.py", line 569, in error
    return self._call_chain(*args)
  File "/usr/lib/python3.7/urllib/request.py", line 503, in _call_chain
    result = func(*args)
  File "/usr/lib/python3.7/urllib/request.py", line 649, in http_error_default
    raise HTTPError(req.full_url, code, msg, hdrs, fp)
urllib.error.HTTPError: HTTP Error 404: Not Found

[INFO] (wahlrecht) This package is up to date.
[ERROR] (wai) Could not get a response from API for this package. See below for details.
Traceback (most recent call last):
  File "/usr/local/lib/python3.7/dist-packages/pypicontents/api/pypi.py", line 264, in get_pkgdata
    timeout=10).read()
  File "/usr/lib/python3.7/urllib/request.py", line 222, in urlopen
    return opener.open(url, data, timeout)
  File "/usr/lib/python3.7/urllib/request.py", line 531, in open
    response = meth(req, response)
  File "/usr/lib/python3.7/urllib/request.py", line 641, in http_response
    'http', request, response, code, msg, hdrs)
  File "/usr/lib/python3.7/urllib/request.py", line 569, in error
    return self._call_chain(*args)
  File "/usr/lib/python3.7/urllib/request.py", line 503, in _call_chain
    result = func(*args)
  File "/usr/lib/python3.7/urllib/request.py", line 649, in http_error_default
    raise HTTPError(req.full_url, code, msg, hdrs, fp)
urllib.error.HTTPError: HTTP Error 404: Not Found

[INFO] (wai-annotations) This package is up to date.
[INFO] (wai-common) This package is up to date.
[INFO] (wai-ma) This package is up to date.
[INFO] (wai-test) This package is up to date.
[INFO] (wai-tfimageclass) This package is up to date.
[INFO] (wai-tfrecords) This package is up to date.
[INFO] (wai-tfutils) This package is up to date.
[INFO] (waifu) This package is up to date.
[INFO] (waifu-cli) This package is up to date.
[INFO] (waifuai) This package is up to date.
[INFO] (waimoku) This package is up to date.
[INFO] (waipy) This package is up to date.
[INFO] (wait) This package is up to date.
[INFO] (wait-for) This package is up to date.
[INFO] (wait-for-it) This package is up to date.
[INFO] (wait-for-it-to) This package is up to date.
[INFO] (wait-for-port) This package is up to date.
[INFO] (wait-ios-serial) This package is up to date.
[ERROR] (wait-notify) Could not get a response from API for this package. See below for details.
Traceback (most recent call last):
  File "/usr/lib/python3.7/urllib/request.py", line 1319, in do_open
    encode_chunked=req.has_header('Transfer-encoding'))
  File "/usr/lib/python3.7/http/client.py", line 1252, in request
    self._send_request(method, url, body, headers, encode_chunked)
  File "/usr/lib/python3.7/http/client.py", line 1298, in _send_request
    self.endheaders(body, encode_chunked=encode_chunked)
  File "/usr/lib/python3.7/http/client.py", line 1247, in endheaders
    self._send_output(message_body, encode_chunked=encode_chunked)
  File "/usr/lib/python3.7/http/client.py", line 1026, in _send_output
    self.send(msg)
  File "/usr/lib/python3.7/http/client.py", line 966, in send
    self.connect()
  File "/usr/lib/python3.7/http/client.py", line 1414, in connect
    super().connect()
  File "/usr/lib/python3.7/http/client.py", line 938, in connect
    (self.host,self.port), self.timeout, self.source_address)
  File "/usr/lib/python3.7/socket.py", line 707, in create_connection
    for res in getaddrinfo(host, port, 0, SOCK_STREAM):
  File "/usr/lib/python3.7/socket.py", line 752, in getaddrinfo
    for res in _socket.getaddrinfo(host, port, family, type, proto, flags):
socket.gaierror: [Errno -3] Temporary failure in name resolution

During handling of the above exception, another exception occurred:

Traceback (most recent call last):
  File "/usr/local/lib/python3.7/dist-packages/pypicontents/api/pypi.py", line 264, in get_pkgdata
    timeout=10).read()
  File "/usr/lib/python3.7/urllib/request.py", line 222, in urlopen
    return opener.open(url, data, timeout)
  File "/usr/lib/python3.7/urllib/request.py", line 525, in open
    response = self._open(req, data)
  File "/usr/lib/python3.7/urllib/request.py", line 543, in _open
    '_open', req)
  File "/usr/lib/python3.7/urllib/request.py", line 503, in _call_chain
    result = func(*args)
  File "/usr/lib/python3.7/urllib/request.py", line 1362, in https_open
    context=self._context, check_hostname=self._check_hostname)
  File "/usr/lib/python3.7/urllib/request.py", line 1321, in do_open
    raise URLError(err)
urllib.error.URLError: <urlopen error [Errno -3] Temporary failure in name resolution>

[INFO] (wait-response) This package is up to date.
[INFO] (waiter) This package is up to date.
[INFO] (waiter-client) This package is up to date.
[INFO] (waiterdb) This package is up to date.
[INFO] (waitforit) This package is up to date.
[INFO] (waitfornet) This package is up to date.
[INFO] (waitgpu) This package is up to date.
[INFO] (waiting) This package is up to date.
[INFO] (waitredis) This package is up to date.
[INFO] (waitress) This package is up to date.
[INFO] (waity) This package is up to date.
[INFO] (waitz-s3-api) This package is up to date.
[INFO] (waiverdb) This package is up to date.
[INFO] (waiwera-credo) Data has been updated for this package.
[INFO] (wajiwaji) This package is up to date.
[INFO] (wakadump) This package is up to date.
[ERROR] (wakame) Could not get a response from API for this package. See below for details.
Traceback (most recent call last):
  File "/usr/lib/python3.7/urllib/request.py", line 1319, in do_open
    encode_chunked=req.has_header('Transfer-encoding'))
  File "/usr/lib/python3.7/http/client.py", line 1252, in request
    self._send_request(method, url, body, headers, encode_chunked)
  File "/usr/lib/python3.7/http/client.py", line 1298, in _send_request
    self.endheaders(body, encode_chunked=encode_chunked)
  File "/usr/lib/python3.7/http/client.py", line 1247, in endheaders
    self._send_output(message_body, encode_chunked=encode_chunked)
  File "/usr/lib/python3.7/http/client.py", line 1026, in _send_output
    self.send(msg)
  File "/usr/lib/python3.7/http/client.py", line 966, in send
    self.connect()
  File "/usr/lib/python3.7/http/client.py", line 1414, in connect
    super().connect()
  File "/usr/lib/python3.7/http/client.py", line 938, in connect
    (self.host,self.port), self.timeout, self.source_address)
  File "/usr/lib/python3.7/socket.py", line 707, in create_connection
    for res in getaddrinfo(host, port, 0, SOCK_STREAM):
  File "/usr/lib/python3.7/socket.py", line 752, in getaddrinfo
    for res in _socket.getaddrinfo(host, port, family, type, proto, flags):
socket.gaierror: [Errno -3] Temporary failure in name resolution

During handling of the above exception, another exception occurred:

Traceback (most recent call last):
  File "/usr/local/lib/python3.7/dist-packages/pypicontents/api/pypi.py", line 264, in get_pkgdata
    timeout=10).read()
  File "/usr/lib/python3.7/urllib/request.py", line 222, in urlopen
    return opener.open(url, data, timeout)
  File "/usr/lib/python3.7/urllib/request.py", line 525, in open
    response = self._open(req, data)
  File "/usr/lib/python3.7/urllib/request.py", line 543, in _open
    '_open', req)
  File "/usr/lib/python3.7/urllib/request.py", line 503, in _call_chain
    result = func(*args)
  File "/usr/lib/python3.7/urllib/request.py", line 1362, in https_open
    context=self._context, check_hostname=self._check_hostname)
  File "/usr/lib/python3.7/urllib/request.py", line 1321, in do_open
    raise URLError(err)
urllib.error.URLError: <urlopen error [Errno -3] Temporary failure in name resolution>

[INFO] (wakapy) This package is up to date.
[INFO] (wakati) This package is up to date.
[INFO] (wakatime) This package is up to date.
[ERROR] (wake) Could not get a response from API for this package. See below for details.
Traceback (most recent call last):
  File "/usr/lib/python3.7/urllib/request.py", line 1319, in do_open
    encode_chunked=req.has_header('Transfer-encoding'))
  File "/usr/lib/python3.7/http/client.py", line 1252, in request
    self._send_request(method, url, body, headers, encode_chunked)
  File "/usr/lib/python3.7/http/client.py", line 1298, in _send_request
    self.endheaders(body, encode_chunked=encode_chunked)
  File "/usr/lib/python3.7/http/client.py", line 1247, in endheaders
    self._send_output(message_body, encode_chunked=encode_chunked)
  File "/usr/lib/python3.7/http/client.py", line 1026, in _send_output
    self.send(msg)
  File "/usr/lib/python3.7/http/client.py", line 966, in send
    self.connect()
  File "/usr/lib/python3.7/http/client.py", line 1414, in connect
    super().connect()
  File "/usr/lib/python3.7/http/client.py", line 938, in connect
    (self.host,self.port), self.timeout, self.source_address)
  File "/usr/lib/python3.7/socket.py", line 707, in create_connection
    for res in getaddrinfo(host, port, 0, SOCK_STREAM):
  File "/usr/lib/python3.7/socket.py", line 752, in getaddrinfo
    for res in _socket.getaddrinfo(host, port, family, type, proto, flags):
socket.gaierror: [Errno -3] Temporary failure in name resolution

During handling of the above exception, another exception occurred:

Traceback (most recent call last):
  File "/usr/local/lib/python3.7/dist-packages/pypicontents/api/pypi.py", line 264, in get_pkgdata
    timeout=10).read()
  File "/usr/lib/python3.7/urllib/request.py", line 222, in urlopen
    return opener.open(url, data, timeout)
  File "/usr/lib/python3.7/urllib/request.py", line 525, in open
    response = self._open(req, data)
  File "/usr/lib/python3.7/urllib/request.py", line 543, in _open
    '_open', req)
  File "/usr/lib/python3.7/urllib/request.py", line 503, in _call_chain
    result = func(*args)
  File "/usr/lib/python3.7/urllib/request.py", line 1362, in https_open
    context=self._context, check_hostname=self._check_hostname)
  File "/usr/lib/python3.7/urllib/request.py", line 1321, in do_open
    raise URLError(err)
urllib.error.URLError: <urlopen error [Errno -3] Temporary failure in name resolution>

[INFO] (wake-assets) This package is up to date.
[INFO] (wakeonlan) This package is up to date.
[INFO] (wakeywakey) This package is up to date.
[INFO] (waky) This package is up to date.
[ERROR] (wal) This package does not have downloadable releases.
[INFO] (wal-e) This package is up to date.
[INFO] (wal-steam) This package is up to date.
[INFO] (waldcli) This package is up to date.
[INFO] (waldo) This package is up to date.
[INFO] (waldorf) This package is up to date.
[INFO] (waldur-ansible) This package is up to date.
[INFO] (waldur-auth-openid) This package is up to date.
[INFO] (waldur-auth-saml2) This package is up to date.
[INFO] (waldur-auth-social) This package is up to date.
[INFO] (waldur-auth-valimo) This package is up to date.
[INFO] (waldur-aws) This package is up to date.
[INFO] (waldur-azure) This package is up to date.
[INFO] (waldur-core) This package is up to date.
[INFO] (waldur-cost-planning) This package is up to date.
[INFO] (waldur-digitalocean) This package is up to date.
[INFO] (waldur-freeipa) This package is up to date.
[INFO] (waldur-jira) This package is up to date.
[INFO] (waldur-mastermind) Data has been updated for this package.
[INFO] (waldur-openstack) This package is up to date.
[INFO] (waldur-paypal) This package is up to date.
[INFO] (waldur-slurm) This package is up to date.
[INFO] (waldur-zabbix) This package is up to date.
[INFO] (wales) This package is up to date.
[INFO] (waliki) This package is up to date.
[INFO] (walk) This package is up to date.
[INFO] (walkabout) This package is up to date.
[INFO] (walkcompare) This package is up to date.
[INFO] (walkdict) This package is up to date.
[INFO] (walkdir) This package is up to date.
[INFO] (walker) This package is up to date.
[ERROR] (walkframe) This package does not have downloadable releases.
[INFO] (walkingcode) This package is up to date.
[INFO] (walkingliberty) This package is up to date.
[INFO] (walkingmodule) This package is up to date.
[INFO] (walkscore-api) This package is up to date.
[INFO] (walkscore-api-binding) This package is up to date.
[INFO] (walkscore-frontend) This package is up to date.
[ERROR] (wall) Could not get a response from API for this package. See below for details.
Traceback (most recent call last):
  File "/usr/lib/python3.7/urllib/request.py", line 1319, in do_open
    encode_chunked=req.has_header('Transfer-encoding'))
  File "/usr/lib/python3.7/http/client.py", line 1252, in request
    self._send_request(method, url, body, headers, encode_chunked)
  File "/usr/lib/python3.7/http/client.py", line 1298, in _send_request
    self.endheaders(body, encode_chunked=encode_chunked)
  File "/usr/lib/python3.7/http/client.py", line 1247, in endheaders
    self._send_output(message_body, encode_chunked=encode_chunked)
  File "/usr/lib/python3.7/http/client.py", line 1026, in _send_output
    self.send(msg)
  File "/usr/lib/python3.7/http/client.py", line 966, in send
    self.connect()
  File "/usr/lib/python3.7/http/client.py", line 1414, in connect
    super().connect()
  File "/usr/lib/python3.7/http/client.py", line 938, in connect
    (self.host,self.port), self.timeout, self.source_address)
  File "/usr/lib/python3.7/socket.py", line 707, in create_connection
    for res in getaddrinfo(host, port, 0, SOCK_STREAM):
  File "/usr/lib/python3.7/socket.py", line 752, in getaddrinfo
    for res in _socket.getaddrinfo(host, port, family, type, proto, flags):
socket.gaierror: [Errno -3] Temporary failure in name resolution

During handling of the above exception, another exception occurred:

Traceback (most recent call last):
  File "/usr/local/lib/python3.7/dist-packages/pypicontents/api/pypi.py", line 264, in get_pkgdata
    timeout=10).read()
  File "/usr/lib/python3.7/urllib/request.py", line 222, in urlopen
    return opener.open(url, data, timeout)
  File "/usr/lib/python3.7/urllib/request.py", line 525, in open
    response = self._open(req, data)
  File "/usr/lib/python3.7/urllib/request.py", line 543, in _open
    '_open', req)
  File "/usr/lib/python3.7/urllib/request.py", line 503, in _call_chain
    result = func(*args)
  File "/usr/lib/python3.7/urllib/request.py", line 1362, in https_open
    context=self._context, check_hostname=self._check_hostname)
  File "/usr/lib/python3.7/urllib/request.py", line 1321, in do_open
    raise URLError(err)
urllib.error.URLError: <urlopen error [Errno -3] Temporary failure in name resolution>

[INFO] (wall-e) This package is up to date.
[INFO] (wall-timeout) This package is up to date.
[INFO] (wallabag-api) This package is up to date.
[INFO] (wallabag-cli) This package is up to date.
[INFO] (wallablur) This package is up to date.
[INFO] (wallaby) This package is up to date.
[INFO] (wallaby-app-crm) This package is up to date.
[INFO] (wallaby-app-inspector) This package is up to date.
[INFO] (wallaby-backend-couchdb) This package is up to date.
[INFO] (wallaby-backend-elasticsearch) This package is up to date.
[INFO] (wallaby-backend-http) This package is up to date.
[INFO] (wallaby-base) This package is up to date.
[ERROR] (wallaby-frontend-qt) Could not get a response from API for this package. See below for details.
Traceback (most recent call last):
  File "/usr/lib/python3.7/urllib/request.py", line 1319, in do_open
    encode_chunked=req.has_header('Transfer-encoding'))
  File "/usr/lib/python3.7/http/client.py", line 1252, in request
    self._send_request(method, url, body, headers, encode_chunked)
  File "/usr/lib/python3.7/http/client.py", line 1298, in _send_request
    self.endheaders(body, encode_chunked=encode_chunked)
  File "/usr/lib/python3.7/http/client.py", line 1247, in endheaders
    self._send_output(message_body, encode_chunked=encode_chunked)
  File "/usr/lib/python3.7/http/client.py", line 1026, in _send_output
    self.send(msg)
  File "/usr/lib/python3.7/http/client.py", line 966, in send
    self.connect()
  File "/usr/lib/python3.7/http/client.py", line 1414, in connect
    super().connect()
  File "/usr/lib/python3.7/http/client.py", line 938, in connect
    (self.host,self.port), self.timeout, self.source_address)
  File "/usr/lib/python3.7/socket.py", line 707, in create_connection
    for res in getaddrinfo(host, port, 0, SOCK_STREAM):
  File "/usr/lib/python3.7/socket.py", line 752, in getaddrinfo
    for res in _socket.getaddrinfo(host, port, family, type, proto, flags):
socket.gaierror: [Errno -3] Temporary failure in name resolution

During handling of the above exception, another exception occurred:

Traceback (most recent call last):
  File "/usr/local/lib/python3.7/dist-packages/pypicontents/api/pypi.py", line 264, in get_pkgdata
    timeout=10).read()
  File "/usr/lib/python3.7/urllib/request.py", line 222, in urlopen
    return opener.open(url, data, timeout)
  File "/usr/lib/python3.7/urllib/request.py", line 525, in open
    response = self._open(req, data)
  File "/usr/lib/python3.7/urllib/request.py", line 543, in _open
    '_open', req)
  File "/usr/lib/python3.7/urllib/request.py", line 503, in _call_chain
    result = func(*args)
  File "/usr/lib/python3.7/urllib/request.py", line 1362, in https_open
    context=self._context, check_hostname=self._check_hostname)
  File "/usr/lib/python3.7/urllib/request.py", line 1321, in do_open
    raise URLError(err)
urllib.error.URLError: <urlopen error [Errno -3] Temporary failure in name resolution>

[INFO] (wallaby-plugin-couchdb) This package is up to date.
[INFO] (wallaby-plugin-elasticsearch) This package is up to date.
[INFO] (wallaby-plugin-pdfgenerator) This package is up to date.
[ERROR] (wallace) Could not get a response from API for this package. See below for details.
Traceback (most recent call last):
  File "/usr/lib/python3.7/urllib/request.py", line 1319, in do_open
    encode_chunked=req.has_header('Transfer-encoding'))
  File "/usr/lib/python3.7/http/client.py", line 1252, in request
    self._send_request(method, url, body, headers, encode_chunked)
  File "/usr/lib/python3.7/http/client.py", line 1298, in _send_request
    self.endheaders(body, encode_chunked=encode_chunked)
  File "/usr/lib/python3.7/http/client.py", line 1247, in endheaders
    self._send_output(message_body, encode_chunked=encode_chunked)
  File "/usr/lib/python3.7/http/client.py", line 1026, in _send_output
    self.send(msg)
  File "/usr/lib/python3.7/http/client.py", line 966, in send
    self.connect()
  File "/usr/lib/python3.7/http/client.py", line 1414, in connect
    super().connect()
  File "/usr/lib/python3.7/http/client.py", line 938, in connect
    (self.host,self.port), self.timeout, self.source_address)
  File "/usr/lib/python3.7/socket.py", line 707, in create_connection
    for res in getaddrinfo(host, port, 0, SOCK_STREAM):
  File "/usr/lib/python3.7/socket.py", line 752, in getaddrinfo
    for res in _socket.getaddrinfo(host, port, family, type, proto, flags):
socket.gaierror: [Errno -3] Temporary failure in name resolution

During handling of the above exception, another exception occurred:

Traceback (most recent call last):
  File "/usr/local/lib/python3.7/dist-packages/pypicontents/api/pypi.py", line 264, in get_pkgdata
    timeout=10).read()
  File "/usr/lib/python3.7/urllib/request.py", line 222, in urlopen
    return opener.open(url, data, timeout)
  File "/usr/lib/python3.7/urllib/request.py", line 525, in open
    response = self._open(req, data)
  File "/usr/lib/python3.7/urllib/request.py", line 543, in _open
    '_open', req)
  File "/usr/lib/python3.7/urllib/request.py", line 503, in _call_chain
    result = func(*args)
  File "/usr/lib/python3.7/urllib/request.py", line 1362, in https_open
    context=self._context, check_hostname=self._check_hostname)
  File "/usr/lib/python3.7/urllib/request.py", line 1321, in do_open
    raise URLError(err)
urllib.error.URLError: <urlopen error [Errno -3] Temporary failure in name resolution>

[ERROR] (wallace-app) This package does not have downloadable releases.
[ERROR] (wallace-platform) This package does not have downloadable releases.
[INFO] (wallall) This package is up to date.
[INFO] (wallapopy) This package is up to date.
[INFO] (wallarm-fast-cli) This package is up to date.
[INFO] (wallarmrasp) This package is up to date.
[INFO] (wallberry-uberpotato) This package is up to date.
[INFO] (wallclock) This package is up to date.
[INFO] (walle) This package is up to date.
[ERROR] (walle-pyzmq) Could not get a response from API for this package. See below for details.
Traceback (most recent call last):
  File "/usr/local/lib/python3.7/dist-packages/pypicontents/api/pypi.py", line 264, in get_pkgdata
    timeout=10).read()
  File "/usr/lib/python3.7/urllib/request.py", line 222, in urlopen
    return opener.open(url, data, timeout)
  File "/usr/lib/python3.7/urllib/request.py", line 531, in open
    response = meth(req, response)
  File "/usr/lib/python3.7/urllib/request.py", line 641, in http_response
    'http', request, response, code, msg, hdrs)
  File "/usr/lib/python3.7/urllib/request.py", line 563, in error
    result = self._call_chain(*args)
  File "/usr/lib/python3.7/urllib/request.py", line 503, in _call_chain
    result = func(*args)
  File "/usr/lib/python3.7/urllib/request.py", line 755, in http_error_302
    return self.parent.open(new, timeout=req.timeout)
  File "/usr/lib/python3.7/urllib/request.py", line 531, in open
    response = meth(req, response)
  File "/usr/lib/python3.7/urllib/request.py", line 641, in http_response
    'http', request, response, code, msg, hdrs)
  File "/usr/lib/python3.7/urllib/request.py", line 569, in error
    return self._call_chain(*args)
  File "/usr/lib/python3.7/urllib/request.py", line 503, in _call_chain
    result = func(*args)
  File "/usr/lib/python3.7/urllib/request.py", line 649, in http_error_default
    raise HTTPError(req.full_url, code, msg, hdrs, fp)
urllib.error.HTTPError: HTTP Error 404: Not Found

[INFO] (walleclient) This package is up to date.
[INFO] (wallee) This package is up to date.
[ERROR] (wallet) This package does not have downloadable releases.
[INFO] (wallet-lib) This package is up to date.
[INFO] (wallet-parser) This package is up to date.
[INFO] (wallet-py3k) This package is up to date.
[INFO] (walletkit) This package is up to date.
[INFO] (walletlib) This package is up to date.
[ERROR] (walletobjects) Could not get a response from API for this package. See below for details.
Traceback (most recent call last):
  File "/usr/local/lib/python3.7/dist-packages/pypicontents/api/pypi.py", line 264, in get_pkgdata
    timeout=10).read()
  File "/usr/lib/python3.7/urllib/request.py", line 222, in urlopen
    return opener.open(url, data, timeout)
  File "/usr/lib/python3.7/urllib/request.py", line 531, in open
    response = meth(req, response)
  File "/usr/lib/python3.7/urllib/request.py", line 641, in http_response
    'http', request, response, code, msg, hdrs)
  File "/usr/lib/python3.7/urllib/request.py", line 569, in error
    return self._call_chain(*args)
  File "/usr/lib/python3.7/urllib/request.py", line 503, in _call_chain
    result = func(*args)
  File "/usr/lib/python3.7/urllib/request.py", line 649, in http_error_default
    raise HTTPError(req.full_url, code, msg, hdrs, fp)
urllib.error.HTTPError: HTTP Error 404: Not Found

[ERROR] (wallhaven) Could not get a response from API for this package. See below for details.
Traceback (most recent call last):
  File "/usr/lib/python3.7/urllib/request.py", line 1319, in do_open
    encode_chunked=req.has_header('Transfer-encoding'))
  File "/usr/lib/python3.7/http/client.py", line 1252, in request
    self._send_request(method, url, body, headers, encode_chunked)
  File "/usr/lib/python3.7/http/client.py", line 1298, in _send_request
    self.endheaders(body, encode_chunked=encode_chunked)
  File "/usr/lib/python3.7/http/client.py", line 1247, in endheaders
    self._send_output(message_body, encode_chunked=encode_chunked)
  File "/usr/lib/python3.7/http/client.py", line 1026, in _send_output
    self.send(msg)
  File "/usr/lib/python3.7/http/client.py", line 966, in send
    self.connect()
  File "/usr/lib/python3.7/http/client.py", line 1414, in connect
    super().connect()
  File "/usr/lib/python3.7/http/client.py", line 938, in connect
    (self.host,self.port), self.timeout, self.source_address)
  File "/usr/lib/python3.7/socket.py", line 707, in create_connection
    for res in getaddrinfo(host, port, 0, SOCK_STREAM):
  File "/usr/lib/python3.7/socket.py", line 752, in getaddrinfo
    for res in _socket.getaddrinfo(host, port, family, type, proto, flags):
socket.gaierror: [Errno -3] Temporary failure in name resolution

During handling of the above exception, another exception occurred:

Traceback (most recent call last):
  File "/usr/local/lib/python3.7/dist-packages/pypicontents/api/pypi.py", line 264, in get_pkgdata
    timeout=10).read()
  File "/usr/lib/python3.7/urllib/request.py", line 222, in urlopen
    return opener.open(url, data, timeout)
  File "/usr/lib/python3.7/urllib/request.py", line 525, in open
    response = self._open(req, data)
  File "/usr/lib/python3.7/urllib/request.py", line 543, in _open
    '_open', req)
  File "/usr/lib/python3.7/urllib/request.py", line 503, in _call_chain
    result = func(*args)
  File "/usr/lib/python3.7/urllib/request.py", line 1362, in https_open
    context=self._context, check_hostname=self._check_hostname)
  File "/usr/lib/python3.7/urllib/request.py", line 1321, in do_open
    raise URLError(err)
urllib.error.URLError: <urlopen error [Errno -3] Temporary failure in name resolution>

[INFO] (wallme) This package is up to date.
[INFO] (wallp) This package is up to date.
[INFO] (wallpaper) This package is up to date.
[INFO] (wallpaper-app) This package is up to date.
[ERROR] (wallpaper-changer) This package does not have downloadable releases.
[ERROR] (wallpaperentropy) Could not get a response from API for this package. See below for details.
Traceback (most recent call last):
  File "/usr/lib/python3.7/urllib/request.py", line 1319, in do_open
    encode_chunked=req.has_header('Transfer-encoding'))
  File "/usr/lib/python3.7/http/client.py", line 1252, in request
    self._send_request(method, url, body, headers, encode_chunked)
  File "/usr/lib/python3.7/http/client.py", line 1298, in _send_request
    self.endheaders(body, encode_chunked=encode_chunked)
  File "/usr/lib/python3.7/http/client.py", line 1247, in endheaders
    self._send_output(message_body, encode_chunked=encode_chunked)
  File "/usr/lib/python3.7/http/client.py", line 1026, in _send_output
    self.send(msg)
  File "/usr/lib/python3.7/http/client.py", line 966, in send
    self.connect()
  File "/usr/lib/python3.7/http/client.py", line 1414, in connect
    super().connect()
  File "/usr/lib/python3.7/http/client.py", line 938, in connect
    (self.host,self.port), self.timeout, self.source_address)
  File "/usr/lib/python3.7/socket.py", line 707, in create_connection
    for res in getaddrinfo(host, port, 0, SOCK_STREAM):
  File "/usr/lib/python3.7/socket.py", line 752, in getaddrinfo
    for res in _socket.getaddrinfo(host, port, family, type, proto, flags):
socket.gaierror: [Errno -3] Temporary failure in name resolution

During handling of the above exception, another exception occurred:

Traceback (most recent call last):
  File "/usr/local/lib/python3.7/dist-packages/pypicontents/api/pypi.py", line 264, in get_pkgdata
    timeout=10).read()
  File "/usr/lib/python3.7/urllib/request.py", line 222, in urlopen
    return opener.open(url, data, timeout)
  File "/usr/lib/python3.7/urllib/request.py", line 525, in open
    response = self._open(req, data)
  File "/usr/lib/python3.7/urllib/request.py", line 543, in _open
    '_open', req)
  File "/usr/lib/python3.7/urllib/request.py", line 503, in _call_chain
    result = func(*args)
  File "/usr/lib/python3.7/urllib/request.py", line 1362, in https_open
    context=self._context, check_hostname=self._check_hostname)
  File "/usr/lib/python3.7/urllib/request.py", line 1321, in do_open
    raise URLError(err)
urllib.error.URLError: <urlopen error [Errno -3] Temporary failure in name resolution>

[INFO] (wallpaperkiller) This package is up to date.
[INFO] (wallpaperoptimizer) This package is up to date.
[INFO] (wallpoppy) This package is up to date.
[INFO] (wallpyper) This package is up to date.
[INFO] (walls) This package is up to date.
[INFO] (wallstreet) This package is up to date.
[INFO] (walltask) This package is up to date.
[INFO] (wallthick) This package is up to date.
[INFO] (wally) This package is up to date.
[INFO] (wallypractice) This package is up to date.
[ERROR] (walmart) Could not get a response from API for this package. See below for details.
Traceback (most recent call last):
  File "/usr/lib/python3.7/urllib/request.py", line 1319, in do_open
    encode_chunked=req.has_header('Transfer-encoding'))
  File "/usr/lib/python3.7/http/client.py", line 1252, in request
    self._send_request(method, url, body, headers, encode_chunked)
  File "/usr/lib/python3.7/http/client.py", line 1298, in _send_request
    self.endheaders(body, encode_chunked=encode_chunked)
  File "/usr/lib/python3.7/http/client.py", line 1247, in endheaders
    self._send_output(message_body, encode_chunked=encode_chunked)
  File "/usr/lib/python3.7/http/client.py", line 1026, in _send_output
    self.send(msg)
  File "/usr/lib/python3.7/http/client.py", line 966, in send
    self.connect()
  File "/usr/lib/python3.7/http/client.py", line 1414, in connect
    super().connect()
  File "/usr/lib/python3.7/http/client.py", line 938, in connect
    (self.host,self.port), self.timeout, self.source_address)
  File "/usr/lib/python3.7/socket.py", line 707, in create_connection
    for res in getaddrinfo(host, port, 0, SOCK_STREAM):
  File "/usr/lib/python3.7/socket.py", line 752, in getaddrinfo
    for res in _socket.getaddrinfo(host, port, family, type, proto, flags):
socket.gaierror: [Errno -3] Temporary failure in name resolution

During handling of the above exception, another exception occurred:

Traceback (most recent call last):
  File "/usr/local/lib/python3.7/dist-packages/pypicontents/api/pypi.py", line 264, in get_pkgdata
    timeout=10).read()
  File "/usr/lib/python3.7/urllib/request.py", line 222, in urlopen
    return opener.open(url, data, timeout)
  File "/usr/lib/python3.7/urllib/request.py", line 525, in open
    response = self._open(req, data)
  File "/usr/lib/python3.7/urllib/request.py", line 543, in _open
    '_open', req)
  File "/usr/lib/python3.7/urllib/request.py", line 503, in _call_chain
    result = func(*args)
  File "/usr/lib/python3.7/urllib/request.py", line 1362, in https_open
    context=self._context, check_hostname=self._check_hostname)
  File "/usr/lib/python3.7/urllib/request.py", line 1321, in do_open
    raise URLError(err)
urllib.error.URLError: <urlopen error [Errno -3] Temporary failure in name resolution>

[INFO] (walmart-api-client) This package is up to date.
[INFO] (walmart-calendar) This package is up to date.
[INFO] (walmart-cloudsec-flask-restplus) This package is up to date.
[INFO] (walmart-reviews) This package is up to date.
[INFO] (walmartcalendar) This package is up to date.
[INFO] (walnut) This package is up to date.
[INFO] (walq) This package is up to date.
[INFO] (walrus) This package is up to date.
[INFO] (walrus-compiler) This package is up to date.
[INFO] (walrus-converter) This package is up to date.
[INFO] (walrus37) This package is up to date.
[ERROR] (walscript) Could not get a response from API for this package. See below for details.
Traceback (most recent call last):
  File "/usr/lib/python3.7/urllib/request.py", line 1319, in do_open
    encode_chunked=req.has_header('Transfer-encoding'))
  File "/usr/lib/python3.7/http/client.py", line 1252, in request
    self._send_request(method, url, body, headers, encode_chunked)
  File "/usr/lib/python3.7/http/client.py", line 1298, in _send_request
    self.endheaders(body, encode_chunked=encode_chunked)
  File "/usr/lib/python3.7/http/client.py", line 1247, in endheaders
    self._send_output(message_body, encode_chunked=encode_chunked)
  File "/usr/lib/python3.7/http/client.py", line 1026, in _send_output
    self.send(msg)
  File "/usr/lib/python3.7/http/client.py", line 966, in send
    self.connect()
  File "/usr/lib/python3.7/http/client.py", line 1414, in connect
    super().connect()
  File "/usr/lib/python3.7/http/client.py", line 938, in connect
    (self.host,self.port), self.timeout, self.source_address)
  File "/usr/lib/python3.7/socket.py", line 707, in create_connection
    for res in getaddrinfo(host, port, 0, SOCK_STREAM):
  File "/usr/lib/python3.7/socket.py", line 752, in getaddrinfo
    for res in _socket.getaddrinfo(host, port, family, type, proto, flags):
socket.gaierror: [Errno -3] Temporary failure in name resolution

During handling of the above exception, another exception occurred:

Traceback (most recent call last):
  File "/usr/local/lib/python3.7/dist-packages/pypicontents/api/pypi.py", line 264, in get_pkgdata
    timeout=10).read()
  File "/usr/lib/python3.7/urllib/request.py", line 222, in urlopen
    return opener.open(url, data, timeout)
  File "/usr/lib/python3.7/urllib/request.py", line 525, in open
    response = self._open(req, data)
  File "/usr/lib/python3.7/urllib/request.py", line 543, in _open
    '_open', req)
  File "/usr/lib/python3.7/urllib/request.py", line 503, in _call_chain
    result = func(*args)
  File "/usr/lib/python3.7/urllib/request.py", line 1362, in https_open
    context=self._context, check_hostname=self._check_hostname)
  File "/usr/lib/python3.7/urllib/request.py", line 1321, in do_open
    raise URLError(err)
urllib.error.URLError: <urlopen error [Errno -3] Temporary failure in name resolution>

[INFO] (walt) This package is up to date.
[INFO] (walt-client) This package is up to date.
[INFO] (walt-common) This package is up to date.
[INFO] (walt-node) This package is up to date.
[INFO] (walt-server) This package is up to date.
[INFO] (walt-virtual) This package is up to date.
[INFO] (walter) This package is up to date.
[INFO] (walterdl-nester) This package is up to date.
[INFO] (walterize) This package is up to date.
[INFO] (waltersco-app) This package is up to date.
[INFO] (walterscoapp) This package is up to date.
[INFO] (walton) This package is up to date.
[INFO] (waltz) This package is up to date.
[INFO] (waluigi) This package is up to date.
[INFO] (waluigi-facade) This package is up to date.
[INFO] (wammu) This package is up to date.
[INFO] (wamp-connection) This package is up to date.
[INFO] (wampli) This package is up to date.
[INFO] (wamptest) This package is up to date.
[INFO] (wampy) This package is up to date.
[INFO] (wampyre) This package is up to date.
[INFO] (wanabrain) This package is up to date.
[INFO] (wanakana) This package is up to date.
[INFO] (wanakana-python) This package is up to date.
[INFO] (wand) This package is up to date.
[INFO] (wandb) This package is up to date.
[INFO] (wandb-summarizer) This package is up to date.
[WARNING] 
[WARNING] Processing has taken more than 2100 seconds. Interrupting.
[WARNING] Processing will continue in next iteration.
[WARNING] 
[INFO] 
[INFO] 
[INFO] Total packages: 4324
[INFO]     Packages processed: 503
[INFO]         Packages updated: 2
[INFO]         Packages up-to-date: 436
[INFO]         Packages without response: 45
[INFO]         Packages without urls: 0
[INFO]         Packages without downloads: 16
[INFO]         Packages with data errors: 4
[INFO]     Packages not processed: 3821
[INFO] 
[INFO] 
[INFO] Ending execution.
